
# Created by Ruins mod version 15.1 Ingame Parser
# authoring Player: Tmtravlr

weight=1
embed_into_distance=1
acceptable_target_blocks=
unacceptable_target_blocks=flowing_water,water,flowing_lava,lava
dimensions=5,7,7
leveling_buffer=-1
preserve_water=0
preserve_lava=0
preserve_plants=0
max_cut_in=0
allowable_overhang=0

rule1=0,100,minecraft:quartz_block-0
rule2=0,100,minecraft:quartz_block-2
rule3=0,100,minecraft:quartz_stairs-0
rule4=0,100,minecraft:quartz_stairs-2
rule5=1,100,minecraft:torch-5
rule6=0,100,minecraft:quartz_stairs-3
rule7=0,100,minecraft:quartz_stairs-1
rule8=0,100,minecraft:quartz_block-1
rule9=0,100,minecraft:diamond_block-0

layer
1,1,1,1,1,1,1
1,1,1,1,1,1,1
1,1,1,1,1,1,1
1,1,1,1,1,1,1
1,1,1,1,1,1,1
1,1,1,1,1,1,1
1,1,1,1,1,1,1
endlayer

layer
2,3,3,3,3,3,2
6,0,5,0,5,0,4
6,5,0,0,0,5,4
6,0,0,0,0,0,4
6,5,0,0,0,5,4
6,0,5,0,5,0,4
2,7,7,7,7,7,2
endlayer

layer
2,0,0,0,0,0,2
0,3,3,8,3,3,0
0,6,0,0,0,4,0
0,8,0,0,0,8,0
0,6,0,0,0,4,0
0,6,7,8,7,7,0
2,0,0,0,0,0,2
endlayer

layer
2,0,0,0,0,0,2
0,0,0,0,0,0,0
0,0,6,3,3,0,0
0,0,6,0,4,0,0
0,0,7,7,4,0,0
0,0,0,0,0,0,0
2,0,0,0,0,0,2
endlayer

layer
9,0,0,0,0,0,9
0,0,0,0,0,0,0
0,0,0,0,0,0,0
0,0,0,9,0,0,0
0,0,0,0,0,0,0
0,0,0,0,0,0,0
9,0,0,0,0,0,9
endlayer

