
# Created by Ruins mod version 15.1 Ingame Parser
# authoring Player: Tmtravlr

weight=1
embed_into_distance=0
acceptable_target_blocks=
unacceptable_target_blocks=flowing_water,water,flowing_lava,lava
dimensions=18,6,6
leveling_buffer=-1
preserve_water=0
preserve_lava=0
preserve_plants=0
max_cut_in=0
allowable_overhang=0

rule1=0,100,minecraft:stone_slab-15
rule2=0,100,minecraft:wool-4
rule3=0,100,minecraft:wool-3
rule4=0,100,minecraft:wool-14
rule5=0,100,minecraft:wool-5
rule6=0,100,minecraft:wool-1
rule7=2,100,minecraft:redstone_torch-2
rule8=0,100,minecraft:rail-6
rule9=0,100,minecraft:rail-5
rule10=0,100,minecraft:wool-9
rule11=0,100,minecraft:rail-3
rule12=0,100,minecraft:wool-11
rule13=0,100,minecraft:rail-7
rule14=0,100,minecraft:rail-0
rule15=0,100,minecraft:golden_rail-5
rule16=0,100,minecraft:wool-2
rule17=0,100,minecraft:wool-10
rule18=0,100,minecraft:rail-9
rule19=0,100,minecraft:golden_rail-11
rule20=0,100,minecraft:rail-1
rule21=0,100,minecraft:lever-6
rule22=0,100,minecraft:rail-8
rule23=2,100,minecraft:redstone_torch-3
rule24=0,100,minecraft:golden_rail-13
rule25=2,100,minecraft:redstone_torch-1
rule26=0,100,minecraft:golden_rail-10
rule27=0,100,minecraft:rail-2
rule28=2,100,minecraft:redstone_torch-4
rule29=0,100,minecraft:rail-4
rule30=0,100,minecraft:golden_rail-12

layer
0,0,0,0,0,0
0,0,0,0,0,0
0,0,2,1,0,0
0,0,0,0,0,0
0,0,4,0,0,3
0,0,4,6,2,5
endlayer

layer
0,0,0,0,0,0
0,0,0,0,0,0
3,5,9,8,0,7
10,0,0,1,0,10
12,0,4,0,0,11
17,16,15,14,14,13
endlayer

layer
0,0,0,0,0,0
0,0,0,0,0,0
18,14,0,0,0,12
20,0,1,13,0,19
20,0,21,0,0,0
22,14,0,0,0,0
endlayer

layer
0,0,0,0,0,0
0,0,0,0,0,17
0,0,1,0,0,11
0,0,22,0,0,0
0,0,0,0,0,0
0,0,0,0,0,0
endlayer

layer
0,0,0,0,4,16
0,0,0,0,0,11
0,0,18,1,0,0
0,0,0,0,0,0
0,0,0,0,0,0
0,0,0,0,0,0
endlayer

layer
0,0,23,6,9,8
0,0,0,0,0,0
0,0,0,8,0,0
0,0,0,1,0,0
0,0,0,0,0,0
0,0,0,0,0,0
endlayer

layer
0,0,2,24,0,0
0,0,0,0,0,0
0,0,0,0,0,0
0,0,1,13,0,0
0,0,0,0,0,0
0,0,0,0,0,0
endlayer

layer
0,5,9,0,0,0
0,0,0,0,0,0
0,0,1,0,0,0
0,0,22,0,0,0
0,0,0,0,0,0
0,0,0,0,0,0
endlayer

layer
3,9,0,0,0,0
10,0,0,0,0,0
25,0,18,1,0,0
0,0,0,0,0,0
0,0,0,0,0,0
0,0,0,0,0,0
endlayer

layer
18,0,0,0,0,0
26,0,0,0,0,0
12,0,0,8,0,0
0,0,0,1,0,0
0,0,0,0,0,0
0,0,0,0,0,0
endlayer

layer
0,0,0,0,0,0
0,0,0,0,0,0
27,0,0,0,0,0
17,0,1,13,0,0
0,0,0,0,0,0
0,0,0,0,0,0
endlayer

layer
0,0,0,0,0,0
0,0,0,0,0,0
0,0,1,0,0,0
27,0,22,0,0,0
16,4,28,0,0,0
0,0,0,0,0,0
endlayer

layer
0,0,0,0,0,0
0,0,0,0,0,0
0,0,18,1,0,0
0,0,0,0,0,0
22,29,6,0,0,0
0,0,0,0,0,0
endlayer

layer
0,0,0,0,0,0
0,0,0,0,0,0
0,0,0,8,0,0
0,0,0,1,0,0
0,0,30,2,0,0
0,0,0,0,0,0
endlayer

layer
0,0,0,0,0,0
0,0,0,0,0,0
0,0,0,0,0,0
0,0,1,13,3,0
0,0,0,29,5,0
0,0,0,0,0,0
endlayer

layer
0,0,0,0,0,0
0,0,0,0,0,0
0,0,1,0,10,0
0,0,22,0,11,0
0,0,0,0,13,0
0,0,0,0,0,0
endlayer

layer
0,0,0,0,0,0
0,0,0,17,12,0
0,0,18,1,11,0
0,0,0,0,0,0
0,0,0,0,0,0
0,0,0,0,0,0
endlayer

layer
0,0,0,0,0,0
0,0,0,18,8,0
0,0,0,13,0,0
0,0,0,0,0,0
0,0,0,0,0,0
0,0,0,0,0,0
endlayer

