
# Created by Ruins mod version 15.1 Ingame Parser
# authoring Player: Tmtravlr

weight=1
embed_into_distance=0
acceptable_target_blocks=
unacceptable_target_blocks=flowing_water,water,flowing_lava,lava
dimensions=5,7,7
leveling_buffer=-1
preserve_water=0
preserve_lava=0
preserve_plants=0
max_cut_in=0
allowable_overhang=0

rule1=0,100,MobSpawner:Zombie
rule2=0,100,MobSpawner:Skeleton
rule3=0,100,TConstruct:decoration.multibrick-1
rule4=0,100,preserveBlock

layer
0,0,0,0,0,0,0
0,2,0,0,0,1,0
0,0,0,0,0,0,0
0,0,0,0,0,0,0
0,0,0,0,0,0,0
0,1,0,0,0,2,0
0,0,0,0,0,0,0
endlayer

layer
0,0,0,0,0,0,0
0,0,0,0,0,0,0
0,0,0,0,0,0,0
0,0,0,0,0,0,0
0,0,0,0,0,0,0
0,0,0,0,0,0,0
0,0,0,0,0,0,0
endlayer

layer
0,0,0,0,0,0,0
0,0,0,0,0,0,0
0,0,0,0,0,0,0
0,0,0,0,0,0,0
0,0,0,0,0,0,0
0,0,0,0,0,0,0
0,0,0,0,0,0,0
endlayer

layer
0,0,0,0,0,0,0
0,0,0,0,0,0,0
0,0,0,0,0,0,0
0,0,0,0,0,0,0
0,0,0,0,0,0,0
0,0,0,0,0,0,0
0,0,0,0,0,0,0
endlayer

layer
4,4,4,4,4,4,4
4,4,4,4,4,4,4
4,4,4,4,4,4,4
4,4,4,3,4,4,4
4,4,4,4,4,4,4
4,4,4,4,4,4,4
4,4,4,4,4,4,4
endlayer

