
# Created by Ruins mod version 15.1 Ingame Parser
# authoring Player: Tmtravlr

weight=1
embed_into_distance=2
acceptable_target_blocks=
unacceptable_target_blocks=flowing_water,water,flowing_lava,lava
dimensions=21,29,29
leveling_buffer=-1
preserve_water=0
preserve_lava=0
preserve_plants=0
max_cut_in=0
allowable_overhang=0

rule1=0,100,TConstruct:slime.grass-0
rule2=0,100,TConstruct:CraftedSoil-5
rule3=0,100,preserveBlock
rule4=0,100,TConstruct:decoration.multibrickfancy-11
rule5=0,100,TConstruct:decoration.multibrickfancy-10
rule6=0,100,TConstruct:decoration.multibrick-11
rule7=0,100,TConstruct:decoration.multibrick-10
rule8=0,100,minecraft:wooden_door-0
rule9=0,100,TConstruct:slime.gel-1
rule10=0,100,TConstruct:slime.grass.tall-0
rule11=0,100,minecraft:wooden_door-1
rule12=0,100,CommandBlock:testruin spiral/slime_castle/castle_room ~ ~ ~:@
rule13=0,100,minecraft:wooden_door-3
rule14=0,100,TConstruct:slime.pad-6
rule15=0,100,TConstruct:slime.pad-0
rule16=0,100,TConstruct:slime.gel-0
rule17=0,100,TConstruct:slime.pad-4
rule18=0,100,TConstruct:slime.pad-2
rule19=0,100,minecraft:wooden_door-2
rule20=0,100,TConstruct:slime.leaves-0
rule21=0,100,TConstruct:GlassPaneClearStained-5
rule22=0,100,minecraft:wooden_door-8
rule23=2,100,minecraft:torch-4
rule24=2,100,minecraft:torch-3
rule25=0,100,lootplusplus:command_block_trigger-0
rule26=0,100,minecraft:wooden_door-9
rule27=2,100,minecraft:torch-2
rule28=2,100,minecraft:torch-1
rule29=0,100,minecraft:glowstone-0
rule30=0,100,CommandBlock:testruin spiral/slime_castle/castle_top ~ ~ ~:@
rule31=0,100,TConstruct:GlassPaneClearStained-3
rule32=0,100,CommandBlock:summon Slime ~ ~ ~ {Size:3,PersistenceRequired:true,CustomName:\"\u00A7a\u00A7lSlimy Guard\"}:@
rule33=0,100,CommandBlock:summon TConstruct.KingSlime ~ ~ ~ {Size:8,PersistenceRequired:true}:@
rule34=1,100,minecraft:torch-5
rule35=0,100,TConstruct:GlassBlock-0

layer
1,1,1,1,1,1,1,1,1,1,1,1,1,1,1,1,1,1,1,1,1,1,1,1,1,1,1,1,1
1,2,2,2,2,1,2,2,2,2,2,2,2,2,2,2,2,2,2,2,2,2,2,2,2,2,2,2,1
1,2,2,2,2,2,2,2,2,2,2,2,2,2,2,2,2,2,2,2,2,2,2,2,2,2,2,2,1
1,2,2,2,2,2,2,2,2,2,2,2,2,2,2,2,2,2,2,2,2,2,2,2,2,2,2,2,1
1,2,2,2,2,2,2,2,2,2,2,2,2,2,2,2,2,2,2,2,2,2,2,2,2,2,2,2,1
1,2,2,2,2,2,2,2,2,2,2,2,2,2,2,2,2,2,2,2,2,2,2,2,2,2,2,2,1
1,2,2,2,2,2,2,2,2,2,2,2,2,2,2,2,2,2,2,2,2,2,2,2,2,2,2,2,1
1,2,2,2,2,2,2,2,2,2,2,2,2,2,2,2,2,2,2,2,2,2,2,2,2,2,2,2,1
1,2,2,2,2,2,2,2,2,2,2,2,2,2,2,2,2,2,2,2,2,2,2,2,2,2,2,2,1
1,2,2,2,2,2,2,2,2,2,2,2,2,2,2,2,2,2,2,2,2,2,2,2,2,2,2,2,1
1,2,2,2,2,2,2,2,2,2,2,2,2,2,2,2,2,2,2,2,2,2,2,2,2,2,2,2,1
1,2,2,2,2,2,2,2,2,2,2,2,2,2,2,2,2,2,2,2,2,2,2,2,2,2,2,2,1
1,2,2,2,2,2,2,2,2,2,2,2,2,2,2,2,2,2,2,2,2,2,2,2,2,2,2,2,1
1,2,2,2,2,2,2,2,2,2,2,2,2,2,2,2,2,2,2,2,2,2,2,2,2,2,2,2,1
1,2,2,2,2,2,2,2,2,2,2,2,2,2,2,2,2,2,2,2,2,2,2,2,2,2,2,2,1
1,2,2,2,2,2,2,2,2,2,2,2,2,2,2,2,2,2,2,2,2,2,2,2,2,2,2,2,1
1,2,2,2,2,2,2,2,2,2,2,2,2,2,2,2,2,2,2,2,2,2,2,2,2,2,2,2,1
1,2,2,2,2,2,2,2,2,2,2,2,2,2,2,2,2,2,2,2,2,2,2,2,2,2,2,2,1
1,2,2,2,2,2,2,2,2,2,2,2,2,2,2,2,2,2,2,2,2,2,2,2,2,2,2,2,1
1,2,2,2,2,2,2,2,2,2,2,2,2,2,2,2,2,2,2,2,2,2,2,2,2,2,2,2,1
1,2,2,2,2,2,2,2,2,2,2,2,2,2,2,2,2,2,2,2,2,2,2,2,2,2,2,2,1
1,2,2,2,2,2,2,2,2,2,2,2,2,2,2,2,2,2,2,2,2,2,2,2,2,2,2,2,1
1,2,2,2,2,2,2,2,2,2,2,2,2,2,2,2,2,2,2,2,2,2,2,2,2,2,2,2,1
1,2,2,2,2,2,2,2,2,2,2,2,2,2,2,2,2,2,2,2,2,2,2,2,2,2,2,2,1
1,2,2,2,2,2,2,2,2,2,2,2,2,2,2,2,2,2,2,2,2,2,2,2,2,2,2,2,1
1,2,2,2,2,2,2,2,2,2,2,2,2,2,2,2,2,2,2,2,2,2,2,2,2,2,2,2,1
1,2,2,2,2,2,2,2,2,2,2,2,2,2,2,2,2,2,2,2,2,2,2,2,2,2,2,2,1
1,1,2,1,2,2,2,2,2,2,2,2,2,2,2,2,2,2,2,2,2,2,2,2,2,2,2,2,1
1,1,1,1,1,1,1,1,1,1,1,1,1,1,1,1,1,1,1,1,1,1,1,1,1,1,1,1,1
endlayer

layer
3,3,3,3,3,3,3,3,3,3,3,3,3,3,3,3,3,3,3,3,3,3,3,3,3,3,3,3,3
3,1,1,1,1,1,1,1,1,1,1,1,1,1,1,1,1,1,1,1,1,1,1,1,1,1,1,1,3
3,1,2,2,2,2,2,1,2,2,2,2,2,1,2,2,2,2,2,2,2,2,2,2,2,1,2,1,3
3,1,1,2,2,2,2,2,2,2,2,2,2,2,2,2,2,2,2,2,2,2,2,2,2,2,2,1,3
3,1,2,2,2,2,2,2,2,2,2,2,2,2,2,2,2,2,2,2,2,2,2,2,2,2,2,1,3
3,1,1,2,2,2,2,2,2,2,2,2,2,2,2,2,2,2,2,2,2,2,2,2,2,2,2,1,3
3,1,2,2,2,2,2,2,2,2,2,2,2,2,2,2,2,2,2,2,2,2,2,2,2,2,2,1,3
3,1,1,2,2,2,2,2,2,2,2,2,2,2,2,2,2,2,2,2,2,2,2,2,2,2,2,1,3
3,1,2,2,2,2,2,2,2,2,2,2,2,2,2,2,2,2,2,2,2,2,2,2,2,2,2,1,3
3,1,1,2,2,2,2,2,2,2,2,2,2,2,2,2,2,2,2,2,2,2,2,2,2,2,2,1,3
3,1,2,2,2,2,2,2,2,2,2,2,2,2,2,2,2,2,2,2,2,2,2,2,2,2,2,1,3
3,1,1,2,2,2,2,2,2,2,2,2,2,2,2,2,2,2,2,2,2,2,2,2,2,2,2,1,3
3,1,2,2,2,2,2,2,2,2,2,2,2,2,2,2,2,2,2,2,2,2,2,2,2,2,2,1,3
3,1,2,2,2,2,2,2,2,2,2,2,2,2,2,2,2,2,2,2,2,2,2,2,2,2,2,1,3
3,1,2,2,2,2,2,2,2,2,2,2,2,2,2,2,2,2,2,2,2,2,2,2,2,2,2,1,3
3,1,2,2,2,2,2,2,2,2,2,2,2,2,2,2,2,2,2,2,2,2,2,2,2,2,2,1,3
3,1,2,2,2,2,2,2,2,2,2,2,2,2,2,2,2,2,2,2,2,2,2,2,2,2,2,1,3
3,1,2,2,2,2,2,2,2,2,2,2,2,2,2,2,2,2,2,2,2,2,2,2,2,2,2,1,3
3,1,2,2,2,2,2,2,2,2,2,2,2,2,2,2,2,2,2,2,2,2,2,2,2,2,2,1,3
3,1,2,2,2,2,2,2,2,2,2,2,2,2,2,2,2,2,2,2,2,2,2,2,2,2,2,1,3
3,1,2,2,2,2,2,2,2,2,2,2,2,2,2,2,2,2,2,2,2,2,2,2,2,2,2,1,3
3,1,2,2,2,2,2,2,2,2,2,2,2,2,2,2,2,2,2,2,2,2,2,2,2,2,2,1,3
3,1,2,2,2,2,2,2,2,2,2,2,2,2,2,2,2,2,2,2,2,2,2,2,2,2,2,1,3
3,1,2,2,2,2,2,2,2,2,2,2,2,2,2,2,2,2,2,2,2,2,2,2,2,2,2,1,3
3,1,2,2,2,2,2,2,2,2,2,2,2,2,2,2,2,2,2,2,2,2,2,2,2,2,2,1,3
3,1,2,2,2,2,2,2,2,2,2,2,2,2,2,2,2,2,2,2,2,2,2,2,2,2,2,1,3
3,1,1,2,2,2,2,2,2,2,2,2,2,2,2,2,1,2,2,2,2,2,2,2,2,2,2,1,3
3,1,1,1,1,1,1,1,1,1,1,1,1,1,1,1,1,1,1,1,1,1,1,1,1,1,1,1,3
3,3,3,3,3,3,3,3,3,3,3,3,3,3,3,3,3,3,3,3,3,3,3,3,3,3,3,3,3
endlayer

layer
3,3,3,3,3,3,3,3,3,3,3,3,3,3,3,3,3,3,3,3,3,3,3,3,3,3,3,3,3
3,3,3,3,3,3,3,3,3,3,3,3,3,3,3,3,3,3,3,3,3,3,3,3,3,3,3,3,3
3,3,1,1,1,1,1,1,1,1,1,1,1,1,1,1,1,1,1,1,1,1,1,1,1,1,1,3,3
3,3,1,2,1,1,1,1,2,2,2,2,2,2,4,2,2,2,2,2,2,1,1,1,1,2,1,3,3
3,3,1,1,1,1,1,1,1,1,2,4,4,4,4,4,4,4,2,1,1,1,1,1,1,1,1,3,3
3,3,1,1,1,1,1,1,1,1,2,4,5,5,5,5,5,4,2,1,1,1,1,1,1,1,1,3,3
3,3,1,1,1,1,1,1,1,1,2,4,5,6,6,6,5,4,2,1,1,1,1,1,1,1,1,3,3
3,3,1,1,1,1,1,1,1,1,4,4,5,6,6,6,5,4,4,1,1,1,1,1,1,1,1,3,3
3,3,1,2,1,1,1,1,1,1,2,4,5,6,6,6,5,4,2,1,1,1,1,1,1,2,1,3,3
3,3,1,2,1,1,1,1,1,1,2,4,5,5,5,5,5,4,2,1,1,1,1,1,1,2,1,3,3
3,3,1,2,2,2,2,4,2,2,2,4,4,4,4,4,4,4,2,2,2,4,2,2,2,2,1,3,3
3,3,1,2,4,4,4,4,4,4,4,2,2,2,7,2,2,2,4,4,4,4,4,4,4,2,1,3,3
3,3,1,2,4,5,5,5,5,5,4,2,7,7,7,7,7,2,4,5,5,5,5,5,4,2,1,3,3
3,3,1,2,4,5,6,6,6,5,4,2,7,5,5,5,7,2,4,5,6,6,6,5,4,2,1,3,3
3,3,1,4,4,5,6,6,6,5,4,7,7,5,5,5,7,7,4,5,6,6,6,5,4,4,1,3,3
3,3,1,2,4,5,6,6,6,5,4,2,7,5,5,5,7,2,4,5,6,6,6,5,4,2,1,3,3
3,3,1,2,4,5,5,5,5,5,4,2,7,7,7,7,7,2,4,5,5,5,5,5,4,2,1,3,3
3,3,1,2,4,4,4,4,4,4,4,2,2,2,7,2,2,2,4,4,4,4,4,4,4,2,1,3,3
3,3,1,2,2,2,2,4,2,2,2,4,4,4,4,4,4,4,2,2,2,4,2,2,2,2,1,3,3
3,3,1,2,1,1,1,1,1,1,2,4,5,5,5,5,5,4,2,1,1,1,1,1,1,2,1,3,3
3,3,1,2,1,1,1,1,1,1,2,4,5,6,6,6,5,4,2,1,1,1,1,1,1,2,1,3,3
3,3,1,1,1,1,1,1,1,1,4,4,5,6,6,6,5,4,4,1,1,1,1,1,1,1,1,3,3
3,3,1,1,1,1,1,1,1,1,2,4,5,6,6,6,5,4,2,1,1,1,1,1,1,1,1,3,3
3,3,1,1,1,1,1,1,1,1,2,4,5,5,5,5,5,4,2,1,1,1,1,1,1,1,1,3,3
3,3,1,1,1,1,1,1,1,1,2,4,4,4,4,4,4,4,2,1,1,1,1,1,1,1,1,3,3
3,3,1,2,1,1,1,1,2,2,2,2,2,2,4,2,2,2,2,2,2,1,1,1,1,2,1,3,3
3,3,1,1,1,1,1,1,1,1,1,1,1,1,1,1,1,1,1,1,1,1,1,1,1,1,1,3,3
3,3,3,3,3,3,3,3,3,3,3,3,3,3,3,3,3,3,3,3,3,3,3,3,3,3,3,3,3
3,3,3,3,3,3,3,3,3,3,3,3,3,3,3,3,3,3,3,3,3,3,3,3,3,3,3,3,3
endlayer

layer
3,3,3,3,3,3,3,3,3,3,3,3,3,3,3,3,3,3,3,3,3,3,3,3,3,3,3,3,3
3,3,3,3,3,3,3,3,3,3,3,3,3,3,3,3,3,3,3,3,3,3,3,3,3,3,3,3,3
3,3,3,3,3,3,3,3,3,3,3,3,3,3,3,3,3,3,3,3,3,3,3,3,3,3,3,3,3
3,3,3,5,0,0,0,0,7,7,7,7,7,7,8,7,7,7,7,7,7,0,0,0,0,5,3,3,3
3,3,3,0,9,0,0,10,0,0,7,0,0,0,0,0,0,0,7,9,0,0,0,0,0,0,3,3,3
3,3,3,0,0,0,0,0,0,0,7,0,0,0,0,0,0,0,7,0,0,10,0,0,10,0,3,3,3
3,3,3,0,0,0,0,0,0,0,7,0,0,0,0,0,0,0,7,0,0,0,0,0,0,0,3,3,3
3,3,3,0,10,0,0,0,10,0,13,0,0,0,12,0,0,0,11,0,0,0,0,0,0,0,3,3,3
3,3,3,7,0,0,10,0,0,0,7,0,0,0,0,0,0,0,7,0,0,0,0,10,0,7,3,3,3
3,3,3,7,0,0,0,0,0,0,7,0,0,0,0,0,0,0,7,0,10,0,0,0,0,7,3,3,3
3,3,3,7,7,7,7,8,7,7,7,0,0,0,0,0,0,0,7,7,7,8,7,7,7,7,3,3,3
3,3,3,7,0,0,0,0,0,0,0,7,7,7,0,7,7,7,0,0,0,0,0,0,0,7,3,3,3
3,3,3,7,0,0,0,0,0,0,0,7,0,0,0,0,0,7,0,0,0,0,0,0,0,7,3,3,3
3,3,3,7,0,0,0,0,0,0,0,7,0,0,14,0,0,7,0,0,0,0,0,0,0,7,3,3,3
3,3,3,13,0,0,0,12,0,0,0,0,0,17,16,15,0,0,0,0,0,12,0,0,0,11,3,3,3
3,3,3,7,0,0,0,0,0,0,0,7,0,0,18,0,0,7,0,0,0,0,0,0,0,7,3,3,3
3,3,3,7,0,0,0,0,0,0,0,7,0,0,0,0,0,7,0,0,0,0,0,0,0,7,3,3,3
3,3,3,7,0,0,0,0,0,0,0,7,7,7,0,7,7,7,0,0,0,0,0,0,0,7,3,3,3
3,3,3,7,7,7,7,19,7,7,7,0,0,0,0,0,0,0,7,7,7,19,7,7,7,7,3,3,3
3,3,3,7,0,0,0,0,0,0,7,0,0,0,0,0,0,0,7,0,0,0,0,0,0,7,3,3,3
3,3,3,7,0,0,0,0,10,0,7,0,0,0,0,0,0,0,7,0,10,0,0,0,10,7,3,3,3
3,3,3,0,10,0,0,0,0,0,13,0,0,0,12,0,0,0,11,0,0,0,0,0,0,0,3,3,3
3,3,3,0,0,0,10,0,0,0,7,0,0,0,0,0,0,0,7,0,0,10,0,0,0,0,3,3,3
3,3,3,0,0,0,0,0,0,0,7,0,0,0,0,0,0,0,7,20,0,0,0,10,0,0,3,3,3
3,3,3,0,0,0,0,0,0,0,7,0,0,0,0,0,0,0,7,9,20,0,0,0,0,0,3,3,3
3,3,3,5,0,0,0,10,7,7,7,7,7,7,19,7,7,7,7,7,7,0,0,0,0,5,3,3,3
3,3,3,3,3,3,3,3,3,3,3,3,3,3,3,3,3,3,3,3,3,3,3,3,3,3,3,3,3
3,3,3,3,3,3,3,3,3,3,3,3,3,3,3,3,3,3,3,3,3,3,3,3,3,3,3,3,3
3,3,3,3,3,3,3,3,3,3,3,3,3,3,3,3,3,3,3,3,3,3,3,3,3,3,3,3,3
endlayer

layer
3,3,3,3,3,3,3,3,3,3,3,3,3,3,3,3,3,3,3,3,3,3,3,3,3,3,3,3,3
3,3,3,3,3,3,3,3,3,3,3,3,3,3,3,3,3,3,3,3,3,3,3,3,3,3,3,3,3
3,3,3,3,3,3,3,3,3,3,3,3,3,3,3,3,3,3,3,3,3,3,3,3,3,3,3,3,3
3,3,3,5,20,0,0,0,7,7,7,7,21,7,22,7,21,7,7,7,7,0,0,0,0,5,3,3,3
3,3,3,20,9,20,0,0,0,0,7,0,0,0,0,0,0,0,7,9,0,0,0,0,0,0,3,3,3
3,3,3,0,20,0,0,0,0,24,7,23,0,0,0,0,0,24,7,23,0,0,0,0,0,0,3,3,3
3,3,3,0,0,0,0,0,0,0,7,0,0,0,0,0,0,0,7,0,0,0,0,0,0,0,3,3,3
3,3,3,0,0,0,0,0,0,0,26,0,0,0,25,0,0,0,22,0,0,0,0,0,0,0,3,3,3
3,3,3,7,0,0,0,0,0,0,7,0,0,0,0,0,0,0,7,0,0,0,0,0,0,7,3,3,3
3,3,3,7,0,27,0,0,0,0,7,23,0,0,0,0,0,24,7,0,0,0,0,27,0,7,3,3,3
3,3,3,7,7,7,7,22,7,7,7,0,0,0,0,0,0,0,7,7,7,26,7,7,7,7,3,3,3
3,3,3,7,0,28,0,0,0,28,0,7,7,7,0,7,7,7,0,28,0,0,0,28,0,7,3,3,3
3,3,3,21,0,0,0,0,0,0,0,7,0,0,0,0,0,7,0,0,0,0,0,0,0,21,3,3,3
3,3,3,7,0,0,0,0,0,0,0,7,0,0,0,0,0,7,0,0,0,0,0,0,0,7,3,3,3
3,3,3,22,0,0,0,25,0,0,0,0,0,0,0,0,0,0,0,0,0,25,0,0,0,22,3,3,3
3,3,3,7,0,0,0,0,0,0,0,7,0,0,0,0,0,7,0,0,0,0,0,0,0,7,3,3,3
3,3,3,21,0,0,0,0,0,0,0,7,0,0,0,0,0,7,0,0,0,0,0,0,0,21,3,3,3
3,3,3,7,0,27,0,0,0,27,0,7,7,7,0,7,7,7,0,27,0,0,0,27,0,7,3,3,3
3,3,3,7,7,7,7,26,7,7,7,0,0,0,0,0,0,0,7,7,7,22,7,7,7,7,3,3,3
3,3,3,7,0,28,0,0,0,0,7,23,0,0,0,0,0,24,7,0,0,0,0,28,0,7,3,3,3
3,3,3,7,0,0,0,0,0,0,7,0,0,0,0,0,0,0,7,0,0,0,0,0,0,7,3,3,3
3,3,3,0,0,0,0,0,0,0,22,0,0,0,25,0,0,0,26,0,0,0,0,0,0,0,3,3,3
3,3,3,0,0,0,0,0,0,0,7,0,0,0,0,0,0,0,7,0,0,0,0,0,0,0,3,3,3
3,3,3,0,0,0,0,0,0,24,7,23,0,0,0,0,0,24,7,23,0,0,0,0,0,0,3,3,3
3,3,3,0,0,0,0,0,0,0,7,0,0,0,0,0,0,0,7,20,0,0,0,0,0,0,3,3,3
3,3,3,5,0,0,0,0,7,7,7,7,21,7,22,7,21,7,7,7,7,0,0,0,0,5,3,3,3
3,3,3,3,3,3,3,3,3,3,3,3,3,3,3,3,3,3,3,3,3,3,3,3,3,3,3,3,3
3,3,3,3,3,3,3,3,3,3,3,3,3,3,3,3,3,3,3,3,3,3,3,3,3,3,3,3,3
3,3,3,3,3,3,3,3,3,3,3,3,3,3,3,3,3,3,3,3,3,3,3,3,3,3,3,3,3
endlayer

layer
3,3,3,3,3,3,3,3,3,3,3,3,3,3,3,3,3,3,3,3,3,3,3,3,3,3,3,3,3
3,3,3,3,3,3,3,3,3,3,3,3,3,3,3,3,3,3,3,3,3,3,3,3,3,3,3,3,3
3,3,3,3,3,3,3,3,3,3,3,3,3,3,3,3,3,3,3,3,3,3,3,3,3,3,3,3,3
3,3,3,5,7,0,0,7,7,7,7,7,21,7,7,7,21,7,7,7,7,7,0,0,7,5,3,3,3
3,3,3,7,20,0,0,0,0,0,7,0,0,0,0,0,0,0,7,20,20,0,0,0,0,7,3,3,3
3,3,3,0,0,0,0,0,0,0,7,0,0,0,0,0,0,0,7,20,0,0,0,0,0,0,3,3,3
3,3,3,0,0,0,0,0,0,0,7,0,0,0,0,0,0,0,7,0,0,0,0,0,0,0,3,3,3
3,3,3,7,0,0,0,0,0,0,7,0,0,0,25,0,0,0,7,0,0,0,0,0,0,7,3,3,3
3,3,3,7,0,0,0,0,0,0,7,0,0,0,0,0,0,0,7,0,0,0,0,0,0,7,3,3,3
3,3,3,7,0,0,0,0,0,0,7,0,0,0,0,0,0,0,7,0,0,0,0,0,0,7,3,3,3
3,3,3,7,7,7,7,7,7,7,7,0,0,0,0,0,0,0,7,7,7,7,7,7,7,7,3,3,3
3,3,3,7,0,0,0,0,0,0,0,7,7,7,0,7,7,7,0,0,0,0,0,0,0,7,3,3,3
3,3,3,21,0,0,0,0,0,0,0,7,0,0,0,0,0,7,0,0,0,0,0,0,0,21,3,3,3
3,3,3,7,0,0,0,0,0,0,0,7,0,0,0,0,0,7,0,0,0,0,0,0,0,7,3,3,3
3,3,3,7,0,0,0,25,0,0,0,0,0,0,0,0,0,0,0,0,0,25,0,0,0,7,3,3,3
3,3,3,7,0,0,0,0,0,0,0,7,0,0,0,0,0,7,0,0,0,0,0,0,0,7,3,3,3
3,3,3,21,0,0,0,0,0,0,0,7,0,0,0,0,0,7,0,0,0,0,0,0,0,21,3,3,3
3,3,3,7,0,0,0,0,0,0,0,7,7,7,0,7,7,7,0,0,0,0,0,0,0,7,3,3,3
3,3,3,7,7,7,7,7,7,7,7,0,0,0,0,0,0,0,7,7,7,7,7,7,7,7,3,3,3
3,3,3,7,0,0,0,0,0,0,7,0,0,0,0,0,0,0,7,0,0,0,0,0,0,7,3,3,3
3,3,3,7,0,0,0,0,0,0,7,0,0,0,0,0,0,0,7,0,0,0,0,0,0,7,3,3,3
3,3,3,7,0,0,0,0,0,0,7,0,0,0,25,0,0,0,7,0,0,0,0,0,0,7,3,3,3
3,3,3,0,0,0,0,0,0,0,7,0,0,0,0,0,0,0,7,0,0,0,0,0,0,0,3,3,3
3,3,3,0,0,0,0,0,0,0,7,0,0,0,0,0,0,0,7,0,0,0,0,0,0,0,3,3,3
3,3,3,7,0,0,0,0,0,0,7,0,0,0,0,0,0,0,7,0,0,0,0,0,0,7,3,3,3
3,3,3,5,7,0,0,7,7,7,7,7,21,7,7,7,21,7,7,7,7,7,0,0,7,5,3,3,3
3,3,3,3,3,3,3,3,3,3,3,3,3,3,3,3,3,3,3,3,3,3,3,3,3,3,3,3,3
3,3,3,3,3,3,3,3,3,3,3,3,3,3,3,3,3,3,3,3,3,3,3,3,3,3,3,3,3
3,3,3,3,3,3,3,3,3,3,3,3,3,3,3,3,3,3,3,3,3,3,3,3,3,3,3,3,3
endlayer

layer
3,3,3,3,3,3,3,3,3,3,3,3,3,3,3,3,3,3,3,3,3,3,3,3,3,3,3,3,3
3,3,3,3,3,3,3,3,3,3,3,3,3,3,3,3,3,3,3,3,3,3,3,3,3,3,3,3,3
3,3,3,3,3,3,3,3,3,3,3,3,3,3,3,3,3,3,3,3,3,3,3,3,3,3,3,3,3
3,3,3,5,7,7,7,7,7,7,7,7,7,7,7,7,7,7,7,7,7,7,7,7,7,5,3,3,3
3,3,3,7,0,0,0,0,0,0,7,0,0,0,0,0,0,0,7,20,0,0,0,0,0,7,3,3,3
3,3,3,7,0,0,0,0,0,0,7,0,0,0,0,0,0,0,7,0,0,0,0,0,0,7,3,3,3
3,3,3,7,0,0,0,0,0,0,7,0,0,0,0,0,0,0,7,0,0,0,0,0,0,7,3,3,3
3,3,3,7,0,0,0,0,0,0,7,0,0,0,0,0,0,0,7,0,0,0,0,0,0,7,3,3,3
3,3,3,7,0,0,0,0,0,0,7,0,0,0,0,0,0,0,7,0,0,0,0,0,0,7,3,3,3
3,3,3,7,0,0,0,0,0,0,7,0,0,0,0,0,0,0,7,0,0,0,0,0,0,7,3,3,3
3,3,3,7,7,7,7,7,7,7,7,0,0,0,0,0,0,0,7,7,7,7,7,7,7,7,3,3,3
3,3,3,7,0,0,0,0,0,0,0,7,7,7,7,7,7,7,0,0,0,0,0,0,0,7,3,3,3
3,3,3,7,0,0,0,0,0,0,0,7,0,0,0,0,0,7,0,0,0,0,0,0,0,7,3,3,3
3,3,3,7,0,0,0,0,0,0,0,7,0,0,0,0,0,7,0,0,0,0,0,0,0,7,3,3,3
3,3,3,7,0,0,0,0,0,0,0,7,0,0,0,0,0,7,0,0,0,0,0,0,0,7,3,3,3
3,3,3,7,0,0,0,0,0,0,0,7,0,0,0,0,0,7,0,0,0,0,0,0,0,7,3,3,3
3,3,3,7,0,0,0,0,0,0,0,7,0,0,0,0,0,7,0,0,0,0,0,0,0,7,3,3,3
3,3,3,7,0,0,0,0,0,0,0,7,7,7,7,7,7,7,0,0,0,0,0,0,0,7,3,3,3
3,3,3,7,7,7,7,7,7,7,7,0,0,0,0,0,0,0,7,7,7,7,7,7,7,7,3,3,3
3,3,3,7,0,0,0,0,0,0,7,0,0,0,0,0,0,0,7,0,0,0,0,0,0,7,3,3,3
3,3,3,7,0,0,0,0,0,0,7,0,0,0,0,0,0,0,7,0,0,0,0,0,0,7,3,3,3
3,3,3,7,0,0,0,0,0,0,7,0,0,0,0,0,0,0,7,0,0,0,0,0,0,7,3,3,3
3,3,3,7,0,0,0,0,0,0,7,0,0,0,0,0,0,0,7,0,0,0,0,0,0,7,3,3,3
3,3,3,7,0,0,0,0,0,0,7,0,0,0,0,0,0,0,7,0,0,0,0,0,0,7,3,3,3
3,3,3,7,0,0,0,0,0,0,7,0,0,0,0,0,0,0,7,0,0,0,0,0,0,7,3,3,3
3,3,3,5,7,7,7,7,7,7,7,7,7,7,7,7,7,7,7,7,7,7,7,7,7,5,3,3,3
3,3,3,3,3,3,3,3,3,3,3,3,3,3,3,3,3,3,3,3,3,3,3,3,3,3,3,3,3
3,3,3,3,3,3,3,3,3,3,3,3,3,3,3,3,3,3,3,3,3,3,3,3,3,3,3,3,3
3,3,3,3,3,3,3,3,3,3,3,3,3,3,3,3,3,3,3,3,3,3,3,3,3,3,3,3,3
endlayer

layer
3,3,3,3,3,3,3,3,3,3,3,3,3,3,3,3,3,3,3,3,3,3,3,3,3,3,3,3,3
3,3,3,3,3,3,3,3,3,3,3,3,3,3,3,3,3,3,3,3,3,3,3,3,3,3,3,3,3
3,3,3,3,3,3,3,3,3,3,3,3,3,3,3,3,3,3,3,3,3,3,3,3,3,3,3,3,3
3,3,3,5,6,6,6,6,6,6,7,7,7,7,7,7,7,7,7,6,6,6,6,6,6,5,3,3,3
3,3,3,6,6,6,6,6,6,6,6,6,6,6,6,6,6,6,6,6,6,6,6,6,6,6,3,3,3
3,3,3,6,6,6,6,6,6,6,6,6,6,6,6,6,6,6,6,6,6,6,6,6,6,6,3,3,3
3,3,3,6,6,6,6,6,6,6,6,6,6,6,6,6,6,6,6,6,6,6,6,6,6,6,3,3,3
3,3,3,6,6,6,6,6,6,6,6,6,6,6,6,6,6,6,6,6,6,6,6,6,6,6,3,3,3
3,3,3,6,6,6,6,6,6,6,6,6,6,6,6,6,6,6,6,6,6,6,6,6,6,6,3,3,3
3,3,3,6,6,6,6,6,6,6,6,6,6,6,6,6,6,6,6,6,6,6,6,6,6,6,3,3,3
3,3,3,7,6,6,6,6,6,6,6,6,6,6,6,6,6,6,6,6,6,6,6,6,6,7,3,3,3
3,3,3,7,6,6,6,6,6,6,6,6,6,6,6,6,6,6,6,6,6,6,6,6,6,7,3,3,3
3,3,3,7,6,6,6,6,6,6,6,6,29,29,29,29,29,6,6,6,6,6,6,6,6,7,3,3,3
3,3,3,7,6,6,6,6,6,6,6,6,29,0,0,0,29,6,6,6,6,6,6,6,6,7,3,3,3
3,3,3,7,6,6,6,6,6,6,6,6,29,0,0,0,29,6,6,6,6,6,6,6,6,7,3,3,3
3,3,3,7,6,6,6,6,6,6,6,6,29,0,0,0,29,6,6,6,6,6,6,6,6,7,3,3,3
3,3,3,7,6,6,6,6,6,6,6,6,29,29,29,29,29,6,6,6,6,6,6,6,6,7,3,3,3
3,3,3,7,6,6,6,6,6,6,6,6,6,6,6,6,6,6,6,6,6,6,6,6,6,7,3,3,3
3,3,3,7,6,6,6,6,6,6,6,6,6,6,6,6,6,6,6,6,6,6,6,6,6,7,3,3,3
3,3,3,6,6,6,6,6,6,6,6,6,6,6,6,6,6,6,6,6,6,6,6,6,6,6,3,3,3
3,3,3,6,6,6,6,6,6,6,6,6,6,6,6,6,6,6,6,6,6,6,6,6,6,6,3,3,3
3,3,3,6,6,6,6,6,6,6,6,6,6,6,6,6,6,6,6,6,6,6,6,6,6,6,3,3,3
3,3,3,6,6,6,6,6,6,6,6,6,6,6,6,6,6,6,6,6,6,6,6,6,6,6,3,3,3
3,3,3,6,6,6,6,6,6,6,6,6,6,6,6,6,6,6,6,6,6,6,6,6,6,6,3,3,3
3,3,3,6,6,6,6,6,6,6,6,6,6,6,6,6,6,6,6,6,6,6,6,6,6,6,3,3,3
3,3,3,5,6,6,6,6,6,6,7,7,7,7,7,7,7,7,7,6,6,6,6,6,6,5,3,3,3
3,3,3,3,3,3,3,3,3,3,3,3,3,3,3,3,3,3,3,3,3,3,3,3,3,3,3,3,3
3,3,3,3,3,3,3,3,3,3,3,3,3,3,3,3,3,3,3,3,3,3,3,3,3,3,3,3,3
3,3,3,3,3,3,3,3,3,3,3,3,3,3,3,3,3,3,3,3,3,3,3,3,3,3,3,3,3
endlayer

layer
3,3,3,3,3,3,3,3,3,3,3,3,3,3,3,3,3,3,3,3,3,3,3,3,3,3,3,3,3
3,3,3,3,3,3,3,3,3,3,3,3,3,3,3,3,3,3,3,3,3,3,3,3,3,3,3,3,3
3,3,3,3,3,3,3,3,3,3,3,3,3,3,3,3,3,3,3,3,3,3,3,3,3,3,3,3,3
3,3,3,5,5,5,5,5,5,5,6,6,6,7,7,7,6,6,6,5,5,5,5,5,5,5,3,3,3
3,3,3,5,0,0,0,0,0,0,7,0,0,0,0,0,0,0,7,0,0,0,0,0,0,5,3,3,3
3,3,3,5,0,0,0,0,0,0,7,0,0,0,0,0,0,0,7,0,0,0,0,0,0,5,3,3,3
3,3,3,5,0,0,0,0,0,0,0,0,0,0,0,0,0,0,0,0,0,0,0,0,0,5,3,3,3
3,3,3,5,0,0,12,0,0,0,0,0,0,0,12,0,0,0,0,0,0,12,0,0,0,5,3,3,3
3,3,3,5,0,0,0,0,0,0,7,0,0,0,0,0,0,0,7,0,0,0,0,0,0,5,3,3,3
3,3,3,5,0,0,0,0,0,0,7,0,0,0,0,0,0,0,7,0,0,0,0,0,0,5,3,3,3
3,3,3,6,7,7,0,0,7,7,7,7,7,0,0,0,7,7,7,7,7,0,0,7,7,6,3,3,3
3,3,3,6,0,0,0,0,0,0,7,0,0,0,0,0,0,0,7,0,0,0,0,0,0,6,3,3,3
3,3,3,6,0,0,0,0,0,0,7,0,0,0,0,0,0,0,7,0,0,0,0,0,0,6,3,3,3
3,3,3,7,0,0,0,0,0,0,0,0,0,0,0,0,0,0,0,0,0,0,0,0,0,7,3,3,3
3,3,3,7,0,0,12,0,0,0,0,0,0,0,0,0,0,0,0,0,0,12,0,0,0,7,3,3,3
3,3,3,7,0,0,0,0,0,0,0,0,0,0,0,0,0,0,0,0,0,0,0,0,0,7,3,3,3
3,3,3,6,0,0,0,0,0,0,7,0,0,0,0,0,0,0,7,0,0,0,0,0,0,6,3,3,3
3,3,3,6,0,0,0,0,0,0,7,0,0,0,0,0,0,0,7,0,0,0,0,0,0,6,3,3,3
3,3,3,6,7,7,0,0,7,7,7,7,7,0,0,0,7,7,7,7,7,0,0,7,7,6,3,3,3
3,3,3,5,0,0,0,0,0,0,7,0,0,0,0,0,0,0,7,0,0,0,0,0,0,5,3,3,3
3,3,3,5,0,0,0,0,0,0,7,0,0,0,0,0,0,0,7,0,0,0,0,0,0,5,3,3,3
3,3,3,5,0,0,0,0,0,0,0,0,0,0,0,0,0,0,0,0,0,0,0,0,0,5,3,3,3
3,3,3,5,0,0,30,0,0,0,0,0,0,0,12,0,0,0,0,0,0,12,0,0,0,5,3,3,3
3,3,3,5,0,0,0,0,0,0,7,0,0,0,0,0,0,0,7,0,0,0,0,0,0,5,3,3,3
3,3,3,5,0,0,0,0,0,0,7,0,0,0,0,0,0,0,7,0,0,0,0,0,0,5,3,3,3
3,3,3,5,5,5,5,5,5,5,6,6,6,7,7,7,6,6,6,5,5,5,5,5,5,5,3,3,3
3,3,3,3,3,3,3,3,3,3,3,3,3,3,3,3,3,3,3,3,3,3,3,3,3,3,3,3,3
3,3,3,3,3,3,3,3,3,3,3,3,3,3,3,3,3,3,3,3,3,3,3,3,3,3,3,3,3
3,3,3,3,3,3,3,3,3,3,3,3,3,3,3,3,3,3,3,3,3,3,3,3,3,3,3,3,3
endlayer

layer
3,3,3,3,3,3,3,3,3,3,3,3,3,3,3,3,3,3,3,3,3,3,3,3,3,3,3,3,3
3,3,3,3,3,3,3,3,3,3,3,3,3,3,3,3,3,3,3,3,3,3,3,3,3,3,3,3,3
3,3,3,3,3,3,3,3,3,3,3,3,3,3,3,3,3,3,3,3,3,3,3,3,3,3,3,3,3
3,3,3,4,4,4,31,31,4,4,5,5,21,6,6,6,21,5,5,4,4,31,31,4,4,4,3,3,3
3,3,3,4,0,0,0,0,0,0,7,0,0,0,0,0,0,0,7,0,0,0,0,0,0,4,3,3,3
3,3,3,4,0,0,0,0,0,24,7,23,0,0,0,0,0,24,7,23,0,0,0,0,0,4,3,3,3
3,3,3,31,0,0,0,0,0,0,0,0,0,0,0,0,0,0,0,0,0,0,0,0,0,31,3,3,3
3,3,3,31,0,0,25,0,0,0,0,0,0,0,25,0,0,0,0,0,0,25,0,0,0,31,3,3,3
3,3,3,4,0,0,0,0,0,24,7,23,0,0,0,0,0,24,7,23,0,0,0,0,0,4,3,3,3
3,3,3,4,0,27,0,0,27,0,7,0,0,0,0,0,0,0,7,0,27,0,0,27,0,4,3,3,3
3,3,3,5,7,7,0,0,7,7,7,7,7,0,0,0,7,7,7,7,7,0,0,7,7,5,3,3,3
3,3,3,5,0,28,0,0,28,0,7,0,0,0,0,0,0,0,7,0,28,0,0,28,0,5,3,3,3
3,3,3,21,0,0,0,0,0,0,7,0,0,0,0,0,0,0,7,0,0,0,0,0,0,21,3,3,3
3,3,3,6,0,0,0,0,0,0,0,0,0,0,0,0,0,0,0,0,0,0,0,0,0,6,3,3,3
3,3,3,6,0,0,25,0,0,0,0,0,0,0,0,0,0,0,0,0,0,25,0,0,0,6,3,3,3
3,3,3,6,0,0,0,0,0,0,0,0,0,0,0,0,0,0,0,0,0,0,0,0,0,6,3,3,3
3,3,3,21,0,0,0,0,0,0,7,0,0,0,0,0,0,0,7,0,0,0,0,0,0,21,3,3,3
3,3,3,5,0,27,0,0,27,0,7,0,0,0,0,0,0,0,7,0,27,0,0,27,0,5,3,3,3
3,3,3,5,7,7,0,0,7,7,7,7,7,0,0,0,7,7,7,7,7,0,0,7,7,5,3,3,3
3,3,3,4,0,28,0,0,28,0,7,0,0,0,0,0,0,0,7,0,28,0,0,28,0,4,3,3,3
3,3,3,4,0,0,0,0,0,24,7,23,0,0,0,0,0,24,7,23,0,0,0,0,0,4,3,3,3
3,3,3,31,0,0,0,0,0,0,0,0,0,0,0,0,0,0,0,0,0,0,0,0,0,31,3,3,3
3,3,3,31,0,0,25,0,0,0,0,0,0,0,25,0,0,0,0,0,0,25,0,0,0,31,3,3,3
3,3,3,4,0,0,0,0,0,24,7,23,0,0,0,0,0,24,7,23,0,0,0,0,0,4,3,3,3
3,3,3,4,0,0,0,0,0,0,7,0,0,0,0,0,0,0,7,0,0,0,0,0,0,4,3,3,3
3,3,3,4,4,4,31,31,4,4,5,5,21,6,6,6,21,5,5,4,4,31,31,4,4,4,3,3,3
3,3,3,3,3,3,3,3,3,3,3,3,3,3,3,3,3,3,3,3,3,3,3,3,3,3,3,3,3
3,3,3,3,3,3,3,3,3,3,3,3,3,3,3,3,3,3,3,3,3,3,3,3,3,3,3,3,3
3,3,3,3,3,3,3,3,3,3,3,3,3,3,3,3,3,3,3,3,3,3,3,3,3,3,3,3,3
endlayer

layer
3,3,3,3,3,3,3,3,3,3,3,3,3,3,3,3,3,3,3,3,3,3,3,3,3,3,3,3,3
3,3,3,3,3,3,3,3,3,3,3,3,3,3,3,3,3,3,3,3,3,3,3,3,3,3,3,3,3
3,3,3,3,3,3,3,3,3,3,3,3,3,3,3,3,3,3,3,3,3,3,3,3,3,3,3,3,3
3,3,3,4,6,7,21,21,7,7,4,4,31,5,5,5,31,4,4,7,7,21,21,7,6,4,3,3,3
3,3,3,6,0,0,0,0,0,0,7,0,0,0,0,0,0,0,7,0,0,0,0,0,0,6,3,3,3
3,3,3,7,0,0,0,0,0,0,7,0,0,0,0,0,0,0,7,0,0,0,0,0,0,7,3,3,3
3,3,3,21,0,0,25,0,0,0,0,0,0,0,0,0,0,0,0,0,0,25,0,0,0,21,3,3,3
3,3,3,21,0,0,0,0,0,0,0,0,0,0,0,0,0,0,0,0,0,0,0,0,0,21,3,3,3
3,3,3,7,0,0,0,0,0,0,7,0,0,0,0,0,0,0,7,0,0,0,0,0,0,7,3,3,3
3,3,3,7,0,0,0,0,0,0,7,0,0,0,0,0,0,0,7,0,0,0,0,0,0,7,3,3,3
3,3,3,4,7,7,0,0,7,7,7,7,7,0,0,0,7,7,7,7,7,0,0,7,7,4,3,3,3
3,3,3,4,0,0,0,0,0,0,7,0,0,0,0,0,0,0,7,0,0,0,0,0,0,4,3,3,3
3,3,3,31,0,0,0,0,0,0,7,0,0,0,0,0,0,0,7,0,0,0,0,0,0,31,3,3,3
3,3,3,5,0,0,0,0,0,0,0,0,0,0,0,0,0,0,0,0,0,0,0,0,0,5,3,3,3
3,3,3,5,0,0,0,0,0,0,0,0,0,0,0,0,0,0,0,0,0,0,0,0,0,5,3,3,3
3,3,3,5,0,0,0,0,0,0,0,0,0,0,0,0,0,0,0,0,0,0,0,0,0,5,3,3,3
3,3,3,31,0,0,0,0,0,0,7,0,0,0,0,0,0,0,7,0,0,0,0,0,0,31,3,3,3
3,3,3,4,0,0,0,0,0,0,7,0,0,0,0,0,0,0,7,0,0,0,0,0,0,4,3,3,3
3,3,3,4,7,7,0,0,7,7,7,7,7,0,0,0,7,7,7,7,7,0,0,7,7,4,3,3,3
3,3,3,7,0,0,0,0,0,0,7,0,0,0,0,0,0,0,7,0,0,0,0,0,0,7,3,3,3
3,3,3,7,0,0,0,0,0,0,7,0,0,0,0,0,0,0,7,0,0,0,0,0,0,7,3,3,3
3,3,3,21,0,0,25,0,0,0,0,0,0,0,0,0,0,0,0,0,0,25,0,0,0,21,3,3,3
3,3,3,21,0,0,0,0,0,0,0,0,0,0,0,0,0,0,0,0,0,0,0,0,0,21,3,3,3
3,3,3,7,0,0,0,0,0,0,7,0,0,0,0,0,0,0,7,0,0,0,0,0,0,7,3,3,3
3,3,3,6,0,0,0,0,0,0,7,0,0,0,0,0,0,0,7,0,0,0,0,0,0,6,3,3,3
3,3,3,4,6,7,21,21,7,7,4,4,31,5,5,5,31,4,4,7,7,21,21,7,6,4,3,3,3
3,3,3,3,3,3,3,3,3,3,3,3,3,3,3,3,3,3,3,3,3,3,3,3,3,3,3,3,3
3,3,3,3,3,3,3,3,3,3,3,3,3,3,3,3,3,3,3,3,3,3,3,3,3,3,3,3,3
3,3,3,3,3,3,3,3,3,3,3,3,3,3,3,3,3,3,3,3,3,3,3,3,3,3,3,3,3
endlayer

layer
3,3,3,3,3,3,3,3,3,3,3,3,3,3,3,3,3,3,3,3,3,3,3,3,3,3,3,3,3
3,3,3,3,3,3,3,3,3,3,3,3,3,3,3,3,3,3,3,3,3,3,3,3,3,3,3,3,3
3,3,3,3,3,3,3,3,3,3,3,3,3,3,3,3,3,3,3,3,3,3,3,3,3,3,3,3,3
3,3,3,4,6,7,7,7,7,7,7,7,7,4,4,4,7,7,7,7,7,7,7,7,6,4,3,3,3
3,3,3,6,0,0,0,0,0,0,7,0,0,0,0,0,0,0,7,0,0,0,0,0,0,6,3,3,3
3,3,3,7,0,0,0,0,0,0,7,0,0,0,0,0,0,0,7,0,0,0,0,0,0,7,3,3,3
3,3,3,7,0,0,0,0,0,0,7,0,0,0,0,0,0,0,7,0,0,0,0,0,0,7,3,3,3
3,3,3,7,0,0,0,0,0,0,7,0,0,0,0,0,0,0,7,0,0,0,0,0,0,7,3,3,3
3,3,3,7,0,0,0,0,0,0,7,0,0,0,0,0,0,0,7,0,0,0,0,0,0,7,3,3,3
3,3,3,7,0,0,0,0,0,0,7,0,0,0,0,0,0,0,7,0,0,0,0,0,0,7,3,3,3
3,3,3,7,7,7,7,7,7,7,7,7,7,7,7,7,7,7,7,7,7,7,7,7,7,7,3,3,3
3,3,3,7,0,0,0,0,0,0,7,0,0,0,0,0,0,0,7,0,0,0,0,0,0,7,3,3,3
3,3,3,7,0,0,0,0,0,0,7,0,0,0,0,0,0,0,7,0,0,0,0,0,0,7,3,3,3
3,3,3,4,0,0,0,0,0,0,7,0,0,0,0,0,0,0,7,0,0,0,0,0,0,4,3,3,3
3,3,3,4,0,0,0,0,0,0,7,0,0,0,0,0,0,0,7,0,0,0,0,0,0,4,3,3,3
3,3,3,4,0,0,0,0,0,0,7,0,0,0,0,0,0,0,7,0,0,0,0,0,0,4,3,3,3
3,3,3,7,0,0,0,0,0,0,7,0,0,0,0,0,0,0,7,0,0,0,0,0,0,7,3,3,3
3,3,3,7,0,0,0,0,0,0,7,0,0,0,0,0,0,0,7,0,0,0,0,0,0,7,3,3,3
3,3,3,7,7,7,7,7,7,7,7,7,7,7,7,7,7,7,7,7,7,7,7,7,7,7,3,3,3
3,3,3,7,0,0,0,0,0,0,7,0,0,0,0,0,0,0,7,0,0,0,0,0,0,7,3,3,3
3,3,3,7,0,0,0,0,0,0,7,0,0,0,0,0,0,0,7,0,0,0,0,0,0,7,3,3,3
3,3,3,7,0,0,0,0,0,0,7,0,0,0,0,0,0,0,7,0,0,0,0,0,0,7,3,3,3
3,3,3,7,0,0,0,0,0,0,7,0,0,0,0,0,0,0,7,0,0,0,0,0,0,7,3,3,3
3,3,3,7,0,0,0,0,0,0,7,0,0,0,0,0,0,0,7,0,0,0,0,0,0,7,3,3,3
3,3,3,6,0,0,0,0,0,0,7,0,0,0,0,0,0,0,7,0,0,0,0,0,0,6,3,3,3
3,3,3,4,6,7,7,7,7,7,7,7,7,4,4,4,7,7,7,7,7,7,7,7,6,4,3,3,3
3,3,3,3,3,3,3,3,3,3,3,3,3,3,3,3,3,3,3,3,3,3,3,3,3,3,3,3,3
3,3,3,3,3,3,3,3,3,3,3,3,3,3,3,3,3,3,3,3,3,3,3,3,3,3,3,3,3
3,3,3,3,3,3,3,3,3,3,3,3,3,3,3,3,3,3,3,3,3,3,3,3,3,3,3,3,3
endlayer

layer
3,3,3,3,3,3,3,3,3,3,3,3,3,3,3,3,3,3,3,3,3,3,3,3,3,3,3,3,3
3,3,3,3,3,3,3,3,3,3,3,3,3,3,3,3,3,3,3,3,3,3,3,3,3,3,3,3,3
3,3,3,3,3,3,3,3,3,3,3,3,3,3,3,3,3,3,3,3,3,3,3,3,3,3,3,3,3
3,3,3,4,6,7,7,7,7,7,7,7,7,7,7,7,7,7,7,7,7,7,7,7,6,4,3,3,3
3,3,3,6,0,0,0,0,0,0,7,0,0,0,0,0,0,0,7,0,0,0,0,0,0,6,3,3,3
3,3,3,7,0,0,0,0,0,0,7,0,0,0,0,0,0,0,7,0,0,0,0,0,0,7,3,3,3
3,3,3,7,0,0,0,0,0,0,7,0,0,0,0,0,0,0,7,0,0,0,0,0,0,7,3,3,3
3,3,3,7,0,0,0,0,0,0,7,0,0,0,0,0,0,0,7,0,0,0,0,0,0,7,3,3,3
3,3,3,7,0,0,0,0,0,0,7,0,0,0,0,0,0,0,7,0,0,0,0,0,0,7,3,3,3
3,3,3,7,0,0,0,0,0,0,7,0,0,0,0,0,0,0,7,0,0,0,0,0,0,7,3,3,3
3,3,3,7,7,7,7,7,7,7,7,7,7,7,7,7,7,7,7,7,7,7,7,7,7,7,3,3,3
3,3,3,7,0,0,0,0,0,0,7,0,0,0,0,0,0,0,7,0,0,0,0,0,0,7,3,3,3
3,3,3,7,0,0,0,0,0,0,7,0,0,0,0,0,0,0,7,0,0,0,0,0,0,7,3,3,3
3,3,3,7,0,0,0,0,0,0,7,0,0,0,0,0,0,0,7,0,0,0,0,0,0,7,3,3,3
3,3,3,7,0,0,0,0,0,0,7,0,0,0,0,0,0,0,7,0,0,0,0,0,0,7,3,3,3
3,3,3,7,0,0,0,0,0,0,7,0,0,0,0,0,0,0,7,0,0,0,0,0,0,7,3,3,3
3,3,3,7,0,0,0,0,0,0,7,0,0,0,0,0,0,0,7,0,0,0,0,0,0,7,3,3,3
3,3,3,7,0,0,0,0,0,0,7,0,0,0,0,0,0,0,7,0,0,0,0,0,0,7,3,3,3
3,3,3,7,7,7,7,7,7,7,7,7,7,7,7,7,7,7,7,7,7,7,7,7,7,7,3,3,3
3,3,3,7,0,0,0,0,0,0,7,0,0,0,0,0,0,0,7,0,0,0,0,0,0,7,3,3,3
3,3,3,7,0,0,0,0,0,0,7,0,0,0,0,0,0,0,7,0,0,0,0,0,0,7,3,3,3
3,3,3,7,0,0,0,0,0,0,7,0,0,0,0,0,0,0,7,0,0,0,0,0,0,7,3,3,3
3,3,3,7,0,0,0,0,0,0,7,0,0,0,0,0,0,0,7,0,0,0,0,0,0,7,3,3,3
3,3,3,7,0,0,0,0,0,0,7,0,0,0,0,0,0,0,7,0,0,0,0,0,0,7,3,3,3
3,3,3,6,0,0,0,0,0,0,7,0,0,0,0,0,0,0,7,0,0,0,0,0,0,6,3,3,3
3,3,3,4,6,7,7,7,7,7,7,7,7,7,7,7,7,7,7,7,7,7,7,7,6,4,3,3,3
3,3,3,3,3,3,3,3,3,3,3,3,3,3,3,3,3,3,3,3,3,3,3,3,3,3,3,3,3
3,3,3,3,3,3,3,3,3,3,3,3,3,3,3,3,3,3,3,3,3,3,3,3,3,3,3,3,3
3,3,3,3,3,3,3,3,3,3,3,3,3,3,3,3,3,3,3,3,3,3,3,3,3,3,3,3,3
endlayer

layer
3,3,3,3,3,3,3,3,3,3,3,3,3,3,3,3,3,3,3,3,3,3,3,3,3,3,3,3,3
3,3,3,3,3,3,3,3,3,3,3,3,3,3,3,3,3,3,3,3,3,3,3,3,3,3,3,3,3
3,3,3,3,3,3,3,3,3,3,3,3,3,3,3,3,3,3,3,3,3,3,3,3,3,3,3,3,3
3,3,3,6,7,7,7,7,7,7,7,7,7,7,7,7,7,7,7,7,7,7,7,7,7,6,3,3,3
3,3,3,7,7,7,7,7,7,7,7,7,7,7,7,7,7,7,7,7,7,7,7,7,7,7,3,3,3
3,3,3,7,7,7,7,7,7,7,7,7,7,7,7,7,7,7,7,7,7,7,7,7,7,7,3,3,3
3,3,3,7,7,7,7,7,7,7,7,7,7,7,7,7,7,7,7,7,7,7,7,7,7,7,3,3,3
3,3,3,7,7,7,7,7,7,7,7,7,7,7,7,7,7,7,7,7,7,7,7,7,7,7,3,3,3
3,3,3,7,7,7,7,7,7,7,7,7,7,7,7,7,7,7,7,7,7,7,7,7,7,7,3,3,3
3,3,3,7,7,7,7,7,7,7,7,7,7,7,7,7,7,7,7,7,7,7,7,7,7,7,3,3,3
3,3,3,7,7,7,7,7,7,7,7,7,7,7,7,7,7,7,7,7,7,7,7,7,7,7,3,3,3
3,3,3,7,7,7,7,7,7,7,7,7,7,7,7,7,7,7,7,7,7,7,7,7,7,7,3,3,3
3,3,3,7,7,7,7,7,7,7,7,7,7,7,7,7,7,7,7,7,7,7,7,7,7,7,3,3,3
3,3,3,7,7,7,7,7,7,7,7,7,7,7,7,7,7,7,7,7,7,7,7,7,7,7,3,3,3
3,3,3,7,7,7,7,7,7,7,7,7,7,7,7,7,7,7,7,7,7,7,7,7,7,7,3,3,3
3,3,3,7,7,7,7,7,7,7,7,7,7,7,7,7,7,7,7,7,7,7,7,7,7,7,3,3,3
3,3,3,7,7,7,7,7,7,7,7,7,7,7,7,7,7,7,7,7,7,7,7,7,7,7,3,3,3
3,3,3,7,7,7,7,7,7,7,7,7,7,7,7,7,7,7,7,7,7,7,7,7,7,7,3,3,3
3,3,3,7,7,7,7,7,7,7,7,7,7,7,7,7,7,7,7,7,7,7,7,7,7,7,3,3,3
3,3,3,7,7,7,7,7,7,7,7,7,7,7,7,7,7,7,7,7,7,7,7,7,7,7,3,3,3
3,3,3,7,7,7,7,7,7,7,7,7,7,7,7,7,7,7,7,7,7,7,7,7,7,7,3,3,3
3,3,3,7,7,7,7,7,7,7,7,7,7,7,7,7,7,7,7,7,7,7,7,7,7,7,3,3,3
3,3,3,7,7,7,7,7,7,7,7,7,7,7,7,7,7,7,7,7,7,7,7,7,7,7,3,3,3
3,3,3,7,7,7,7,7,7,7,7,7,7,7,7,7,7,7,7,7,7,7,7,7,7,7,3,3,3
3,3,3,7,7,7,7,7,7,7,7,7,7,7,7,7,7,7,7,7,7,7,7,7,7,7,3,3,3
3,3,3,6,7,7,7,7,7,7,7,7,7,7,7,7,7,7,7,7,7,7,7,7,7,6,3,3,3
3,3,3,3,3,3,3,3,3,3,3,3,3,3,3,3,3,3,3,3,3,3,3,3,3,3,3,3,3
3,3,3,3,3,3,3,3,3,3,3,3,3,3,3,3,3,3,3,3,3,3,3,3,3,3,3,3,3
3,3,3,3,3,3,3,3,3,3,3,3,3,3,3,3,3,3,3,3,3,3,3,3,3,3,3,3,3
endlayer

layer
3,3,3,3,3,3,3,3,3,3,3,3,3,3,3,3,3,3,3,3,3,3,3,3,3,3,3,3,3
3,3,3,3,3,3,3,3,3,3,3,3,3,3,3,3,3,3,3,3,3,3,3,3,3,3,3,3,3
3,3,3,3,3,3,3,3,3,3,3,3,3,3,3,3,3,3,3,3,3,3,3,3,3,3,3,3,3
3,3,3,6,7,7,7,6,7,7,7,6,7,7,7,7,7,6,7,7,7,6,7,7,7,6,3,3,3
3,3,3,7,0,0,0,0,0,0,0,0,0,0,0,0,0,0,0,0,0,0,0,0,0,7,3,3,3
3,3,3,7,0,0,0,0,0,0,0,0,0,0,0,0,0,0,0,0,0,0,0,0,0,7,3,3,3
3,3,3,7,0,0,0,0,0,0,0,0,0,0,0,0,0,0,0,0,0,0,0,0,0,7,3,3,3
3,3,3,6,0,0,0,0,0,0,0,0,0,0,0,0,0,0,0,0,0,0,0,0,0,6,3,3,3
3,3,3,7,0,0,0,0,0,0,0,0,0,0,0,0,0,0,0,0,0,0,0,0,0,7,3,3,3
3,3,3,7,0,0,0,0,0,0,0,0,0,0,0,0,0,0,0,0,0,0,0,0,0,7,3,3,3
3,3,3,7,0,0,0,0,0,0,0,0,0,0,0,0,0,0,0,0,0,0,0,0,0,7,3,3,3
3,3,3,6,0,0,0,0,0,0,0,32,0,0,32,0,0,32,0,0,0,0,0,0,0,6,3,3,3
3,3,3,7,0,0,0,0,0,0,0,0,0,0,0,0,0,0,0,0,0,0,0,0,0,7,3,3,3
3,3,3,7,0,0,0,0,0,0,0,0,0,0,0,0,0,0,0,0,0,0,0,0,0,7,3,3,3
3,3,3,7,0,0,0,0,0,0,0,32,0,0,33,0,0,32,0,0,0,0,0,0,0,7,3,3,3
3,3,3,7,0,0,0,0,0,0,0,0,0,0,0,0,0,0,0,0,0,0,0,0,0,7,3,3,3
3,3,3,7,0,0,0,0,0,0,0,0,0,0,0,0,0,0,0,0,0,0,0,0,0,7,3,3,3
3,3,3,6,0,0,0,0,0,0,0,32,0,0,32,0,0,32,0,0,0,0,0,0,0,6,3,3,3
3,3,3,7,0,0,0,0,0,0,0,0,0,0,0,0,0,0,0,0,0,0,0,0,0,7,3,3,3
3,3,3,7,0,0,0,0,0,0,0,0,0,0,0,0,0,0,0,0,0,0,0,0,0,7,3,3,3
3,3,3,7,0,0,0,0,0,0,0,0,0,0,0,0,0,0,0,0,0,0,0,0,0,7,3,3,3
3,3,3,6,0,0,0,0,0,0,0,0,0,0,0,0,0,0,0,0,0,0,0,0,0,6,3,3,3
3,3,3,7,0,0,0,0,0,0,0,0,0,0,0,0,0,0,0,0,0,0,0,0,0,7,3,3,3
3,3,3,7,0,0,0,0,0,0,0,0,0,0,0,0,0,0,0,0,0,0,0,0,0,7,3,3,3
3,3,3,7,0,0,0,0,0,0,0,0,0,0,0,0,0,0,0,0,0,0,0,0,0,7,3,3,3
3,3,3,6,7,7,7,6,7,7,7,6,7,7,7,7,7,6,7,7,7,6,7,7,7,6,3,3,3
3,3,3,3,3,3,3,3,3,3,3,3,3,3,3,3,3,3,3,3,3,3,3,3,3,3,3,3,3
3,3,3,3,3,3,3,3,3,3,3,3,3,3,3,3,3,3,3,3,3,3,3,3,3,3,3,3,3
3,3,3,3,3,3,3,3,3,3,3,3,3,3,3,3,3,3,3,3,3,3,3,3,3,3,3,3,3
endlayer

layer
3,3,3,3,3,3,3,3,3,3,3,3,3,3,3,3,3,3,3,3,3,3,3,3,3,3,3,3,3
3,3,3,3,3,3,3,3,3,3,3,3,3,3,3,3,3,3,3,3,3,3,3,3,3,3,3,3,3
3,3,3,3,3,3,3,3,3,3,3,3,3,3,3,3,3,3,3,3,3,3,3,3,3,3,3,3,3
3,3,3,6,0,7,0,6,0,7,0,6,0,7,0,7,0,6,0,7,0,6,0,7,0,6,3,3,3
3,3,3,0,0,0,0,0,0,0,0,0,0,0,0,0,0,0,0,0,0,0,0,0,0,0,3,3,3
3,3,3,7,0,0,0,0,0,0,0,0,0,0,0,0,0,0,0,0,0,0,0,0,0,7,3,3,3
3,3,3,0,0,0,0,0,0,0,0,0,0,0,0,0,0,0,0,0,0,0,0,0,0,0,3,3,3
3,3,3,6,0,0,0,0,0,0,0,0,0,0,0,0,0,0,0,0,0,0,0,0,0,6,3,3,3
3,3,3,0,0,0,0,0,0,0,0,0,0,0,0,0,0,0,0,0,0,0,0,0,0,0,3,3,3
3,3,3,7,0,0,0,0,0,0,0,0,0,0,0,0,0,0,0,0,0,0,0,0,0,7,3,3,3
3,3,3,0,0,0,0,0,0,0,0,0,0,0,0,0,0,0,0,0,0,0,0,0,0,0,3,3,3
3,3,3,6,0,0,0,0,0,0,0,0,0,0,0,0,0,0,0,0,0,0,0,0,0,6,3,3,3
3,3,3,0,0,0,0,0,0,0,0,0,0,0,0,0,0,0,0,0,0,0,0,0,0,0,3,3,3
3,3,3,7,0,0,0,0,0,0,0,0,0,0,0,0,0,0,0,0,0,0,0,0,0,7,3,3,3
3,3,3,0,0,0,0,0,0,0,0,0,0,0,25,0,0,0,0,0,0,0,0,0,0,0,3,3,3
3,3,3,7,0,0,0,0,0,0,0,0,0,0,0,0,0,0,0,0,0,0,0,0,0,7,3,3,3
3,3,3,0,0,0,0,0,0,0,0,0,0,0,0,0,0,0,0,0,0,0,0,0,0,0,3,3,3
3,3,3,6,0,0,0,0,0,0,0,0,0,0,0,0,0,0,0,0,0,0,0,0,0,6,3,3,3
3,3,3,0,0,0,0,0,0,0,0,0,0,0,0,0,0,0,0,0,0,0,0,0,0,0,3,3,3
3,3,3,7,0,0,0,0,0,0,0,0,0,0,0,0,0,0,0,0,0,0,0,0,0,7,3,3,3
3,3,3,0,0,0,0,0,0,0,0,0,0,0,0,0,0,0,0,0,0,0,0,0,0,0,3,3,3
3,3,3,6,0,0,0,0,0,0,0,0,0,0,0,0,0,0,0,0,0,0,0,0,0,6,3,3,3
3,3,3,0,0,0,0,0,0,0,0,0,0,0,0,0,0,0,0,0,0,0,0,0,0,0,3,3,3
3,3,3,7,0,0,0,0,0,0,0,0,0,0,0,0,0,0,0,0,0,0,0,0,0,7,3,3,3
3,3,3,0,0,0,0,0,0,0,0,0,0,0,0,0,0,0,0,0,0,0,0,0,0,0,3,3,3
3,3,3,6,0,7,0,6,0,7,0,6,0,7,0,7,0,6,0,7,0,6,0,7,0,6,3,3,3
3,3,3,3,3,3,3,3,3,3,3,3,3,3,3,3,3,3,3,3,3,3,3,3,3,3,3,3,3
3,3,3,3,3,3,3,3,3,3,3,3,3,3,3,3,3,3,3,3,3,3,3,3,3,3,3,3,3
3,3,3,3,3,3,3,3,3,3,3,3,3,3,3,3,3,3,3,3,3,3,3,3,3,3,3,3,3
endlayer

layer
3,3,3,3,3,3,3,3,3,3,3,3,3,3,3,3,3,3,3,3,3,3,3,3,3,3,3,3,3
3,3,3,3,3,3,3,3,3,3,3,3,3,3,3,3,3,3,3,3,3,3,3,3,3,3,3,3,3
3,3,3,3,3,3,3,3,3,3,3,3,3,3,3,3,3,3,3,3,3,3,3,3,3,3,3,3,3
3,3,3,34,0,0,0,34,0,0,0,34,0,0,0,0,0,34,0,0,0,34,0,0,0,34,3,3,3
3,3,3,0,0,0,0,0,0,0,0,0,0,0,0,0,0,0,0,0,0,0,0,0,0,0,3,3,3
3,3,3,0,0,0,0,0,0,0,0,0,0,0,0,0,0,0,0,0,0,0,0,0,0,0,3,3,3
3,3,3,0,0,0,0,0,0,0,0,0,0,0,0,0,0,0,0,0,0,0,0,0,0,0,3,3,3
3,3,3,34,0,0,0,0,0,0,0,0,0,0,0,0,0,0,0,0,0,0,0,0,0,34,3,3,3
3,3,3,0,0,0,0,0,0,0,0,0,0,0,0,0,0,0,0,0,0,0,0,0,0,0,3,3,3
3,3,3,0,0,0,0,0,0,0,0,0,0,0,0,0,0,0,0,0,0,0,0,0,0,0,3,3,3
3,3,3,0,0,0,0,0,0,0,0,0,0,0,0,0,0,0,0,0,0,0,0,0,0,0,3,3,3
3,3,3,34,0,0,0,0,0,0,0,0,0,0,0,0,0,0,0,0,0,0,0,0,0,34,3,3,3
3,3,3,0,0,0,0,0,0,0,0,0,0,0,0,0,0,0,0,0,0,0,0,0,0,0,3,3,3
3,3,3,0,0,0,0,0,0,0,0,0,0,0,0,0,0,0,0,0,0,0,0,0,0,0,3,3,3
3,3,3,0,0,0,0,0,0,0,0,0,0,0,0,0,0,0,0,0,0,0,0,0,0,0,3,3,3
3,3,3,0,0,0,0,0,0,0,0,0,0,0,0,0,0,0,0,0,0,0,0,0,0,0,3,3,3
3,3,3,0,0,0,0,0,0,0,0,0,0,0,0,0,0,0,0,0,0,0,0,0,0,0,3,3,3
3,3,3,34,0,0,0,0,0,0,0,0,0,0,0,0,0,0,0,0,0,0,0,0,0,34,3,3,3
3,3,3,0,0,0,0,0,0,0,0,0,0,0,0,0,0,0,0,0,0,0,0,0,0,0,3,3,3
3,3,3,0,0,0,0,0,0,0,0,0,0,0,0,0,0,0,0,0,0,0,0,0,0,0,3,3,3
3,3,3,0,0,0,0,0,0,0,0,0,0,0,0,0,0,0,0,0,0,0,0,0,0,0,3,3,3
3,3,3,34,0,0,0,0,0,0,0,0,0,0,0,0,0,0,0,0,0,0,0,0,0,34,3,3,3
3,3,3,0,0,0,0,0,0,0,0,0,0,0,0,0,0,0,0,0,0,0,0,0,0,0,3,3,3
3,3,3,0,0,0,0,0,0,0,0,0,0,0,0,0,0,0,0,0,0,0,0,0,0,0,3,3,3
3,3,3,0,0,0,0,0,0,0,0,0,0,0,0,0,0,0,0,0,0,0,0,0,0,0,3,3,3
3,3,3,34,0,0,0,34,0,0,0,34,0,0,0,0,0,34,0,0,0,34,0,0,0,34,3,3,3
3,3,3,3,3,3,3,3,3,3,3,3,3,3,3,3,3,3,3,3,3,3,3,3,3,3,3,3,3
3,3,3,3,3,3,3,3,3,3,3,3,3,3,3,3,3,3,3,3,3,3,3,3,3,3,3,3,3
3,3,3,3,3,3,3,3,3,3,3,3,3,3,3,3,3,3,3,3,3,3,3,3,3,3,3,3,3
endlayer

layer
3,3,3,3,3,3,3,3,3,3,3,3,3,3,3,3,3,3,3,3,3,3,3,3,3,3,3,3,3
3,3,3,3,3,3,3,3,3,3,3,3,3,3,3,3,3,3,3,3,3,3,3,3,3,3,3,3,3
3,3,3,3,3,3,3,3,3,3,3,3,3,3,3,3,3,3,3,3,3,3,3,3,3,3,3,3,3
3,3,3,0,0,0,0,0,0,0,0,0,0,0,0,0,0,0,0,0,0,0,0,0,0,0,3,3,3
3,3,3,0,0,0,0,0,0,0,0,0,0,0,0,0,0,0,0,0,0,0,0,0,0,0,3,3,3
3,3,3,0,0,0,0,0,0,0,0,0,0,0,0,0,0,0,0,0,0,0,0,0,0,0,3,3,3
3,3,3,0,0,0,0,0,0,0,0,0,0,0,0,0,0,0,0,0,0,0,0,0,0,0,3,3,3
3,3,3,0,0,0,0,0,0,0,0,0,0,0,0,0,0,0,0,0,0,0,0,0,0,0,3,3,3
3,3,3,0,0,0,0,0,0,0,0,0,0,0,0,0,0,0,0,0,0,0,0,0,0,0,3,3,3
3,3,3,0,0,0,0,0,0,0,0,0,0,0,0,0,0,0,0,0,0,0,0,0,0,0,3,3,3
3,3,3,0,0,0,0,0,0,0,0,0,0,0,0,0,0,0,0,0,0,0,0,0,0,0,3,3,3
3,3,3,0,0,0,0,0,0,0,0,0,0,0,0,0,0,0,0,0,0,0,0,0,0,0,3,3,3
3,3,3,0,0,0,0,0,0,0,0,0,0,0,0,0,0,0,0,0,0,0,0,0,0,0,3,3,3
3,3,3,0,0,0,0,0,0,0,0,0,0,0,0,0,0,0,0,0,0,0,0,0,0,0,3,3,3
3,3,3,0,0,0,0,0,0,0,0,0,0,0,0,0,0,0,0,0,0,0,0,0,0,0,3,3,3
3,3,3,0,0,0,0,0,0,0,0,0,0,0,0,0,0,0,0,0,0,0,0,0,0,0,3,3,3
3,3,3,0,0,0,0,0,0,0,0,0,0,0,0,0,0,0,0,0,0,0,0,0,0,0,3,3,3
3,3,3,0,0,0,0,0,0,0,0,0,0,0,0,0,0,0,0,0,0,0,0,0,0,0,3,3,3
3,3,3,0,0,0,0,0,0,0,0,0,0,0,0,0,0,0,0,0,0,0,0,0,0,0,3,3,3
3,3,3,0,0,0,0,0,0,0,0,0,0,0,0,0,0,0,0,0,0,0,0,0,0,0,3,3,3
3,3,3,0,0,0,0,0,0,0,0,0,0,0,0,0,0,0,0,0,0,0,0,0,0,0,3,3,3
3,3,3,0,0,0,0,0,0,0,0,0,0,0,0,0,0,0,0,0,0,0,0,0,0,0,3,3,3
3,3,3,0,0,0,0,0,0,0,0,0,0,0,0,0,0,0,0,0,0,0,0,0,0,0,3,3,3
3,3,3,0,0,0,0,0,0,0,0,0,0,0,0,0,0,0,0,0,0,0,0,0,0,0,3,3,3
3,3,3,0,0,0,0,0,0,0,0,0,0,0,0,0,0,0,0,0,0,0,0,0,0,0,3,3,3
3,3,3,0,0,0,0,0,0,0,0,0,0,0,0,0,0,0,0,0,0,0,0,0,0,0,3,3,3
3,3,3,3,3,3,3,3,3,3,3,3,3,3,3,3,3,3,3,3,3,3,3,3,3,3,3,3,3
3,3,3,3,3,3,3,3,3,3,3,3,3,3,3,3,3,3,3,3,3,3,3,3,3,3,3,3,3
3,3,3,3,3,3,3,3,3,3,3,3,3,3,3,3,3,3,3,3,3,3,3,3,3,3,3,3,3
endlayer

layer
3,3,3,3,3,3,3,3,3,3,3,3,3,3,3,3,3,3,3,3,3,3,3,3,3,3,3,3,3
3,3,3,3,3,3,3,3,3,3,3,3,3,3,3,3,3,3,3,3,3,3,3,3,3,3,3,3,3
3,3,3,3,3,3,3,3,3,3,3,3,3,3,3,3,3,3,3,3,3,3,3,3,3,3,3,3,3
3,3,3,0,0,0,0,0,0,0,0,0,0,0,0,0,0,0,0,0,0,0,0,0,0,0,3,3,3
3,3,3,0,0,0,0,0,0,0,0,0,0,0,0,0,0,0,0,0,0,0,0,0,0,0,3,3,3
3,3,3,0,0,0,0,0,0,0,0,0,0,0,0,0,0,0,0,0,0,0,0,0,0,0,3,3,3
3,3,3,0,0,0,0,0,0,0,0,0,0,0,0,0,0,0,0,0,0,0,0,0,0,0,3,3,3
3,3,3,0,0,0,0,0,0,0,0,0,0,0,0,0,0,0,0,0,0,0,0,0,0,0,3,3,3
3,3,3,0,0,0,0,0,0,0,0,0,0,0,0,0,0,0,0,0,0,0,0,0,0,0,3,3,3
3,3,3,0,0,0,0,0,0,0,0,0,0,0,0,0,0,0,0,0,0,0,0,0,0,0,3,3,3
3,3,3,0,0,0,0,0,0,0,0,0,0,0,0,0,0,0,0,0,0,0,0,0,0,0,3,3,3
3,3,3,0,0,0,0,0,0,0,0,0,0,0,0,0,0,0,0,0,0,0,0,0,0,0,3,3,3
3,3,3,0,0,0,0,0,0,0,0,0,0,0,0,0,0,0,0,0,0,0,0,0,0,0,3,3,3
3,3,3,0,0,0,0,0,0,0,0,0,0,0,0,0,0,0,0,0,0,0,0,0,0,0,3,3,3
3,3,3,0,0,0,0,0,0,0,0,0,0,0,0,0,0,0,0,0,0,0,0,0,0,0,3,3,3
3,3,3,0,0,0,0,0,0,0,0,0,0,0,0,0,0,0,0,0,0,0,0,0,0,0,3,3,3
3,3,3,0,0,0,0,0,0,0,0,0,0,0,0,0,0,0,0,0,0,0,0,0,0,0,3,3,3
3,3,3,0,0,0,0,0,0,0,0,0,0,0,0,0,0,0,0,0,0,0,0,0,0,0,3,3,3
3,3,3,0,0,0,0,0,0,0,0,0,0,0,0,0,0,0,0,0,0,0,0,0,0,0,3,3,3
3,3,3,0,0,0,0,0,0,0,0,0,0,0,0,0,0,0,0,0,0,0,0,0,0,0,3,3,3
3,3,3,0,0,0,0,0,0,0,0,0,0,0,0,0,0,0,0,0,0,0,0,0,0,0,3,3,3
3,3,3,0,0,0,0,0,0,0,0,0,0,0,0,0,0,0,0,0,0,0,0,0,0,0,3,3,3
3,3,3,0,0,0,0,0,0,0,0,0,0,0,0,0,0,0,0,0,0,0,0,0,0,0,3,3,3
3,3,3,0,0,0,0,0,0,0,0,0,0,0,0,0,0,0,0,0,0,0,0,0,0,0,3,3,3
3,3,3,0,0,0,0,0,0,0,0,0,0,0,0,0,0,0,0,0,0,0,0,0,0,0,3,3,3
3,3,3,0,0,0,0,0,0,0,0,0,0,0,0,0,0,0,0,0,0,0,0,0,0,0,3,3,3
3,3,3,3,3,3,3,3,3,3,3,3,3,3,3,3,3,3,3,3,3,3,3,3,3,3,3,3,3
3,3,3,3,3,3,3,3,3,3,3,3,3,3,3,3,3,3,3,3,3,3,3,3,3,3,3,3,3
3,3,3,3,3,3,3,3,3,3,3,3,3,3,3,3,3,3,3,3,3,3,3,3,3,3,3,3,3
endlayer

layer
3,3,3,3,3,3,3,3,3,3,3,3,3,3,3,3,3,3,3,3,3,3,3,3,3,3,3,3,3
3,3,3,3,3,3,3,3,3,3,3,3,3,3,3,3,3,3,3,3,3,3,3,3,3,3,3,3,3
3,3,3,3,3,3,3,3,3,3,3,3,3,3,3,3,3,3,3,3,3,3,3,3,3,3,3,3,3
3,3,3,0,0,35,0,0,0,35,0,0,0,35,0,35,0,0,0,35,0,0,0,35,0,0,3,3,3
3,3,3,0,0,0,0,0,0,0,0,0,0,0,0,0,0,0,0,0,0,0,0,0,0,0,3,3,3
3,3,3,35,0,0,0,0,0,0,0,0,0,0,0,0,0,0,0,0,0,0,0,0,0,35,3,3,3
3,3,3,0,0,0,0,0,0,0,0,0,0,0,0,0,0,0,0,0,0,0,0,0,0,0,3,3,3
3,3,3,0,0,0,0,0,0,0,0,0,0,0,0,0,0,0,0,0,0,0,0,0,0,0,3,3,3
3,3,3,0,0,0,0,0,0,0,0,0,0,0,0,0,0,0,0,0,0,0,0,0,0,0,3,3,3
3,3,3,35,0,0,0,0,0,0,0,0,0,0,0,0,0,0,0,0,0,0,0,0,0,35,3,3,3
3,3,3,0,0,0,0,0,0,0,0,0,0,0,0,0,0,0,0,0,0,0,0,0,0,0,3,3,3
3,3,3,0,0,0,0,0,0,0,0,0,0,0,0,0,0,0,0,0,0,0,0,0,0,0,3,3,3
3,3,3,0,0,0,0,0,0,0,0,0,0,0,0,0,0,0,0,0,0,0,0,0,0,0,3,3,3
3,3,3,35,0,0,0,0,0,0,0,0,0,0,0,0,0,0,0,0,0,0,0,0,0,35,3,3,3
3,3,3,0,0,0,0,0,0,0,0,0,0,0,0,0,0,0,0,0,0,0,0,0,0,0,3,3,3
3,3,3,35,0,0,0,0,0,0,0,0,0,0,0,0,0,0,0,0,0,0,0,0,0,35,3,3,3
3,3,3,0,0,0,0,0,0,0,0,0,0,0,0,0,0,0,0,0,0,0,0,0,0,0,3,3,3
3,3,3,0,0,0,0,0,0,0,0,0,0,0,0,0,0,0,0,0,0,0,0,0,0,0,3,3,3
3,3,3,0,0,0,0,0,0,0,0,0,0,0,0,0,0,0,0,0,0,0,0,0,0,0,3,3,3
3,3,3,35,0,0,0,0,0,0,0,0,0,0,0,0,0,0,0,0,0,0,0,0,0,35,3,3,3
3,3,3,0,0,0,0,0,0,0,0,0,0,0,0,0,0,0,0,0,0,0,0,0,0,0,3,3,3
3,3,3,0,0,0,0,0,0,0,0,0,0,0,0,0,0,0,0,0,0,0,0,0,0,0,3,3,3
3,3,3,0,0,0,0,0,0,0,0,0,0,0,0,0,0,0,0,0,0,0,0,0,0,0,3,3,3
3,3,3,35,0,0,0,0,0,0,0,0,0,0,0,0,0,0,0,0,0,0,0,0,0,35,3,3,3
3,3,3,0,0,0,0,0,0,0,0,0,0,0,0,0,0,0,0,0,0,0,0,0,0,0,3,3,3
3,3,3,0,0,35,0,0,0,35,0,0,0,35,0,35,0,0,0,35,0,0,0,35,0,0,3,3,3
3,3,3,3,3,3,3,3,3,3,3,3,3,3,3,3,3,3,3,3,3,3,3,3,3,3,3,3,3
3,3,3,3,3,3,3,3,3,3,3,3,3,3,3,3,3,3,3,3,3,3,3,3,3,3,3,3,3
3,3,3,3,3,3,3,3,3,3,3,3,3,3,3,3,3,3,3,3,3,3,3,3,3,3,3,3,3
endlayer

layer
3,3,3,3,3,3,3,3,3,3,3,3,3,3,3,3,3,3,3,3,3,3,3,3,3,3,3,3,3
3,3,3,3,3,3,3,3,3,3,3,3,3,3,3,3,3,3,3,3,3,3,3,3,3,3,3,3,3
3,3,3,3,3,3,3,3,3,3,3,3,3,3,3,3,3,3,3,3,3,3,3,3,3,3,3,3,3
3,3,3,0,0,35,0,0,0,35,0,0,0,35,0,35,0,0,0,35,0,0,0,35,0,0,3,3,3
3,3,3,0,0,0,0,0,0,0,0,0,0,0,0,0,0,0,0,0,0,0,0,0,0,0,3,3,3
3,3,3,35,0,0,0,0,0,0,0,0,0,0,0,0,0,0,0,0,0,0,0,0,0,35,3,3,3
3,3,3,0,0,0,0,0,0,0,0,0,0,0,0,0,0,0,0,0,0,0,0,0,0,0,3,3,3
3,3,3,0,0,0,0,0,0,0,0,0,0,0,0,0,0,0,0,0,0,0,0,0,0,0,3,3,3
3,3,3,0,0,0,0,0,0,0,0,0,0,0,0,0,0,0,0,0,0,0,0,0,0,0,3,3,3
3,3,3,35,0,0,0,0,0,0,0,0,0,0,0,0,0,0,0,0,0,0,0,0,0,35,3,3,3
3,3,3,0,0,0,0,0,0,0,0,0,0,0,0,0,0,0,0,0,0,0,0,0,0,0,3,3,3
3,3,3,0,0,0,0,0,0,0,0,0,0,0,0,0,0,0,0,0,0,0,0,0,0,0,3,3,3
3,3,3,0,0,0,0,0,0,0,0,0,0,0,0,0,0,0,0,0,0,0,0,0,0,0,3,3,3
3,3,3,35,0,0,0,0,0,0,0,0,0,0,0,0,0,0,0,0,0,0,0,0,0,35,3,3,3
3,3,3,0,0,0,0,0,0,0,0,0,0,0,0,0,0,0,0,0,0,0,0,0,0,0,3,3,3
3,3,3,35,0,0,0,0,0,0,0,0,0,0,0,0,0,0,0,0,0,0,0,0,0,35,3,3,3
3,3,3,0,0,0,0,0,0,0,0,0,0,0,0,0,0,0,0,0,0,0,0,0,0,0,3,3,3
3,3,3,0,0,0,0,0,0,0,0,0,0,0,0,0,0,0,0,0,0,0,0,0,0,0,3,3,3
3,3,3,0,0,0,0,0,0,0,0,0,0,0,0,0,0,0,0,0,0,0,0,0,0,0,3,3,3
3,3,3,35,0,0,0,0,0,0,0,0,0,0,0,0,0,0,0,0,0,0,0,0,0,35,3,3,3
3,3,3,0,0,0,0,0,0,0,0,0,0,0,0,0,0,0,0,0,0,0,0,0,0,0,3,3,3
3,3,3,0,0,0,0,0,0,0,0,0,0,0,0,0,0,0,0,0,0,0,0,0,0,0,3,3,3
3,3,3,0,0,0,0,0,0,0,0,0,0,0,0,0,0,0,0,0,0,0,0,0,0,0,3,3,3
3,3,3,35,0,0,0,0,0,0,0,0,0,0,0,0,0,0,0,0,0,0,0,0,0,35,3,3,3
3,3,3,0,0,0,0,0,0,0,0,0,0,0,0,0,0,0,0,0,0,0,0,0,0,0,3,3,3
3,3,3,0,0,35,0,0,0,35,0,0,0,35,0,35,0,0,0,35,0,0,0,35,0,0,3,3,3
3,3,3,3,3,3,3,3,3,3,3,3,3,3,3,3,3,3,3,3,3,3,3,3,3,3,3,3,3
3,3,3,3,3,3,3,3,3,3,3,3,3,3,3,3,3,3,3,3,3,3,3,3,3,3,3,3,3
3,3,3,3,3,3,3,3,3,3,3,3,3,3,3,3,3,3,3,3,3,3,3,3,3,3,3,3,3
endlayer

