
# Created by Ruins mod version 15.1 Ingame Parser
# authoring Player: Tmtravlr

weight=1
embed_into_distance=0
acceptable_target_blocks=
unacceptable_target_blocks=flowing_water,water,flowing_lava,lava
dimensions=6,6,6
leveling_buffer=-1
preserve_water=0
preserve_lava=0
preserve_plants=0
max_cut_in=0
allowable_overhang=0

rule1=0,100,TConstruct:slime.pad-7
rule2=0,100,TConstruct:slime.pad-3
rule3=0,100,preserveBlock
rule4=0,100,minecraft:glowstone-0

layer
0,0,0,0,0,0
0,0,0,0,0,0
0,0,0,1,0,0
0,0,2,0,0,0
0,0,0,0,0,0
0,0,0,0,0,0
endlayer

layer
0,3,0,0,3,0
3,0,0,0,0,3
0,0,0,0,0,0
0,0,0,0,0,0
3,0,0,0,0,3
0,3,0,0,3,0
endlayer

layer
0,0,0,0,0,0
0,0,0,0,0,0
0,0,0,0,0,0
0,0,0,0,0,0
0,0,0,0,0,0
0,0,0,0,0,0
endlayer

layer
0,0,0,0,0,0
0,0,0,0,0,0
0,0,0,0,0,0
0,0,0,0,0,0
0,0,0,0,0,0
0,0,0,0,0,0
endlayer

layer
0,0,0,0,0,0
0,0,0,0,0,0
0,0,0,0,0,0
0,0,0,0,0,0
0,0,0,0,0,0
0,0,0,0,0,0
endlayer

layer
3,3,3,3,3,3
3,4,4,4,4,3
3,4,0,0,4,3
3,4,0,0,4,3
3,4,4,4,4,3
3,3,3,3,3,3
endlayer

