
# Created by Ruins mod version 15.1 Ingame Parser
# authoring Player: Tmtravlr

weight=1
embed_into_distance=2
acceptable_target_blocks=
unacceptable_target_blocks=flowing_water,water,flowing_lava,lava
dimensions=9,12,12
leveling_buffer=-1
preserve_water=0
preserve_lava=0
preserve_plants=0
max_cut_in=0
allowable_overhang=0

rule1=0,100,preserveBlock
rule2=0,100,minecraft:stained_glass-15

layer
1,1,1,1,1,1,1,1,1,1,1,1
1,1,1,1,1,1,1,1,1,1,1,1
1,1,1,1,1,1,1,1,1,1,1,1
1,1,1,1,1,1,1,1,1,1,1,1
1,1,1,1,1,1,1,1,1,1,1,1
1,1,1,1,1,2,1,1,1,1,1,1
1,1,1,1,1,1,2,1,1,1,1,1
1,1,1,1,1,1,1,1,1,1,1,1
1,1,1,1,1,1,1,1,1,1,1,1
1,1,1,1,1,1,1,1,1,1,1,1
1,1,1,1,1,1,1,1,1,1,1,1
1,1,1,1,1,1,1,1,1,1,1,1
endlayer

layer
1,1,1,1,1,1,1,1,1,1,1,1
1,1,1,1,1,1,1,1,1,1,1,1
1,1,1,1,1,1,1,1,1,1,1,1
1,1,1,0,0,0,0,0,0,1,1,1
1,1,1,0,0,0,0,0,0,1,1,1
1,1,1,0,0,0,0,0,0,1,1,1
1,1,1,0,0,0,0,0,0,1,1,1
1,1,1,0,0,0,0,0,0,1,1,1
1,1,1,0,0,0,0,0,0,1,1,1
1,1,1,1,1,1,1,1,1,1,1,1
1,1,1,1,1,1,1,1,1,1,1,1
1,1,1,1,1,1,1,1,1,1,1,1
endlayer

layer
1,1,1,1,1,1,1,1,1,1,1,1
1,1,1,1,1,1,1,1,1,1,1,1
1,1,1,1,1,1,1,1,1,1,1,1
1,1,1,0,0,0,0,0,0,1,1,1
1,1,1,0,0,0,0,0,0,1,1,1
1,1,1,0,0,0,0,0,0,1,1,1
1,1,1,0,0,1,0,0,0,1,1,1
1,1,1,0,0,0,0,0,0,1,1,1
1,1,1,0,0,0,0,0,0,1,1,1
1,1,1,1,1,1,1,1,1,1,1,1
1,1,1,1,1,1,1,1,1,1,1,1
1,1,1,1,1,1,1,1,1,1,1,1
endlayer

layer
1,1,1,1,1,1,1,1,1,1,1,1
1,1,1,1,1,1,1,1,1,1,1,1
1,1,1,1,1,1,2,1,1,1,1,1
1,1,1,0,0,0,0,0,0,1,1,1
1,1,1,0,0,0,0,0,0,1,1,1
1,1,1,0,0,0,0,0,0,2,1,1
1,1,2,0,0,0,0,0,0,1,1,1
1,1,1,0,0,0,0,0,0,1,1,1
1,1,1,0,0,0,0,0,0,1,1,1
1,1,1,1,1,2,1,1,1,1,1,1
1,1,1,1,1,1,1,1,1,1,1,1
1,1,1,1,1,1,1,1,1,1,1,1
endlayer

layer
1,1,1,1,1,1,1,1,1,1,1,1
1,1,1,1,1,1,1,1,1,1,1,1
1,1,1,1,1,2,1,1,1,1,1,1
1,1,1,0,0,0,0,0,0,1,1,1
1,1,1,0,0,0,0,0,0,1,1,1
1,1,2,0,0,0,0,0,0,1,1,1
1,1,1,0,0,0,0,0,0,2,1,1
1,1,1,0,0,0,0,0,0,1,1,1
1,1,1,0,0,0,0,0,0,1,1,1
1,1,1,1,1,1,2,1,1,1,1,1
1,1,1,1,1,1,1,1,1,1,1,1
1,1,1,1,1,1,1,1,1,1,1,1
endlayer

layer
1,1,1,1,1,1,1,1,1,1,1,1
1,1,1,1,1,1,1,1,1,1,1,1
1,1,1,1,1,1,1,1,1,1,1,1
1,1,1,0,0,0,0,0,0,1,1,1
1,1,1,0,0,0,0,0,0,1,1,1
1,1,1,0,0,0,0,0,0,1,1,1
1,1,1,0,0,0,0,0,0,1,1,1
1,1,1,0,0,0,0,0,0,1,1,1
1,1,1,0,0,0,0,0,0,1,1,1
1,1,1,1,1,1,1,1,1,1,1,1
1,1,1,1,1,1,1,1,1,1,1,1
1,1,1,1,1,1,1,1,1,1,1,1
endlayer

layer
1,1,1,1,1,1,1,1,1,1,1,1
1,1,1,1,1,1,1,1,1,1,1,1
1,1,1,1,1,1,1,1,1,1,1,1
1,1,1,0,0,0,0,0,0,1,1,1
1,1,1,0,0,0,0,0,0,1,1,1
1,1,1,0,0,0,0,0,0,1,1,1
1,1,1,0,0,0,0,0,0,1,1,1
1,1,1,0,0,0,0,0,0,1,1,1
1,1,1,0,0,0,0,0,0,1,1,1
1,1,1,1,1,1,1,1,1,1,1,1
1,1,1,1,1,1,1,1,1,1,1,1
1,1,1,1,1,1,1,1,1,1,1,1
endlayer

layer
1,1,1,1,1,1,1,1,1,1,1,1
1,1,1,1,1,1,1,1,1,1,1,1
1,1,1,1,1,1,1,1,1,1,1,1
1,1,1,1,1,1,1,1,1,1,1,1
1,1,1,1,1,1,1,1,1,1,1,1
1,1,1,1,1,1,2,1,0,1,1,1
1,1,1,1,1,2,1,1,1,1,1,1
1,1,1,1,1,1,1,1,1,1,1,1
1,1,1,1,1,1,1,1,1,1,1,1
1,1,1,1,1,1,1,1,1,1,1,1
1,1,1,1,1,1,1,1,1,1,1,1
1,1,1,1,1,1,1,1,1,1,1,1
endlayer

layer
1,1,1,1,1,1,1,1,1,1,1,1
1,1,1,1,1,1,1,1,1,1,1,1
1,1,1,1,1,1,1,1,1,1,1,1
1,1,1,1,1,1,1,1,1,1,1,1
1,1,1,1,1,1,1,1,1,1,1,1
1,1,1,1,1,1,1,1,1,1,1,1
1,1,1,1,1,1,1,1,1,1,1,1
1,1,1,1,1,1,1,1,1,1,1,1
1,1,1,1,1,1,1,1,1,1,1,1
1,1,1,1,1,1,1,1,1,1,1,1
1,1,1,1,1,1,1,1,1,1,1,1
1,1,1,1,1,1,1,1,1,1,1,1
endlayer

