
# Created by Ruins mod version 15.1 Ingame Parser
# authoring Player: Tmtravlr

weight=1
embed_into_distance=0
acceptable_target_blocks=
unacceptable_target_blocks=flowing_water,water,flowing_lava,lava
dimensions=9,12,12
leveling_buffer=-1
preserve_water=0
preserve_lava=0
preserve_plants=0
max_cut_in=0
allowable_overhang=0

rule1=0,100,air
rule2=0,100,lootplusplus:spiral.black_candy-0
rule3=0,100,lootplusplus:spiral.white_candy-0
rule4=0,100,lootplusplus:spiral.magenta_candy-0
rule5=0,100,lootplusplus:spiral.purple_candy-0
rule6=0,100,lootplusplus:spiral.orange_candy-0
rule7=0,100,lootplusplus:spiral.blue_candy-0
rule8=0,100,lootplusplus:spiral.yellow_candy-0
rule9=0,100,lootplusplus:spiral.red_candy-0
rule10=0,100,lootplusplus:spiral.cyan_candy-0
rule11=0,100,lootplusplus:spiral.lime_candy-0
rule12=0,100,minecraft:lapis_block-0
rule13=0,100,minecraft:lever-2
rule14=0,100,minecraft:redstone_wire-0
rule15=0,100,minecraft:lever-4
rule16=0,100,minecraft:lever-3
rule17=0,100,minecraft:lever-1

layer
1,1,1,1,1,1,1,1,1,1,1,1
1,1,1,1,1,1,1,1,1,1,1,1
1,1,2,2,2,2,2,2,2,2,1,1
1,1,2,3,5,5,5,4,3,2,1,1
1,1,2,7,7,3,6,6,4,2,1,1
1,1,2,7,3,9,3,8,3,2,1,1
1,1,2,10,3,9,9,8,9,2,1,1
1,1,2,10,10,3,11,11,9,2,1,1
1,1,2,3,8,8,6,6,3,2,1,1
1,1,2,2,2,2,2,2,2,2,1,1
1,1,1,1,1,1,1,1,1,1,1,1
1,1,1,1,1,1,1,1,1,1,1,1
endlayer

layer
1,1,1,1,1,1,1,1,1,1,1,1
1,1,1,3,1,3,1,1,3,1,1,1
1,1,2,3,4,3,9,9,3,2,1,1
1,3,3,0,0,0,0,0,0,3,3,1
1,1,9,0,0,0,0,0,0,4,1,1
1,1,9,0,0,0,0,0,0,3,3,1
1,3,3,0,0,0,0,0,0,9,1,1
1,1,4,0,0,0,0,0,0,9,1,1
1,3,3,0,0,0,0,0,0,3,3,1
1,1,2,3,9,9,3,4,3,2,1,1
1,1,1,3,1,1,3,1,3,1,1,1
1,1,1,1,1,1,1,1,1,1,1,1
endlayer

layer
0,0,0,0,0,0,0,0,0,0,0,0
0,0,0,0,0,0,0,0,0,0,0,0
0,0,2,4,6,8,8,11,6,2,0,0
0,0,6,0,0,3,0,0,0,4,0,0
0,0,11,0,0,3,0,0,0,6,0,0
0,0,8,0,0,3,3,3,3,8,0,0
0,0,8,3,3,12,3,0,0,8,0,0
0,0,6,0,0,0,3,0,0,11,0,0
0,0,4,0,0,0,3,0,0,6,0,0
0,0,2,6,11,8,8,6,4,2,0,0
0,0,0,0,0,0,0,0,0,0,0,0
0,0,0,0,0,0,0,0,0,0,0,0
endlayer

layer
0,0,0,0,0,13,0,0,0,0,0,0
0,0,0,0,0,3,0,0,0,0,0,0
0,0,2,5,6,14,9,11,6,2,0,0
0,0,6,0,0,14,0,0,0,5,0,0
0,0,11,0,0,14,0,0,0,6,0,0
0,0,9,0,0,14,14,14,14,14,3,15
16,3,14,14,14,0,14,0,0,9,0,0
0,0,6,0,0,0,14,0,0,11,0,0
0,0,5,0,0,0,14,0,0,6,0,0
0,0,2,6,11,9,14,6,5,2,0,0
0,0,0,0,0,0,3,0,0,0,0,0
0,0,0,0,0,0,17,0,0,0,0,0
endlayer

layer
0,0,0,0,0,0,0,0,0,0,0,0
0,0,0,0,3,0,0,3,0,0,0,0
0,0,2,5,3,9,9,3,8,2,0,0
0,0,8,0,0,0,0,0,0,5,0,0
0,3,3,0,0,0,0,0,0,3,3,0
0,0,9,0,0,0,0,0,0,9,0,0
0,0,9,0,0,0,0,0,0,9,0,0
0,3,3,0,0,0,0,0,0,3,3,0
0,0,5,0,0,0,0,0,0,8,0,0
0,0,2,8,3,9,9,3,5,2,0,0
0,0,0,0,3,0,0,3,0,0,0,0
0,0,0,0,0,0,0,0,0,0,0,0
endlayer

layer
0,0,0,0,0,0,0,0,0,0,0,0
0,0,0,0,0,3,3,0,0,0,0,0
0,0,2,5,7,3,3,10,8,2,0,0
0,0,8,0,0,0,0,0,0,5,0,0
0,0,10,0,0,0,0,0,0,7,0,0
0,3,3,0,0,0,0,0,0,3,3,0
0,3,3,0,0,0,0,0,0,3,3,0
0,0,7,0,0,0,0,0,0,10,0,0
0,0,5,0,0,0,0,0,0,8,0,0
0,0,2,8,10,3,3,7,5,2,0,0
0,0,0,0,0,3,3,0,0,0,0,0
0,0,0,0,0,0,0,0,0,0,0,0
endlayer

layer
0,0,0,0,0,0,0,0,0,0,0,0
0,0,0,3,0,0,0,0,3,0,0,0
0,0,2,3,7,7,10,10,3,2,0,0
0,3,3,0,0,0,0,0,0,3,3,0
0,0,10,0,0,0,0,0,0,7,0,0
0,0,10,0,0,0,0,0,0,7,0,0
0,0,7,0,0,0,0,0,0,10,0,0
0,0,7,0,0,0,0,0,0,10,0,0
0,3,3,0,0,0,0,0,0,3,3,0
0,0,2,3,10,10,7,7,3,2,0,0
0,0,0,3,0,0,0,0,3,0,0,0
0,0,0,0,0,0,0,0,0,0,0,0
endlayer

layer
0,0,0,0,0,0,0,0,0,0,0,0
0,0,0,0,0,0,0,0,0,0,0,0
0,0,2,2,2,2,2,2,2,2,0,0
0,0,2,3,6,6,8,8,3,2,0,0
0,0,2,9,11,11,3,10,10,2,0,0
0,0,2,9,8,9,9,3,10,2,0,0
0,0,2,3,8,3,9,3,7,2,0,0
0,0,2,4,6,6,3,7,7,2,0,0
0,0,2,3,4,5,5,5,3,2,0,0
0,0,2,2,2,2,2,2,2,2,0,0
0,0,0,0,0,0,0,0,0,0,0,0
0,0,0,0,0,0,0,0,0,0,0,0
endlayer

layer
0,0,0,0,0,0,0,0,0,0,0,0
0,0,0,0,0,0,0,0,0,0,0,0
0,0,0,0,0,0,0,0,0,0,0,0
0,0,0,3,0,0,0,0,3,0,0,0
0,0,0,0,0,0,3,0,0,0,0,0
0,0,0,0,0,0,0,3,0,0,0,0
0,0,0,3,0,3,0,3,0,0,0,0
0,0,0,0,0,0,3,0,0,0,0,0
0,0,0,3,0,0,0,0,3,0,0,0
0,0,0,0,0,0,0,0,0,0,0,0
0,0,0,0,0,0,0,0,0,0,0,0
0,0,0,0,0,0,0,0,0,0,0,0
endlayer

