
# Created by Ruins mod version 15.1 Ingame Parser
# authoring Player: Tmtravlr

weight=1
embed_into_distance=1
acceptable_target_blocks=
unacceptable_target_blocks=flowing_water,water,flowing_lava,lava
dimensions=10,9,9
leveling_buffer=-1
preserve_water=0
preserve_lava=0
preserve_plants=0
max_cut_in=0
allowable_overhang=0

rule1=0,100,preserveBlock
rule2=0,100,lootplusplus:spiral.gingerbread-0
rule3=0,100,lootplusplus:spiral.brown_candy-0
rule4=0,100,lootplusplus:spiral.white_candy-0
rule5=0,100,lootplusplus:spiral.icing_fence-0
rule6=0,100,lootplusplus:spiral.gingerbread_stairs-3
rule7=0,100,lootplusplus:spiral.gingerbread_stairs-2
rule8=0,100,lootplusplus:spiral.gingerbread_stairs-1
rule9=0,100,IInventory;minecraft:chest;lootplusplus:spiral.yellow_candy_item#{display:{Lore:[0:\"Lemony!\"]}}#0#2+lootplusplus:spiral.lime_candy_item#{display:{Lore:[0:\"Sour Lime!\"]}}#0#3+minecraft:cookie#1#0#4+lootplusplus:spiral.cyan_candy_item#{display:{Lore:[0:\"Cotton Candy!\"]}}#0#5+lootplusplus:spiral.blue_candy_item#{display:{Lore:[0:\"Blueberry!\"]}}#0#6+lootplusplus:spiral.orange_candy_item#{display:{Lore:[0:\"Tangy Orange!\"]}}#0#10+minecraft:cookie#1#0#12+minecraft:cake#1#0#13+minecraft:cookie#1#0#14+lootplusplus:spiral.purple_candy_item#{display:{Lore:[0:\"Grape!\"]}}#0#16+lootplusplus:spiral.red_candy_item#{display:{Lore:[0:\"Strawberry!\"]}}#0#18+minecraft:cookie#1#0#22+lootplusplus:spiral.magenta_candy_item#{display:{Lore:[0:\"Cherry!\"]}}#0#26-5
rule10=0,100,lootplusplus:spiral.gingerbread_stairs-0
rule11=0,100,lootplusplus:spiral.spiral_lollipop-0
rule12=0,100,minecraft:cake-0
rule13=0,100,lootplusplus:spiral.gingerbread_stairs-7
rule14=0,100,lootplusplus:spiral.gingerbread_stairs-6
rule15=0,100,lootplusplus:spiral.green_candy-0
rule16=0,100,lootplusplus:spiral.yellow_candy-0
rule17=0,100,lootplusplus:spiral.magenta_candy-0
rule18=0,100,lootplusplus:spiral.red_candy-0
rule19=0,100,lootplusplus:spiral.cyan_candy-0
rule20=0,100,lootplusplus:spiral.lime_candy-0
rule21=0,100,lootplusplus:spiral.pink_candy-0
rule22=0,100,lootplusplus:spiral.orange_candy-0
rule23=0,100,lootplusplus:spiral.light_blue_candy-0
rule24=0,100,lootplusplus:spiral.purple_candy-0
rule25=0,100,lootplusplus:spiral.blue_candy-0

layer
1,1,1,1,1,1,1,1,1
1,2,2,2,2,2,2,2,1
1,2,2,2,2,2,2,2,1
1,2,2,2,2,2,2,2,1
1,2,2,2,3,2,2,2,1
1,2,2,2,2,2,2,2,1
1,2,2,2,2,2,2,2,1
1,2,2,2,2,2,2,2,1
1,1,1,4,4,4,1,1,1
endlayer

layer
0,5,0,0,0,0,0,5,0
5,2,2,2,2,2,2,2,5
0,2,3,7,5,6,3,2,0
0,2,8,0,0,0,8,2,0
0,2,5,0,9,0,5,2,0
0,2,10,0,0,0,10,2,0
0,2,3,0,0,0,3,2,0
5,2,2,7,0,6,2,2,5
0,5,0,0,0,0,0,5,0
endlayer

layer
0,5,0,0,0,0,0,5,0
5,2,2,0,0,0,2,2,5
0,2,11,0,12,0,11,2,0
0,0,0,0,0,0,0,0,0
0,0,12,0,0,0,12,0,0
0,0,0,0,0,0,0,0,0
0,2,11,0,0,0,11,2,0
5,2,2,14,0,13,2,2,5
0,5,0,0,0,0,0,5,0
endlayer

layer
0,5,0,0,0,0,0,5,0
5,2,2,15,16,15,2,2,5
0,2,0,0,0,0,0,2,0
0,18,0,0,0,0,0,17,0
0,16,0,0,0,0,0,16,0
0,18,0,0,0,0,0,17,0
0,2,0,0,0,0,0,2,0
5,2,2,19,16,19,2,2,5
0,5,0,0,0,0,0,5,0
endlayer

layer
0,5,5,5,0,5,5,5,0
5,2,2,2,20,2,2,2,5
5,2,5,5,0,5,5,2,5
5,2,5,0,0,0,5,2,5
0,22,0,0,0,0,0,21,0
5,2,5,0,0,0,5,2,5
5,2,5,0,0,5,5,2,5
5,2,2,2,23,2,2,2,5
0,5,5,5,0,5,5,5,0
endlayer

layer
6,24,0,5,5,5,0,18,7
6,2,4,2,2,2,4,2,7
6,2,14,5,5,5,13,2,7
6,2,14,0,0,0,13,2,7
6,2,14,0,0,0,13,2,7
6,2,14,0,0,0,13,2,7
6,2,14,5,5,5,13,2,7
6,2,4,2,2,2,4,2,7
6,18,0,5,5,5,0,24,7
endlayer

layer
0,6,25,0,0,0,22,7,0
0,6,2,4,0,4,2,7,0
0,6,2,14,0,13,2,7,0
0,6,2,14,0,13,2,7,0
0,6,2,14,0,13,2,7,0
0,6,2,14,0,13,2,7,0
0,6,2,14,0,13,2,7,0
0,6,2,4,0,4,2,7,0
0,6,22,0,0,0,25,7,0
endlayer

layer
0,0,6,19,0,16,7,0,0
0,0,6,2,4,2,7,0,0
0,0,6,2,0,2,7,0,0
0,0,6,2,0,2,7,0,0
0,0,6,2,0,2,7,0,0
0,0,6,2,0,2,7,0,0
0,0,6,2,0,2,7,0,0
0,0,6,2,4,2,7,0,0
0,0,6,16,0,19,7,0,0
endlayer

layer
0,0,0,6,20,7,0,0,0
0,0,0,6,24,7,0,0,0
0,0,0,6,25,7,0,0,0
0,0,0,6,19,7,0,0,0
0,0,0,6,20,7,0,0,0
0,0,0,6,16,7,0,0,0
0,0,0,6,22,7,0,0,0
0,0,0,6,18,7,0,0,0
0,0,0,6,20,7,0,0,0
endlayer

layer
0,0,0,0,5,0,0,0,0
0,0,0,0,5,0,0,0,0
0,0,0,0,5,0,0,0,0
0,0,0,0,5,0,0,0,0
0,0,0,0,5,0,0,0,0
0,0,0,0,5,0,0,0,0
0,0,0,0,5,0,0,0,0
0,0,0,0,5,0,0,0,0
0,0,0,0,5,0,0,0,0
endlayer

