
# Created by Ruins mod version 15.1 Ingame Parser
# authoring Player: Tmtravlr

weight=1
embed_into_distance=7
acceptable_target_blocks=
unacceptable_target_blocks=flowing_water,water,flowing_lava,lava
dimensions=7,9,9
leveling_buffer=-1
preserve_water=0
preserve_lava=0
preserve_plants=0
max_cut_in=0
allowable_overhang=0

rule1=0,100,minecraft:stained_hardened_clay-1
rule2=0,100,minecraft:planks-4
rule3=0,100,minecraft:sand-1
rule4=0,100,minecraft:lit_pumpkin-0
rule5=0,100,minecraft:lit_pumpkin-2
rule6=0,100,minecraft:nether_brick-0
rule7=0,100,minecraft:ladder-5
rule8=0,100,CommandBlock:testruin spiral/dungeon/azkor ~ ~ ~:@
rule9=0,100,minecraft:lit_pumpkin-1
rule10=0,100,minecraft:lit_pumpkin-3
rule11=0,100,lootplusplus:command_block_trigger-0
rule12=0,100,preserveBlock
rule13=0,100,minecraft:stone_brick_stairs-0
rule14=0,100,minecraft:nether_brick_stairs-0
rule15=0,100,minecraft:nether_brick_stairs-2
rule16=0,100,minecraft:nether_brick_stairs-3
rule17=0,100,minecraft:nether_brick_stairs-1
rule18=0,100,minecraft:stone_brick_stairs-1

layer
1,1,1,1,1,1,1,1,1
1,1,1,1,1,1,1,1,1
1,1,1,1,1,1,1,1,1
1,1,1,1,1,1,1,1,1
1,1,1,1,1,1,1,1,1
1,1,1,1,1,1,1,1,1
1,1,1,1,1,1,1,1,1
1,1,1,1,1,1,1,1,1
1,1,1,1,1,1,1,1,1
endlayer

layer
1,3,1,2,3,1,2,1,1
2,0,0,0,0,0,0,0,4
5,0,0,0,0,0,0,0,1
2,0,0,0,6,0,0,0,3
1,0,0,0,7,0,0,0,2
3,0,0,0,8,0,0,0,1
2,0,0,0,0,0,0,0,2
1,0,0,0,0,0,0,0,5
1,2,10,3,2,3,9,2,1
endlayer

layer
1,3,10,3,1,2,1,9,1
4,0,0,0,0,0,0,0,1
3,0,0,0,0,0,0,0,2
1,0,0,0,6,0,0,0,1
3,0,0,0,7,0,0,0,5
4,0,0,0,0,0,0,0,1
1,0,0,0,0,0,0,0,2
2,0,0,0,0,0,0,0,2
1,10,2,3,1,2,2,3,1
endlayer

layer
1,1,2,1,9,3,2,2,1
1,0,0,0,0,0,0,0,2
2,0,0,0,0,0,0,0,3
3,0,0,0,6,0,0,0,2
3,0,0,0,7,0,0,0,3
5,0,0,0,11,0,0,0,3
3,0,0,0,0,0,0,0,4
3,0,0,0,0,0,0,0,1
1,2,3,1,9,3,1,1,1
endlayer

layer
1,1,1,2,1,3,1,10,1
2,0,0,0,0,0,0,0,3
4,0,0,0,0,0,0,0,5
1,0,0,0,6,0,0,0,1
2,0,0,0,7,0,0,0,1
1,0,0,0,0,0,0,0,2
2,0,0,0,0,0,0,0,3
3,0,0,0,0,0,0,0,3
1,3,2,2,1,3,3,2,1
endlayer

layer
6,6,6,6,6,6,6,6,6
6,6,6,6,6,6,6,6,6
6,6,6,6,6,6,6,6,6
6,6,6,6,6,6,6,6,6
6,6,6,6,7,6,6,6,6
6,6,6,6,6,6,6,6,6
6,6,6,6,6,6,6,6,6
6,6,6,6,6,6,6,6,6
6,6,6,6,6,6,6,6,6
endlayer

layer
12,12,12,12,12,12,12,12,12
12,12,12,12,12,12,12,12,12
12,12,13,14,14,14,13,12,12
12,12,16,17,17,16,15,12,12
12,12,16,15,0,16,15,12,12
12,12,16,15,14,14,15,12,12
12,12,18,17,17,17,18,12,12
12,12,12,12,12,12,12,12,12
12,12,12,12,12,12,12,12,12
endlayer

