
# Created by Ruins mod version 15.1 Ingame Parser
# authoring Player: Tmtravlr

weight=1
embed_into_distance=12
acceptable_target_blocks=
unacceptable_target_blocks=flowing_water,water,flowing_lava,lava
dimensions=17,45,45
leveling_buffer=-1
preserve_water=0
preserve_lava=0
preserve_plants=0
max_cut_in=0
allowable_overhang=0

rule1=0,100,TConstruct:decoration.multibrick-9
rule2=0,100,TConstruct:decoration.multibrick-1
rule3=0,100,minecraft:glowstone-0
rule4=0,100,CommandBlock:setblock ~ ~ ~ lootplusplus:command_trigger_block 0 replace {CommandList:[0:\"lppblockdata ~ ~2 ~2 {Items:[]}\", 1:\"lppblockdata ~ ~2 ~4 {Items:[]}\", 2:\"setblock ~ ~1 ~2 air 0 replace\", 3:\"setblock ~ ~1 ~4 air 0 replace\", 4:\"setblock ~ ~ ~2 TConstruct:decoration.multibrick 1\", 5:\"setblock ~ ~ ~4 TConstruct:decoration.multibrick 1\", 6:\"setblock ~ ~2 ~2 air 0 replace\", 7:\"setblock ~ ~2 ~4 air 0 replace\"]}:@
rule5=0,100,CommandBlock:setblock ~ ~ ~ lootplusplus:command_trigger_block 0 replace {CommandList:[0:\"lppblockdata ~ ~2 ~-2 {Items:[]}\", 1:\"lppblockdata ~ ~2 ~2 {Items:[]}\", 2:\"setblock ~ ~1 ~2 air 0 replace\", 3:\"setblock ~ ~1 ~-2 air 0 replace\", 4:\"setblock ~ ~ ~2 TConstruct:decoration.multibrick 1\", 5:\"setblock ~ ~ ~-2 TConstruct:decoration.multibrick 1\", 6:\"setblock ~ ~2 ~2 air 0 replace\", 7:\"setblock ~ ~2 ~-2 air 0 replace\"]}:@
rule6=0,100,CommandBlock:setblock ~ ~ ~ lootplusplus:command_trigger_block 0 replace {CommandList:[0:\"lppblockdata ~ ~2 ~-2 {Items:[]}\", 1:\"lppblockdata ~ ~2 ~-4 {Items:[]}\", 2:\"setblock ~ ~1 ~-2 air 0 replace\", 3:\"setblock ~ ~1 ~-4 air 0 replace\", 4:\"setblock ~ ~ ~-2 TConstruct:decoration.multibrick 1\", 5:\"setblock ~ ~ ~-4 TConstruct:decoration.multibrick 1\", 6:\"setblock ~ ~2 ~-2 air 0 replace\", 7:\"setblock ~ ~2 ~-4 air 0 replace\"]}:@
rule7=0,100,TConstruct:SpeedBlock-1
rule8=0,100,TConstruct:SpeedBlock-3
rule9=0,100,TConstruct:SpeedBlock-0
rule10=0,100,CommandBlock:testruin spiral/dungeon/dungeon_room ~ ~ ~:@
rule11=0,100,TConstruct:SpeedBlock-2
rule12=0,100,CommandBlock:testruin spiral/dungeon/dungeon_merchants ~ ~ ~:@
rule13=0,100,minecraft:ladder-3
rule14=0,100,TConstruct:SpeedBlock-6
rule15=1,100,StandingSign:null:Spiral Dungeon:Secret Shop:null-4
rule16=1,100,StandingSign:null:Choose One:Reward:null-4
rule17=0,100,CommandBlock:testruin spiral/dungeon/dungeon_boss ~ ~ ~:@
rule18=0,100,minecraft:stained_hardened_clay-3
rule19=0,100,minecraft:stained_hardened_clay-14
rule20=0,100,minecraft:stained_hardened_clay-4
rule21=0,100,lootplusplus:command_block_trigger-0
rule22=2,100,minecraft:torch-2
rule23=2,100,minecraft:torch-4
rule24=2,100,minecraft:torch-1
rule25=0,100,IInventory;minecraft:trapped_chest;lootplusplus:loot_item#{Type:\"spiralTreats\",PrimaryColor:11989787,SecondaryColor:10643166}#0#4+lootplusplus:loot_item#{Type:\"spiralTreats\",PrimaryColor:11989787,SecondaryColor:10643166}#0#12+lootplusplus:spiral.spiral_sword#1#0#13+lootplusplus:loot_item#{Type:\"spiralTreats\",PrimaryColor:11989787,SecondaryColor:10643166}#0#14+lootplusplus:loot_item#{Type:\"spiralTreats\",PrimaryColor:11989787,SecondaryColor:10643166}#0#22-4
rule26=0,100,IInventory;minecraft:trapped_chest;minecraft:golden_apple#1#0#4+minecraft:golden_apple#1#0#12+lootplusplus:spiral.spiral_chestplate#1#0#13+minecraft:golden_apple#1#0#14+minecraft:golden_apple#1#0#22-4
rule27=0,100,IInventory;minecraft:trapped_chest;lootplusplus:spiral.spiral_lollipop_item#1#0#4+lootplusplus:spiral.spiral_lollipop_item#1#0#12+lootplusplus:spiral.spiral_triple_bow#{ench:[0:{lvl:1s,id:51s}]}#0#13+lootplusplus:spiral.spiral_lollipop_item#1#0#14+minecraft:arrow#1#0#16+lootplusplus:spiral.spiral_lollipop_item#1#0#22-4
rule28=0,100,minecraft:lit_redstone_lamp-0
rule29=0,100,preserveBlock
rule30=0,100,minecraft:lever-14
rule31=0,100,minecraft:nether_brick-0
rule32=0,100,minecraft:stonebrick-0
rule33=0,100,minecraft:cobblestone_wall-1
rule34=0,100,minecraft:cobblestone_wall-0
rule35=0,100,minecraft:nether_brick_stairs-2
rule36=0,100,minecraft:nether_brick_stairs-0
rule37=0,100,minecraft:nether_brick_stairs-3
rule38=0,100,minecraft:stone_brick_stairs-5
rule39=0,100,minecraft:jungle_stairs-5
rule40=0,100,minecraft:stone_brick_stairs-6
rule41=0,100,minecraft:jungle_stairs-7
rule42=0,100,minecraft:jungle_stairs-6
rule43=0,100,minecraft:nether_brick_stairs-1
rule44=0,100,minecraft:stone_brick_stairs-7
rule45=0,100,minecraft:jungle_stairs-4
rule46=0,100,minecraft:stone_brick_stairs-2
rule47=0,100,minecraft:jungle_stairs-0
rule48=0,100,minecraft:stone_brick_stairs-0
rule49=0,100,minecraft:jungle_stairs-2
rule50=0,100,minecraft:jungle_stairs-3
rule51=0,100,minecraft:jungle_stairs-1
rule52=0,100,minecraft:stone_brick_stairs-3

layer
1,1,1,2,2,2,1,1,1,1,1,1,2,2,2,1,1,1,1,1,1,2,2,2,1,1,1,1,1,1,2,2,2,1,1,1,1,1,1,2,2,2,1,1,1
1,2,1,1,1,1,1,2,1,1,2,1,1,1,1,1,2,1,1,2,1,1,1,1,1,2,1,1,2,1,1,1,1,1,2,1,1,2,1,1,1,1,1,2,1
1,1,1,2,2,2,1,1,1,1,1,1,2,2,2,1,1,1,1,1,1,2,2,2,1,1,1,1,1,1,2,2,2,1,1,1,1,1,1,2,2,2,1,1,1
2,1,2,1,1,1,2,1,2,2,1,2,1,1,1,2,1,2,2,1,2,1,1,1,2,1,2,2,1,2,1,1,1,2,1,2,2,1,2,1,1,1,2,1,2
2,1,2,1,2,1,2,1,2,2,1,2,1,2,1,2,1,2,2,1,2,1,2,1,2,1,2,2,1,2,1,2,1,2,1,2,2,1,2,1,2,1,2,1,2
2,1,2,1,1,2,1,1,2,2,1,2,1,1,2,1,1,2,2,1,2,1,1,2,1,1,2,2,1,2,1,1,2,1,1,2,2,1,2,1,1,2,1,1,2
1,1,1,2,1,1,1,2,1,1,1,1,2,1,1,1,2,1,1,1,1,2,1,1,1,2,1,1,1,1,2,1,1,1,2,1,1,1,1,2,1,1,1,2,1
1,2,1,1,2,2,2,1,1,1,2,1,1,2,2,2,1,1,1,2,1,1,2,2,2,1,1,1,2,1,1,2,2,2,1,1,1,2,1,1,2,2,2,1,1
1,1,1,1,1,1,1,1,1,1,1,1,1,1,1,1,1,1,1,1,1,1,1,1,1,1,1,1,1,1,1,1,1,1,1,1,1,1,1,1,1,1,1,1,1
1,1,1,2,2,2,1,1,1,1,1,1,2,2,2,1,1,1,1,1,1,2,2,2,1,1,1,1,1,1,2,2,2,1,1,1,1,1,1,2,2,2,1,1,1
1,2,1,1,1,1,1,2,1,1,2,1,1,1,1,1,2,1,1,2,1,1,1,1,1,2,1,1,2,1,1,1,1,1,2,1,1,2,1,1,1,1,1,2,1
1,1,1,2,2,2,1,1,1,1,1,1,2,2,2,1,1,1,1,1,1,2,2,2,1,1,1,1,1,1,2,2,2,1,1,1,1,1,1,2,2,2,1,1,1
2,1,2,1,1,1,2,1,2,2,1,2,1,1,1,2,1,2,2,1,2,1,1,1,2,1,2,2,1,2,1,1,1,2,1,2,2,1,2,1,1,1,2,1,2
2,1,2,1,2,1,2,1,2,2,1,2,1,2,1,2,1,2,2,1,2,1,2,1,2,1,2,2,1,2,1,2,1,2,1,2,2,1,2,1,2,1,2,1,2
2,1,2,1,1,2,1,1,2,2,1,2,1,1,2,1,1,2,2,1,2,1,1,2,1,1,2,2,1,2,1,1,2,1,1,2,2,1,2,1,1,2,1,1,2
1,1,1,2,1,1,1,2,1,1,1,1,2,1,1,1,2,1,1,1,1,2,1,1,1,2,1,1,1,1,2,1,1,1,2,1,1,1,1,2,1,1,1,2,1
1,2,1,1,2,2,2,1,1,1,2,1,1,2,2,2,1,1,1,2,1,1,2,2,2,1,1,1,2,1,1,2,2,2,1,1,1,2,1,1,2,2,2,1,1
1,1,1,1,1,1,1,1,1,1,1,1,1,1,1,1,1,1,1,1,1,1,1,1,1,1,1,1,1,1,1,1,1,1,1,1,1,1,1,1,1,1,1,1,1
1,1,1,2,2,2,1,1,1,1,1,1,2,2,2,1,1,1,1,1,1,2,2,2,1,1,1,1,1,1,2,2,2,1,1,1,1,1,1,2,2,2,1,1,1
1,2,1,1,1,1,1,2,1,1,2,1,1,1,1,1,2,1,1,2,1,1,1,1,1,2,1,1,2,1,1,1,1,1,2,1,1,2,1,1,1,1,1,2,1
1,1,1,2,2,2,1,1,1,1,1,1,2,2,2,1,1,1,1,1,1,2,2,2,1,1,1,1,1,1,2,2,2,1,1,1,1,1,1,2,2,2,1,1,1
2,1,2,1,1,1,2,1,2,2,1,2,1,1,1,2,1,2,2,1,2,1,1,1,2,1,2,2,1,2,1,1,1,2,1,2,2,1,2,1,1,1,2,1,2
2,1,2,1,2,1,2,1,2,2,1,2,1,2,1,2,1,2,2,1,2,1,2,1,2,1,2,2,1,2,1,2,1,2,1,2,2,1,2,1,2,1,2,1,2
2,1,2,1,1,2,1,1,2,2,1,2,1,1,2,1,1,2,2,1,2,1,1,2,1,1,2,2,1,2,1,1,2,1,1,2,2,1,2,1,1,2,1,1,2
1,1,1,2,1,1,1,2,1,1,1,1,2,1,1,1,2,1,1,1,1,2,1,1,1,2,1,1,1,1,2,1,1,1,2,1,1,1,1,2,1,1,1,2,1
1,2,1,1,2,2,2,1,1,1,2,1,1,2,2,2,1,1,1,2,1,1,2,2,2,1,1,1,2,1,1,2,2,2,1,1,1,2,1,1,2,2,2,1,1
1,1,1,1,1,1,1,1,1,1,1,1,1,1,1,1,1,1,1,1,1,1,1,1,1,1,1,1,1,1,1,1,1,1,1,1,1,1,1,1,1,1,1,1,1
1,1,1,2,2,2,1,1,1,1,1,1,2,2,2,1,1,1,1,1,1,2,2,2,1,1,1,1,1,1,2,2,2,1,1,1,1,1,1,2,2,2,1,1,1
1,2,1,1,1,1,1,2,1,1,2,1,1,1,1,1,2,1,1,2,1,1,1,1,1,2,1,1,2,1,1,1,1,1,2,1,1,2,1,1,1,1,1,2,1
1,1,1,2,2,2,1,1,1,1,1,1,2,2,2,1,1,1,1,1,1,2,2,2,1,1,1,1,1,1,2,2,2,1,1,1,1,1,1,2,2,2,1,1,1
2,1,2,1,1,1,2,1,2,2,1,2,1,1,1,2,1,2,2,1,2,1,1,1,2,1,2,2,1,2,1,1,1,2,1,2,2,1,2,1,1,1,2,1,2
2,1,2,1,2,1,2,1,2,2,1,2,1,2,1,2,1,2,2,1,2,1,2,1,2,1,2,2,1,2,1,2,1,2,1,2,2,1,2,1,2,1,2,1,2
2,1,2,1,1,2,1,1,2,2,1,2,1,1,2,1,1,2,2,1,2,1,1,2,1,1,2,2,1,2,1,1,2,1,1,2,2,1,2,1,1,2,1,1,2
1,1,1,2,1,1,1,2,1,1,1,1,2,1,1,1,2,1,1,1,1,2,1,1,1,2,1,1,1,1,2,1,1,1,2,1,1,1,1,2,1,1,1,2,1
1,2,1,1,2,2,2,1,1,1,2,1,1,2,2,2,1,1,1,2,1,1,2,2,2,1,1,1,2,1,1,2,2,2,1,1,1,2,1,1,2,2,2,1,1
1,1,1,1,1,1,1,1,1,1,1,1,1,1,1,1,1,1,1,1,1,1,1,1,1,1,1,1,1,1,1,1,1,1,1,1,1,1,1,1,1,1,1,1,1
1,1,1,2,2,2,1,1,1,1,1,1,2,2,2,1,1,1,1,1,1,2,2,2,1,1,1,1,1,1,2,2,2,1,1,1,1,1,1,2,2,2,1,1,1
1,2,1,1,1,1,1,2,1,1,2,1,1,1,1,1,2,1,1,2,1,1,1,1,1,2,1,1,2,1,1,1,1,1,2,1,1,2,1,1,1,1,1,2,1
1,1,1,2,2,2,1,1,1,1,1,1,2,2,2,1,1,1,1,1,1,2,2,2,1,1,1,1,1,1,2,2,2,1,1,1,1,1,1,2,2,2,1,1,1
2,1,2,1,1,1,2,1,2,2,1,2,1,1,1,2,1,2,2,1,2,1,1,1,2,1,2,2,1,2,1,1,1,2,1,2,2,1,2,1,1,1,2,1,2
2,1,2,1,2,1,2,1,2,2,1,3,1,3,1,3,1,2,2,1,2,1,2,1,2,1,2,2,1,2,1,2,1,2,1,2,2,1,2,1,2,1,2,1,2
2,1,2,1,1,2,1,1,2,2,1,2,1,1,2,1,1,2,2,1,2,1,1,2,1,1,2,2,1,2,1,1,2,1,1,2,2,1,2,1,1,2,1,1,2
1,1,1,2,1,1,1,2,1,1,1,6,2,5,1,4,2,1,1,1,1,2,1,1,1,2,1,1,1,1,2,1,1,1,2,1,1,1,1,2,1,1,1,2,1
1,2,1,1,2,2,2,1,1,1,2,1,1,2,2,2,1,1,1,2,1,1,2,2,2,1,1,1,2,1,1,2,2,2,1,1,1,2,1,1,2,2,2,1,1
1,1,1,1,1,1,1,1,1,1,1,1,1,1,1,1,1,1,1,1,1,1,1,1,1,1,1,1,1,1,1,1,1,1,1,1,1,1,1,1,1,1,1,1,1
endlayer

layer
7,7,8,7,7,8,7,7,7,7,7,8,7,7,8,7,7,7,7,7,8,7,7,8,7,7,7,7,7,8,7,7,8,7,7,7,7,7,8,7,7,8,7,7,7
7,0,0,0,0,0,0,0,8,7,0,0,0,0,0,0,0,8,7,0,0,0,0,0,0,0,8,7,0,0,0,0,0,0,0,8,7,0,0,0,0,0,0,0,8
8,0,0,0,0,0,0,0,7,8,0,0,0,0,0,0,0,7,8,0,0,0,0,0,0,0,7,8,0,0,0,0,0,0,0,7,8,0,0,0,0,0,0,0,7
7,0,0,0,0,0,0,0,9,9,0,0,0,0,0,0,0,9,9,0,0,0,0,0,0,0,9,9,0,0,0,0,0,0,0,9,9,0,0,0,0,0,0,0,7
7,0,0,0,10,0,0,0,11,9,0,0,0,10,0,0,0,11,9,0,0,0,10,0,0,0,11,9,0,0,0,12,0,0,0,11,9,0,0,0,10,0,0,0,8
8,0,0,0,0,0,0,0,9,11,0,0,0,0,0,0,0,9,11,0,0,0,0,0,0,0,9,11,0,0,0,0,0,0,0,9,11,0,0,0,0,0,0,0,7
7,0,0,0,0,0,0,0,7,7,0,0,0,0,0,0,0,7,7,0,0,0,0,0,0,0,7,7,0,0,0,0,0,0,0,7,7,0,0,0,0,0,0,0,7
7,0,0,0,0,0,0,0,7,7,0,0,0,0,0,0,0,7,7,0,0,0,0,0,0,0,7,7,0,0,0,0,0,0,0,7,7,0,0,0,0,0,0,0,7
7,8,7,9,11,9,7,8,7,7,8,7,9,11,9,7,8,7,7,8,7,9,11,9,7,8,7,7,8,7,9,11,9,7,8,7,7,8,7,9,11,9,7,8,7
7,7,8,9,9,11,7,7,7,7,7,8,9,9,11,7,7,7,7,7,8,9,9,11,7,7,7,7,7,8,9,9,11,7,7,7,7,7,8,9,9,11,7,7,7
7,0,0,0,0,0,0,0,8,7,0,0,0,0,0,0,0,8,7,0,0,0,0,0,0,0,8,7,0,0,0,0,0,0,0,8,7,0,0,0,0,0,0,0,8
8,0,0,0,0,0,0,0,7,8,0,0,0,0,0,0,0,7,8,0,0,0,0,0,0,0,7,8,0,0,0,0,0,0,0,7,8,0,0,0,0,0,0,0,7
7,0,0,0,0,0,0,0,9,9,0,0,0,0,0,0,0,9,9,0,0,0,0,0,0,0,9,9,0,0,0,0,0,0,0,9,9,0,0,0,0,0,0,0,7
7,0,0,0,10,0,0,0,11,9,0,0,0,10,0,0,0,11,9,0,0,0,10,0,0,0,11,9,0,0,0,10,0,0,0,11,9,0,0,0,10,0,0,0,8
8,0,0,0,0,0,0,0,9,11,0,0,0,0,0,0,0,9,11,0,0,0,0,0,0,0,9,11,0,0,0,0,0,0,0,9,11,0,0,0,0,0,0,0,7
7,0,0,0,0,0,0,0,7,7,0,0,0,0,0,0,0,7,7,0,0,0,0,0,0,0,7,7,0,0,0,0,0,0,0,7,7,0,0,0,0,0,0,0,7
7,0,0,0,0,0,0,0,7,7,0,0,0,0,0,0,0,7,7,0,0,0,0,0,0,0,7,7,0,0,0,0,0,0,0,7,7,0,0,0,0,0,0,0,7
7,8,7,9,11,9,7,8,7,7,8,7,9,11,9,7,8,7,7,8,7,0,0,0,7,8,7,7,8,7,9,11,9,7,8,7,7,8,7,9,11,9,7,8,7
7,7,8,9,9,11,7,7,7,7,7,8,9,9,11,7,7,7,7,7,8,0,0,0,7,7,7,7,7,8,9,9,11,7,7,7,7,7,8,9,9,11,7,7,7
7,0,0,0,0,0,0,0,8,7,0,0,0,0,0,0,0,8,7,0,0,0,0,0,0,0,8,7,0,0,0,0,0,0,0,8,7,0,0,0,0,0,0,0,8
8,0,0,0,0,0,0,0,7,8,0,0,0,0,0,0,0,7,8,0,0,0,0,0,0,0,7,8,0,0,0,0,0,0,0,7,8,0,0,0,0,0,0,0,7
7,0,0,0,0,0,0,0,9,9,0,0,0,0,0,0,0,0,0,0,0,0,0,0,0,0,0,0,0,0,0,0,0,0,0,9,9,0,0,0,0,0,0,0,7
7,0,0,0,10,0,0,0,11,9,0,0,0,10,0,0,0,0,0,0,0,0,13,1,0,0,0,0,0,0,0,10,0,0,0,11,9,0,0,0,10,0,0,0,8
8,0,0,0,0,0,0,0,9,11,0,0,0,0,0,0,0,0,0,0,0,0,0,0,0,0,0,0,0,0,0,0,0,0,0,9,11,0,0,0,0,0,0,0,7
7,0,0,0,0,0,0,0,7,7,0,0,0,0,0,0,0,7,7,0,0,0,0,0,0,0,7,7,0,0,0,0,0,0,0,7,7,0,0,0,0,0,0,0,7
7,0,0,0,0,0,0,0,7,7,0,0,0,0,0,0,0,7,7,0,0,0,0,0,0,0,7,7,0,0,0,0,0,0,0,7,7,0,0,0,0,0,0,0,7
7,8,7,9,11,9,7,8,7,7,8,7,9,11,9,7,8,7,7,8,7,0,0,0,7,8,7,7,8,7,9,11,9,7,8,7,7,8,7,9,11,9,7,8,7
7,7,8,9,9,11,7,7,7,7,7,8,9,9,11,7,7,7,7,7,8,0,0,0,7,7,7,7,7,8,9,9,11,7,7,7,7,7,8,9,9,11,7,7,7
7,0,0,0,0,0,0,0,8,7,0,0,0,0,0,0,0,8,7,0,0,0,0,0,0,0,8,7,0,0,0,0,0,0,0,8,7,0,0,0,0,0,0,0,8
8,0,0,0,0,0,0,0,7,8,0,0,0,0,0,0,0,7,8,0,0,0,0,0,0,0,7,8,0,0,0,0,0,0,0,7,8,0,0,0,0,0,0,0,7
7,0,0,0,0,0,0,0,9,9,0,0,0,0,0,0,0,9,9,0,0,0,0,0,0,0,9,9,0,0,0,0,0,0,0,9,9,0,0,0,0,0,0,0,7
7,0,0,0,10,0,0,0,11,9,0,0,0,10,0,0,0,11,9,0,0,0,10,0,0,0,11,9,0,0,0,10,0,0,0,11,9,0,0,0,10,0,0,0,8
8,0,0,0,0,0,0,0,9,11,0,0,0,0,0,0,0,9,11,0,0,0,0,0,0,0,9,11,0,0,0,0,0,0,0,9,11,0,0,0,0,0,0,0,7
7,0,0,0,0,0,0,0,7,7,0,0,0,0,0,0,0,7,7,0,0,0,0,0,0,0,7,7,0,0,0,0,0,0,0,7,7,0,0,0,0,0,0,0,7
7,0,0,0,0,0,0,0,7,7,0,0,0,0,0,0,0,7,7,0,0,0,0,0,0,0,7,7,0,0,0,0,0,0,0,7,7,0,0,0,0,0,0,0,7
7,8,7,9,11,9,7,8,7,7,8,7,7,14,7,7,8,7,7,8,7,9,11,9,7,8,7,7,8,7,9,11,9,7,8,7,7,8,7,9,11,9,7,8,7
7,7,8,9,9,11,7,7,7,7,7,8,7,7,8,7,7,7,7,7,8,9,9,11,7,7,7,7,7,8,9,9,11,7,7,7,7,7,8,9,9,11,7,7,7
7,0,0,0,0,0,0,0,8,7,0,0,0,0,0,0,0,8,7,0,0,0,0,0,0,0,8,7,0,0,0,0,0,0,0,8,7,0,0,0,0,0,0,0,8
8,0,0,0,0,0,0,0,7,8,0,0,0,0,0,0,0,7,8,0,0,0,0,0,0,0,7,8,0,0,0,0,0,0,0,7,8,0,0,0,0,0,0,0,7
7,0,0,0,0,0,0,0,14,7,0,0,0,0,0,0,0,7,14,0,0,0,0,0,0,0,9,9,0,0,0,0,0,0,0,9,9,0,0,0,0,0,0,0,7
7,0,0,0,17,0,0,0,8,7,0,0,16,0,15,0,0,14,7,0,0,0,10,0,0,0,11,9,0,0,0,10,0,0,0,11,9,0,0,0,10,0,0,0,8
8,0,0,0,0,0,0,0,7,8,0,0,0,0,0,0,0,7,8,0,0,0,0,0,0,0,9,11,0,0,0,0,0,0,0,9,11,0,0,0,0,0,0,0,7
7,0,0,0,0,0,0,0,7,7,0,20,0,19,0,18,0,7,7,0,0,0,0,0,0,0,7,7,0,0,0,0,0,0,0,7,7,0,0,0,0,0,0,0,7
7,0,0,0,0,0,0,0,7,7,0,0,0,0,0,0,0,7,7,0,0,0,0,0,0,0,7,7,0,0,0,0,0,0,0,7,7,0,0,0,0,0,0,0,7
7,8,7,7,8,7,7,8,7,7,8,7,7,8,7,7,8,7,7,8,7,7,8,7,7,8,7,7,8,7,7,8,7,7,8,7,7,8,7,7,8,7,7,8,7
endlayer

layer
7,7,7,8,7,7,8,7,7,7,7,7,8,7,7,8,7,7,7,7,7,8,7,7,8,7,7,7,7,7,8,7,7,8,7,7,7,7,7,8,7,7,8,7,7
8,0,0,0,0,0,0,0,7,8,0,0,0,0,0,0,0,7,8,0,0,0,0,0,0,0,7,8,0,0,0,0,0,0,0,7,8,0,0,0,0,0,0,0,7
7,0,0,0,0,0,0,0,8,7,0,0,0,0,0,0,0,8,7,0,0,0,0,0,0,0,8,7,0,0,0,0,0,0,0,8,7,0,0,0,0,0,0,0,8
7,0,0,0,0,0,0,0,9,9,0,0,0,0,0,0,0,9,9,0,0,0,0,0,0,0,9,9,0,0,0,0,0,0,0,9,9,0,0,0,0,0,0,0,7
8,0,0,0,0,0,0,0,9,11,0,0,0,0,0,0,0,9,11,0,0,0,0,0,0,0,9,11,0,0,0,0,0,0,0,9,11,0,0,0,0,0,0,0,7
7,0,0,0,0,0,0,0,11,9,0,0,0,0,0,0,0,11,9,0,0,0,0,0,0,0,11,9,0,0,0,0,0,0,0,11,9,0,0,0,0,0,0,0,8
7,0,0,0,0,0,0,0,7,7,0,0,0,0,0,0,0,7,7,0,0,0,0,0,0,0,7,7,0,0,0,0,0,0,0,7,7,0,0,0,0,0,0,0,7
8,0,0,0,0,0,0,0,7,8,0,0,0,0,0,0,0,7,8,0,0,0,0,0,0,0,7,8,0,0,0,0,0,0,0,7,8,0,0,0,0,0,0,0,7
7,7,7,11,9,9,8,7,7,7,7,7,11,9,9,8,7,7,7,7,7,11,9,9,8,7,7,7,7,7,11,9,9,8,7,7,7,7,7,11,9,9,8,7,7
7,7,7,11,9,9,8,7,7,7,7,7,11,9,9,8,7,7,7,7,7,11,9,9,8,7,7,7,7,7,11,9,9,8,7,7,7,7,7,11,9,9,8,7,7
8,0,0,0,0,0,0,0,7,8,0,0,0,0,0,0,0,7,8,0,0,0,0,0,0,0,7,8,0,0,0,0,0,0,0,7,8,0,0,0,0,0,0,0,7
7,0,0,0,0,0,0,0,8,7,0,0,0,0,0,0,0,8,7,0,0,0,0,0,0,0,8,7,0,0,0,0,0,0,0,8,7,0,0,0,0,0,0,0,8
7,0,0,0,0,0,0,0,9,9,0,0,0,0,0,0,0,9,9,0,0,0,0,0,0,0,9,9,0,0,0,0,0,0,0,9,9,0,0,0,0,0,0,0,7
8,0,0,0,0,0,0,0,9,11,0,0,0,0,0,0,0,9,11,0,0,0,0,0,0,0,9,11,0,0,0,0,0,0,0,9,11,0,0,0,0,0,0,0,7
7,0,0,0,0,0,0,0,11,9,0,0,0,0,0,0,0,11,9,0,0,0,0,0,0,0,11,9,0,0,0,0,0,0,0,11,9,0,0,0,0,0,0,0,8
7,0,0,0,0,0,0,0,7,7,0,0,0,0,0,0,0,7,7,0,0,0,0,0,0,0,7,7,0,0,0,0,0,0,0,7,7,0,0,0,0,0,0,0,7
8,0,0,0,0,0,0,0,7,8,0,0,0,0,0,0,0,7,8,0,0,0,0,0,0,0,7,8,0,0,0,0,0,0,0,7,8,0,0,0,0,0,0,0,7
7,7,7,11,9,9,8,7,7,7,7,7,11,9,9,8,7,7,7,7,7,0,0,0,8,7,7,7,7,7,11,9,9,8,7,7,7,7,7,11,9,9,8,7,7
7,7,7,11,9,9,8,7,7,7,7,7,11,9,9,8,7,7,7,7,7,0,0,0,8,7,7,7,7,7,11,9,9,8,7,7,7,7,7,11,9,9,8,7,7
8,0,0,0,0,0,0,0,7,8,0,0,0,0,0,0,0,7,8,0,0,0,0,0,0,0,7,8,0,0,0,0,0,0,0,7,8,0,0,0,0,0,0,0,7
7,0,0,0,0,0,0,0,8,7,0,0,0,0,0,0,0,8,7,0,0,0,0,0,0,0,8,7,0,0,0,0,0,0,0,8,7,0,0,0,0,0,0,0,8
7,0,0,0,0,0,0,0,9,9,0,0,0,0,0,0,0,0,0,0,0,0,0,22,0,0,0,0,0,0,0,0,0,0,0,9,9,0,0,0,0,0,0,0,7
8,0,0,0,0,0,0,0,9,11,0,0,0,0,0,0,0,0,0,0,0,0,13,1,23,0,0,0,0,0,0,0,0,0,0,9,11,0,0,0,0,0,0,0,7
7,0,0,0,0,0,0,0,11,9,0,0,0,0,0,0,0,0,0,0,0,0,0,24,0,0,0,0,0,0,0,0,0,0,0,11,9,0,0,0,0,0,0,0,8
7,0,0,0,0,0,0,0,7,7,0,0,0,0,0,0,0,7,7,0,0,0,0,0,0,0,7,7,0,0,0,0,0,0,0,7,7,0,0,0,0,0,0,0,7
8,0,0,0,0,0,0,0,7,8,0,0,0,0,0,0,0,7,8,0,0,0,0,0,0,0,7,8,0,0,0,0,0,0,0,7,8,0,0,0,0,0,0,0,7
7,7,7,11,9,9,8,7,7,7,7,7,11,9,9,8,7,7,7,7,7,0,0,0,8,7,7,7,7,7,11,9,9,8,7,7,7,7,7,11,9,9,8,7,7
7,7,7,11,9,9,8,7,7,7,7,7,11,9,9,8,7,7,7,7,7,0,0,0,8,7,7,7,7,7,11,9,9,8,7,7,7,7,7,11,9,9,8,7,7
8,0,0,0,0,0,0,0,7,8,0,0,0,0,0,0,0,7,8,0,0,0,0,0,0,0,7,8,0,0,0,0,0,0,0,7,8,0,0,0,0,0,0,0,7
7,0,0,0,0,0,0,0,8,7,0,0,0,0,0,0,0,8,7,0,0,0,0,0,0,0,8,7,0,0,0,0,0,0,0,8,7,0,0,0,0,0,0,0,8
7,0,0,0,0,0,0,0,9,9,0,0,0,0,0,0,0,9,9,0,0,0,0,0,0,0,9,9,0,0,0,0,0,0,0,9,9,0,0,0,0,0,0,0,7
8,0,0,0,0,0,0,0,9,11,0,0,0,0,0,0,0,9,11,0,0,0,0,0,0,0,9,11,0,0,0,0,0,0,0,9,11,0,0,0,0,0,0,0,7
7,0,0,0,0,0,0,0,11,9,0,0,0,0,0,0,0,11,9,0,0,0,0,0,0,0,11,9,0,0,0,0,0,0,0,11,9,0,0,0,0,0,0,0,8
7,0,0,0,0,0,0,0,7,7,0,0,0,0,0,0,0,7,7,0,0,0,0,0,0,0,7,7,0,0,0,0,0,0,0,7,7,0,0,0,0,0,0,0,7
8,0,0,0,0,0,0,0,7,8,0,0,0,0,0,0,0,7,8,0,0,0,0,0,0,0,7,8,0,0,0,0,0,0,0,7,8,0,0,0,0,0,0,0,7
7,7,7,11,9,9,8,7,7,7,7,7,14,7,14,8,7,7,7,7,7,11,9,9,8,7,7,7,7,7,11,9,9,8,7,7,7,7,7,11,9,9,8,7,7
7,7,7,11,9,9,8,7,7,7,7,7,14,14,7,8,7,7,7,7,7,11,9,9,8,7,7,7,7,7,11,9,9,8,7,7,7,7,7,11,9,9,8,7,7
8,0,0,0,0,0,0,0,7,8,0,0,0,0,0,0,0,7,8,0,0,0,0,0,0,0,7,8,0,0,0,0,0,0,0,7,8,0,0,0,0,0,0,0,7
7,0,0,0,0,0,0,0,8,7,0,0,0,0,0,0,0,8,7,0,0,0,0,0,0,0,8,7,0,0,0,0,0,0,0,8,7,0,0,0,0,0,0,0,8
7,0,0,0,0,0,0,0,7,14,0,0,0,0,0,0,0,14,7,0,0,0,0,0,0,0,9,9,0,0,0,0,0,0,0,9,9,0,0,0,0,0,0,0,7
8,0,0,0,0,0,0,0,7,14,0,0,0,0,0,0,0,7,8,0,0,0,0,0,0,0,9,11,0,0,0,0,0,0,0,9,11,0,0,0,0,0,0,0,7
7,0,0,0,0,0,0,0,14,7,0,0,0,0,0,0,0,8,14,0,0,0,0,0,0,0,11,9,0,0,0,0,0,0,0,11,9,0,0,0,0,0,0,0,8
7,0,0,0,0,0,0,0,7,7,0,27,0,26,0,25,0,7,7,0,0,0,0,0,0,0,7,7,0,0,0,0,0,0,0,7,7,0,0,0,0,0,0,0,7
8,0,0,0,0,0,0,0,7,8,0,0,0,0,0,0,0,7,8,0,0,0,0,0,0,0,7,8,0,0,0,0,0,0,0,7,8,0,0,0,0,0,0,0,7
7,7,7,8,7,7,8,7,7,7,7,7,8,7,7,8,7,7,7,7,7,8,7,7,8,7,7,7,7,7,8,7,7,8,7,7,7,7,7,8,7,7,8,7,7
endlayer

layer
7,8,7,7,8,7,7,8,7,7,8,7,7,8,7,7,8,7,7,8,7,7,8,7,7,8,7,7,8,7,7,8,7,7,8,7,7,8,7,7,8,7,7,8,7
7,0,0,0,0,0,0,0,7,7,0,0,0,0,0,0,0,7,7,0,0,0,0,0,0,0,7,7,0,0,0,0,0,0,0,7,7,0,0,0,0,0,0,0,7
7,0,0,0,0,0,0,0,7,7,0,0,0,0,0,0,0,7,7,0,0,0,0,0,0,0,7,7,0,0,0,0,0,0,0,7,7,0,0,0,0,0,0,0,7
8,0,0,0,0,0,0,0,11,11,0,0,0,0,0,0,0,11,11,0,0,0,0,0,0,0,11,11,0,0,0,0,0,0,0,11,11,0,0,0,0,0,0,0,8
7,0,0,0,21,0,0,0,9,9,0,0,0,21,0,0,0,9,9,0,0,0,21,0,0,0,9,9,0,0,0,21,0,0,0,9,9,0,0,0,21,0,0,0,7
7,0,0,0,0,0,0,0,9,9,0,0,0,0,0,0,0,9,9,0,0,0,0,0,0,0,9,9,0,0,0,0,0,0,0,9,9,0,0,0,0,0,0,0,7
8,0,0,0,0,0,0,0,8,8,0,0,0,0,0,0,0,8,8,0,0,0,0,0,0,0,8,8,0,0,0,0,0,0,0,8,8,0,0,0,0,0,0,0,8
7,0,0,0,0,0,0,0,7,7,0,0,0,0,0,0,0,7,7,0,0,0,0,0,0,0,7,7,0,0,0,0,0,0,0,7,7,0,0,0,0,0,0,0,7
7,7,8,9,9,11,7,7,7,7,7,8,9,9,11,7,7,7,7,7,8,9,9,11,7,7,7,7,7,8,9,9,11,7,7,7,7,7,8,9,9,11,7,7,7
7,8,7,9,11,9,7,8,7,7,8,7,9,11,9,7,8,7,7,8,7,9,11,9,7,8,7,7,8,7,9,11,9,7,8,7,7,8,7,9,11,9,7,8,7
7,0,0,0,0,0,0,0,7,7,0,0,0,0,0,0,0,7,7,0,0,0,0,0,0,0,7,7,0,0,0,0,0,0,0,7,7,0,0,0,0,0,0,0,7
7,0,0,0,0,0,0,0,7,7,0,0,0,0,0,0,0,7,7,0,0,0,0,0,0,0,7,7,0,0,0,0,0,0,0,7,7,0,0,0,0,0,0,0,7
8,0,0,0,0,0,0,0,11,11,0,0,0,0,0,0,0,11,11,0,0,0,0,0,0,0,11,11,0,0,0,0,0,0,0,11,11,0,0,0,0,0,0,0,8
7,0,0,0,21,0,0,0,9,9,0,0,0,21,0,0,0,9,9,0,0,0,21,0,0,0,9,9,0,0,0,21,0,0,0,9,9,0,0,0,21,0,0,0,7
7,0,0,0,0,0,0,0,9,9,0,0,0,0,0,0,0,9,9,0,0,0,0,0,0,0,9,9,0,0,0,0,0,0,0,9,9,0,0,0,0,0,0,0,7
8,0,0,0,0,0,0,0,8,8,0,0,0,0,0,0,0,8,8,0,0,0,0,0,0,0,8,8,0,0,0,0,0,0,0,8,8,0,0,0,0,0,0,0,8
7,0,0,0,0,0,0,0,7,7,0,0,0,0,0,0,0,7,7,0,0,0,0,0,0,0,7,7,0,0,0,0,0,0,0,7,7,0,0,0,0,0,0,0,7
7,7,8,9,9,11,7,7,7,7,7,8,9,9,11,7,7,7,7,7,8,0,0,0,7,7,7,7,7,8,9,9,11,7,7,7,7,7,8,9,9,11,7,7,7
7,8,7,9,11,9,7,8,7,7,8,7,9,11,9,7,8,7,7,8,7,0,0,0,7,8,7,7,8,7,9,11,9,7,8,7,7,8,7,9,11,9,7,8,7
7,0,0,0,0,0,0,0,7,7,0,0,0,0,0,0,0,7,7,0,0,0,0,0,0,0,7,7,0,0,0,0,0,0,0,7,7,0,0,0,0,0,0,0,7
7,0,0,0,0,0,0,0,7,7,0,0,0,0,0,0,0,7,7,0,0,0,0,0,0,0,7,7,0,0,0,0,0,0,0,7,7,0,0,0,0,0,0,0,7
8,0,0,0,0,0,0,0,11,11,0,0,0,0,0,0,0,0,0,0,0,0,0,0,0,0,0,0,0,0,0,0,0,0,0,11,11,0,0,0,0,0,0,0,8
7,0,0,0,21,0,0,0,9,9,0,0,0,21,0,0,0,0,0,0,0,0,13,1,0,0,0,0,0,0,0,21,0,0,0,9,9,0,0,0,21,0,0,0,7
7,0,0,0,0,0,0,0,9,9,0,0,0,0,0,0,0,0,0,0,0,0,0,0,0,0,0,0,0,0,0,0,0,0,0,9,9,0,0,0,0,0,0,0,7
8,0,0,0,0,0,0,0,8,8,0,0,0,0,0,0,0,8,8,0,0,0,0,0,0,0,8,8,0,0,0,0,0,0,0,8,8,0,0,0,0,0,0,0,8
7,0,0,0,0,0,0,0,7,7,0,0,0,0,0,0,0,7,7,0,0,0,0,0,0,0,7,7,0,0,0,0,0,0,0,7,7,0,0,0,0,0,0,0,7
7,7,8,9,9,11,7,7,7,7,7,8,9,9,11,7,7,7,7,7,8,0,0,0,7,7,7,7,7,8,9,9,11,7,7,7,7,7,8,9,9,11,7,7,7
7,8,7,9,11,9,7,8,7,7,8,7,9,11,9,7,8,7,7,8,7,0,0,0,7,8,7,7,8,7,9,11,9,7,8,7,7,8,7,9,11,9,7,8,7
7,0,0,0,0,0,0,0,7,7,0,0,0,0,0,0,0,7,7,0,0,0,0,0,0,0,7,7,0,0,0,0,0,0,0,7,7,0,0,0,0,0,0,0,7
7,0,0,0,0,0,0,0,7,7,0,0,0,0,0,0,0,7,7,0,0,0,0,0,0,0,7,7,0,0,0,0,0,0,0,7,7,0,0,0,0,0,0,0,7
8,0,0,0,0,0,0,0,11,11,0,0,0,0,0,0,0,11,11,0,0,0,0,0,0,0,11,11,0,0,0,0,0,0,0,11,11,0,0,0,0,0,0,0,8
7,0,0,0,21,0,0,0,9,9,0,0,0,21,0,0,0,9,9,0,0,0,21,0,0,0,9,9,0,0,0,21,0,0,0,9,9,0,0,0,21,0,0,0,7
7,0,0,0,0,0,0,0,9,9,0,0,0,0,0,0,0,9,9,0,0,0,0,0,0,0,9,9,0,0,0,0,0,0,0,9,9,0,0,0,0,0,0,0,7
8,0,0,0,0,0,0,0,8,8,0,0,0,0,0,0,0,8,8,0,0,0,0,0,0,0,8,8,0,0,0,0,0,0,0,8,8,0,0,0,0,0,0,0,8
7,0,0,0,0,0,0,0,7,7,0,0,0,0,0,0,0,7,7,0,0,0,0,0,0,0,7,7,0,0,0,0,0,0,0,7,7,0,0,0,0,0,0,0,7
7,7,8,9,9,11,7,7,7,7,7,8,14,7,8,7,7,7,7,7,8,9,9,11,7,7,7,7,7,8,9,9,11,7,7,7,7,7,8,9,9,11,7,7,7
7,8,7,9,11,9,7,8,7,7,8,7,7,8,14,7,8,7,7,8,7,9,11,9,7,8,7,7,8,7,9,11,9,7,8,7,7,8,7,9,11,9,7,8,7
7,0,0,0,0,0,0,0,7,7,0,0,0,0,0,0,0,7,7,0,0,0,0,0,0,0,7,7,0,0,0,0,0,0,0,7,7,0,0,0,0,0,0,0,7
7,0,0,0,0,0,0,0,7,7,0,0,0,0,0,0,0,7,7,0,0,0,0,0,0,0,7,7,0,0,0,0,0,0,0,7,7,0,0,0,0,0,0,0,7
8,0,0,0,0,0,0,0,8,8,0,0,0,0,0,0,0,8,14,0,0,0,0,0,0,0,11,11,0,0,0,0,0,0,0,11,11,0,0,0,0,0,0,0,8
7,0,0,0,21,0,0,0,14,7,0,0,0,0,0,0,0,14,7,0,0,0,21,0,0,0,9,9,0,0,0,21,0,0,0,9,9,0,0,0,21,0,0,0,7
7,0,0,0,0,0,0,0,7,14,0,0,0,0,0,0,0,7,7,0,0,0,0,0,0,0,9,9,0,0,0,0,0,0,0,9,9,0,0,0,0,0,0,0,7
8,0,0,0,0,0,0,0,8,8,0,0,0,0,0,0,0,8,8,0,0,0,0,0,0,0,8,8,0,0,0,0,0,0,0,8,8,0,0,0,0,0,0,0,8
7,0,0,0,0,0,0,0,7,7,0,0,0,0,0,0,0,7,7,0,0,0,0,0,0,0,7,7,0,0,0,0,0,0,0,7,7,0,0,0,0,0,0,0,7
7,7,8,7,7,8,7,7,7,7,7,8,7,7,8,7,7,7,7,7,8,7,7,8,7,7,7,7,7,8,7,7,8,7,7,7,7,7,8,7,7,8,7,7,7
endlayer

layer
7,7,8,7,7,8,7,7,7,7,7,8,7,7,8,7,7,7,7,7,8,7,7,8,7,7,7,7,7,8,7,7,8,7,7,7,7,7,8,7,7,8,7,7,7
7,0,0,0,0,0,0,0,8,7,0,0,0,0,0,0,0,8,7,0,0,0,0,0,0,0,8,7,0,0,0,0,0,0,0,8,7,0,0,0,0,0,0,0,8
8,0,0,0,0,0,0,0,7,8,0,0,0,0,0,0,0,7,8,0,0,0,0,0,0,0,7,8,0,0,0,0,0,0,0,7,8,0,0,0,0,0,0,0,7
7,0,0,0,0,0,0,0,7,7,0,0,0,0,0,0,0,7,7,0,0,0,0,0,0,0,7,7,0,0,0,0,0,0,0,7,7,0,0,0,0,0,0,0,7
7,0,0,0,0,0,0,0,8,7,0,0,0,0,0,0,0,8,7,0,0,0,0,0,0,0,8,7,0,0,0,0,0,0,0,8,7,0,0,0,0,0,0,0,8
8,0,0,0,0,0,0,0,7,8,0,0,0,0,0,0,0,7,8,0,0,0,0,0,0,0,7,8,0,0,0,0,0,0,0,7,8,0,0,0,0,0,0,0,7
7,0,0,0,0,0,0,0,7,7,0,0,0,0,0,0,0,7,7,0,0,0,0,0,0,0,7,7,0,0,0,0,0,0,0,7,7,0,0,0,0,0,0,0,7
7,0,0,0,0,0,0,0,8,7,0,0,0,0,0,0,0,8,7,0,0,0,0,0,0,0,8,7,0,0,0,0,0,0,0,8,7,0,0,0,0,0,0,0,8
7,8,7,7,8,7,7,7,7,7,8,7,7,8,7,7,7,7,7,8,7,7,8,7,7,7,7,7,8,7,7,8,7,7,7,7,7,8,7,7,8,7,7,7,7
7,7,8,7,7,8,7,7,7,7,7,8,7,7,8,7,7,7,7,7,8,7,7,8,7,7,7,7,7,8,7,7,8,7,7,7,7,7,8,7,7,8,7,7,7
7,0,0,0,0,0,0,0,8,7,0,0,0,0,0,0,0,8,7,0,0,0,0,0,0,0,8,7,0,0,0,0,0,0,0,8,7,0,0,0,0,0,0,0,8
8,0,0,0,0,0,0,0,7,8,0,0,0,0,0,0,0,7,8,0,0,0,0,0,0,0,7,8,0,0,0,0,0,0,0,7,8,0,0,0,0,0,0,0,7
7,0,0,0,0,0,0,0,7,7,0,0,0,0,0,0,0,7,7,0,0,0,0,0,0,0,7,7,0,0,0,0,0,0,0,7,7,0,0,0,0,0,0,0,7
7,0,0,0,0,0,0,0,8,7,0,0,0,0,0,0,0,8,7,0,0,0,0,0,0,0,8,7,0,0,0,0,0,0,0,8,7,0,0,0,0,0,0,0,8
8,0,0,0,0,0,0,0,7,8,0,0,0,0,0,0,0,7,8,0,0,0,0,0,0,0,7,8,0,0,0,0,0,0,0,7,8,0,0,0,0,0,0,0,7
7,0,0,0,0,0,0,0,7,7,0,0,0,0,0,0,0,7,7,0,0,0,0,0,0,0,7,7,0,0,0,0,0,0,0,7,7,0,0,0,0,0,0,0,7
7,0,0,0,0,0,0,0,8,7,0,0,0,0,0,0,0,8,7,0,0,0,0,0,0,0,8,7,0,0,0,0,0,0,0,8,7,0,0,0,0,0,0,0,8
7,8,7,7,8,7,7,7,7,7,8,7,7,8,7,7,7,7,7,8,7,7,8,7,7,7,7,7,8,7,7,8,7,7,7,7,7,8,7,7,8,7,7,7,7
7,7,8,7,7,8,7,7,7,7,7,8,7,7,8,7,7,7,7,7,8,7,7,8,7,7,7,7,7,8,7,7,8,7,7,7,7,7,8,7,7,8,7,7,7
7,0,0,0,0,0,0,0,8,7,0,0,0,0,0,0,0,8,7,0,0,0,0,0,0,0,8,7,0,0,0,0,0,0,0,8,7,0,0,0,0,0,0,0,8
8,0,0,0,0,0,0,0,7,8,0,0,0,0,0,0,0,7,8,0,0,0,0,0,0,0,7,8,0,0,0,0,0,0,0,7,8,0,0,0,0,0,0,0,7
7,0,0,0,0,0,0,0,7,7,0,0,0,0,0,0,0,7,7,0,0,0,0,0,0,0,7,7,0,0,0,0,0,0,0,7,7,0,0,0,0,0,0,0,7
7,0,0,0,0,0,0,0,8,7,0,0,0,0,0,0,0,8,7,0,0,0,13,1,0,0,8,7,0,0,0,0,0,0,0,8,7,0,0,0,0,0,0,0,8
8,0,0,0,0,0,0,0,7,8,0,0,0,0,0,0,0,7,8,0,0,0,0,0,0,0,7,8,0,0,0,0,0,0,0,7,8,0,0,0,0,0,0,0,7
7,0,0,0,0,0,0,0,7,7,0,0,0,0,0,0,0,7,7,0,0,0,0,0,0,0,7,7,0,0,0,0,0,0,0,7,7,0,0,0,0,0,0,0,7
7,0,0,0,0,0,0,0,8,7,0,0,0,0,0,0,0,8,7,0,0,0,0,0,0,0,8,7,0,0,0,0,0,0,0,8,7,0,0,0,0,0,0,0,8
7,8,7,7,8,7,7,7,7,7,8,7,7,8,7,7,7,7,7,8,7,7,8,7,7,7,7,7,8,7,7,8,7,7,7,7,7,8,7,7,8,7,7,7,7
7,7,8,7,7,8,7,7,7,7,7,8,7,7,8,7,7,7,7,7,8,7,7,8,7,7,7,7,7,8,7,7,8,7,7,7,7,7,8,7,7,8,7,7,7
7,0,0,0,0,0,0,0,8,7,0,0,0,0,0,0,0,8,7,0,0,0,0,0,0,0,8,7,0,0,0,0,0,0,0,8,7,0,0,0,0,0,0,0,8
8,0,0,0,0,0,0,0,7,8,0,0,0,0,0,0,0,7,8,0,0,0,0,0,0,0,7,8,0,0,0,0,0,0,0,7,8,0,0,0,0,0,0,0,7
7,0,0,0,0,0,0,0,7,7,0,0,0,0,0,0,0,7,7,0,0,0,0,0,0,0,7,7,0,0,0,0,0,0,0,7,7,0,0,0,0,0,0,0,7
7,0,0,0,0,0,0,0,8,7,0,0,0,0,0,0,0,8,7,0,0,0,0,0,0,0,8,7,0,0,0,0,0,0,0,8,7,0,0,0,0,0,0,0,8
8,0,0,0,0,0,0,0,7,8,0,0,0,0,0,0,0,7,8,0,0,0,0,0,0,0,7,8,0,0,0,0,0,0,0,7,8,0,0,0,0,0,0,0,7
7,0,0,0,0,0,0,0,7,7,0,0,0,0,0,0,0,7,7,0,0,0,0,0,0,0,7,7,0,0,0,0,0,0,0,7,7,0,0,0,0,0,0,0,7
7,0,0,0,0,0,0,0,8,7,0,0,0,0,0,0,0,8,7,0,0,0,0,0,0,0,8,7,0,0,0,0,0,0,0,8,7,0,0,0,0,0,0,0,8
7,8,7,7,8,7,7,7,7,7,8,7,7,8,7,7,7,7,7,8,7,7,8,7,7,7,7,7,8,7,7,8,7,7,7,7,7,8,7,7,8,7,7,7,7
7,7,8,7,7,8,7,7,7,7,7,8,7,7,8,7,7,7,7,7,8,7,7,8,7,7,7,7,7,8,7,7,8,7,7,7,7,7,8,7,7,8,7,7,7
7,0,0,0,0,0,0,0,8,7,0,0,0,0,0,0,0,8,7,0,0,0,0,0,0,0,8,7,0,0,0,0,0,0,0,8,7,0,0,0,0,0,0,0,8
8,0,0,0,0,0,0,0,7,8,0,0,0,0,0,0,0,7,8,0,0,0,0,0,0,0,7,8,0,0,0,0,0,0,0,7,8,0,0,0,0,0,0,0,7
7,0,0,0,0,0,0,0,7,7,0,0,0,0,0,0,0,7,7,0,0,0,0,0,0,0,7,7,0,0,0,0,0,0,0,7,7,0,0,0,0,0,0,0,7
7,0,0,0,0,0,0,0,8,7,0,0,0,0,0,0,0,8,7,0,0,0,0,0,0,0,8,7,0,0,0,0,0,0,0,8,7,0,0,0,0,0,0,0,8
8,0,0,0,0,0,0,0,7,8,0,0,0,0,0,0,0,7,8,0,0,0,0,0,0,0,7,8,0,0,0,0,0,0,0,7,8,0,0,0,0,0,0,0,7
7,0,0,0,0,0,0,0,7,7,0,0,0,0,0,0,0,7,7,0,0,0,0,0,0,0,7,7,0,0,0,0,0,0,0,7,7,0,0,0,0,0,0,0,7
7,0,0,0,0,0,0,0,8,7,0,0,0,0,0,0,0,8,7,0,0,0,0,0,0,0,8,7,0,0,0,0,0,0,0,8,7,0,0,0,0,0,0,0,8
7,8,7,7,8,7,7,7,7,7,8,7,7,8,7,7,7,7,7,8,7,7,8,7,7,7,7,7,8,7,7,8,7,7,7,7,7,8,7,7,8,7,7,7,7
endlayer

layer
2,2,2,2,2,2,2,2,2,2,2,2,2,2,2,2,2,2,2,2,2,2,2,2,2,2,2,2,2,2,2,2,2,2,2,2,2,2,2,2,2,2,2,2,2
2,2,2,2,2,2,2,2,2,2,2,2,2,2,2,2,2,2,2,2,2,2,2,2,2,2,2,2,2,2,2,2,2,2,2,2,2,2,2,2,2,2,2,2,2
2,2,2,2,2,2,2,2,2,2,2,2,2,2,2,2,2,2,2,2,2,2,2,2,2,2,2,2,2,2,2,2,2,2,2,2,2,2,2,2,2,2,2,2,2
2,2,2,2,2,2,2,2,2,2,2,2,2,2,2,2,2,2,2,2,2,2,2,2,2,2,2,2,2,2,2,2,2,2,2,2,2,2,2,2,2,2,2,2,2
2,2,2,2,28,2,2,2,2,2,2,2,2,28,2,2,2,2,2,2,2,2,28,2,2,2,2,2,2,2,2,28,2,2,2,2,2,2,2,2,28,2,2,2,2
2,2,2,2,2,2,2,2,2,2,2,2,2,2,2,2,2,2,2,2,2,2,2,2,2,2,2,2,2,2,2,2,2,2,2,2,2,2,2,2,2,2,2,2,2
2,2,2,2,2,2,2,2,2,2,2,2,2,2,2,2,2,2,2,2,2,2,2,2,2,2,2,2,2,2,2,2,2,2,2,2,2,2,2,2,2,2,2,2,2
2,2,2,2,2,2,2,2,2,2,2,2,2,2,2,2,2,2,2,2,2,2,2,2,2,2,2,2,2,2,2,2,2,2,2,2,2,2,2,2,2,2,2,2,2
2,2,2,2,2,2,2,2,2,2,2,2,2,2,2,2,2,2,2,2,2,2,2,2,2,2,2,2,2,2,2,2,2,2,2,2,2,2,2,2,2,2,2,2,2
2,2,2,2,2,2,2,2,2,2,2,2,2,2,2,2,2,2,2,2,2,2,2,2,2,2,2,2,2,2,2,2,2,2,2,2,2,2,2,2,2,2,2,2,2
2,2,2,2,2,2,2,2,2,2,2,2,2,2,2,2,2,2,2,2,2,2,2,2,2,2,2,2,2,2,2,2,2,2,2,2,2,2,2,2,2,2,2,2,2
2,2,2,2,2,2,2,2,2,2,2,2,2,2,2,2,2,2,2,2,2,2,2,2,2,2,2,2,2,2,2,2,2,2,2,2,2,2,2,2,2,2,2,2,2
2,2,2,2,2,2,2,2,2,2,2,2,2,2,2,2,2,2,2,2,2,2,2,2,2,2,2,2,2,2,2,2,2,2,2,2,2,2,2,2,2,2,2,2,2
2,2,2,2,28,2,2,2,2,2,2,2,2,28,2,2,2,2,2,2,2,2,28,2,2,2,2,2,2,2,2,28,2,2,2,2,2,2,2,2,28,2,2,2,2
2,2,2,2,2,2,2,2,2,2,2,2,2,2,2,2,2,2,2,2,2,2,2,2,2,2,2,2,2,2,2,2,2,2,2,2,2,2,2,2,2,2,2,2,2
2,2,2,2,2,2,2,2,2,2,2,2,2,2,2,2,2,2,2,2,2,2,2,2,2,2,2,2,2,2,2,2,2,2,2,2,2,2,2,2,2,2,2,2,2
2,2,2,2,2,2,2,2,2,2,2,2,2,2,2,2,2,2,2,2,2,2,2,2,2,2,2,2,2,2,2,2,2,2,2,2,2,2,2,2,2,2,2,2,2
2,2,2,2,2,2,2,2,2,2,2,2,2,2,2,2,2,2,2,2,2,2,2,2,2,2,2,2,2,2,2,2,2,2,2,2,2,2,2,2,2,2,2,2,2
2,2,2,2,2,2,2,2,2,2,2,2,2,2,2,2,2,2,2,2,2,2,2,2,2,2,2,2,2,2,2,2,2,2,2,2,2,2,2,2,2,2,2,2,2
2,2,2,2,2,2,2,2,2,2,2,2,2,2,2,2,2,2,2,2,2,2,2,2,2,2,2,2,2,2,2,2,2,2,2,2,2,2,2,2,2,2,2,2,2
2,2,2,2,2,2,2,2,2,2,2,2,2,2,2,2,2,2,2,2,2,2,2,2,2,2,2,2,2,2,2,2,2,2,2,2,2,2,2,2,2,2,2,2,2
2,2,2,2,2,2,2,2,2,2,2,2,2,2,2,2,2,2,2,2,2,2,1,2,2,2,2,2,2,2,2,2,2,2,2,2,2,2,2,2,2,2,2,2,2
2,2,2,2,28,2,2,2,2,2,2,2,2,28,2,2,2,2,2,2,2,1,13,1,2,2,2,2,2,2,2,28,2,2,2,2,2,2,2,2,28,2,2,2,2
2,2,2,2,2,2,2,2,2,2,2,2,2,2,2,2,2,2,2,2,2,2,1,2,2,2,2,2,2,2,2,2,2,2,2,2,2,2,2,2,2,2,2,2,2
2,2,2,2,2,2,2,2,2,2,2,2,2,2,2,2,2,2,2,2,2,2,2,2,2,2,2,2,2,2,2,2,2,2,2,2,2,2,2,2,2,2,2,2,2
2,2,2,2,2,2,2,2,2,2,2,2,2,2,2,2,2,2,2,2,2,2,2,2,2,2,2,2,2,2,2,2,2,2,2,2,2,2,2,2,2,2,2,2,2
2,2,2,2,2,2,2,2,2,2,2,2,2,2,2,2,2,2,2,2,2,2,2,2,2,2,2,2,2,2,2,2,2,2,2,2,2,2,2,2,2,2,2,2,2
2,2,2,2,2,2,2,2,2,2,2,2,2,2,2,2,2,2,2,2,2,2,2,2,2,2,2,2,2,2,2,2,2,2,2,2,2,2,2,2,2,2,2,2,2
2,2,2,2,2,2,2,2,2,2,2,2,2,2,2,2,2,2,2,2,2,2,2,2,2,2,2,2,2,2,2,2,2,2,2,2,2,2,2,2,2,2,2,2,2
2,2,2,2,2,2,2,2,2,2,2,2,2,2,2,2,2,2,2,2,2,2,2,2,2,2,2,2,2,2,2,2,2,2,2,2,2,2,2,2,2,2,2,2,2
2,2,2,2,2,2,2,2,2,2,2,2,2,2,2,2,2,2,2,2,2,2,2,2,2,2,2,2,2,2,2,2,2,2,2,2,2,2,2,2,2,2,2,2,2
2,2,2,2,28,2,2,2,2,2,2,2,2,28,2,2,2,2,2,2,2,2,28,2,2,2,2,2,2,2,2,28,2,2,2,2,2,2,2,2,28,2,2,2,2
2,2,2,2,2,2,2,2,2,2,2,2,2,2,2,2,2,2,2,2,2,2,2,2,2,2,2,2,2,2,2,2,2,2,2,2,2,2,2,2,2,2,2,2,2
2,2,2,2,2,2,2,2,2,2,2,2,2,2,2,2,2,2,2,2,2,2,2,2,2,2,2,2,2,2,2,2,2,2,2,2,2,2,2,2,2,2,2,2,2
2,2,2,2,2,2,2,2,2,2,2,2,2,2,2,2,2,2,2,2,2,2,2,2,2,2,2,2,2,2,2,2,2,2,2,2,2,2,2,2,2,2,2,2,2
2,2,2,2,2,2,2,2,2,2,2,2,2,2,2,2,2,2,2,2,2,2,2,2,2,2,2,2,2,2,2,2,2,2,2,2,2,2,2,2,2,2,2,2,2
2,2,2,2,2,2,2,2,2,2,2,2,2,2,2,2,2,2,2,2,2,2,2,2,2,2,2,2,2,2,2,2,2,2,2,2,2,2,2,2,2,2,2,2,2
2,2,2,2,2,2,2,2,2,2,2,2,2,2,2,2,2,2,2,2,2,2,2,2,2,2,2,2,2,2,2,2,2,2,2,2,2,2,2,2,2,2,2,2,2
2,2,2,2,2,2,2,2,2,2,2,2,2,2,2,2,2,2,2,2,2,2,2,2,2,2,2,2,2,2,2,2,2,2,2,2,2,2,2,2,2,2,2,2,2
2,2,2,2,2,2,2,2,2,2,2,2,2,2,2,2,2,2,2,2,2,2,2,2,2,2,2,2,2,2,2,2,2,2,2,2,2,2,2,2,2,2,2,2,2
2,2,2,2,28,2,2,2,2,2,2,2,2,28,2,2,2,2,2,2,2,2,28,2,2,2,2,2,2,2,2,28,2,2,2,2,2,2,2,2,28,2,2,2,2
2,2,2,2,2,2,2,2,2,2,2,2,2,2,2,2,2,2,2,2,2,2,2,2,2,2,2,2,2,2,2,2,2,2,2,2,2,2,2,2,2,2,2,2,2
2,2,2,2,2,2,2,2,2,2,2,2,2,2,2,2,2,2,2,2,2,2,2,2,2,2,2,2,2,2,2,2,2,2,2,2,2,2,2,2,2,2,2,2,2
2,2,2,2,2,2,2,2,2,2,2,2,2,2,2,2,2,2,2,2,2,2,2,2,2,2,2,2,2,2,2,2,2,2,2,2,2,2,2,2,2,2,2,2,2
2,2,2,2,2,2,2,2,2,2,2,2,2,2,2,2,2,2,2,2,2,2,2,2,2,2,2,2,2,2,2,2,2,2,2,2,2,2,2,2,2,2,2,2,2
endlayer

layer
29,29,29,29,29,29,29,29,29,29,29,29,29,29,29,29,29,29,29,29,29,29,29,29,29,29,29,29,29,29,29,29,29,29,29,29,29,29,29,29,29,29,29,29,29
29,29,29,29,29,29,29,29,29,29,29,29,29,29,29,29,29,29,29,29,29,29,29,29,29,29,29,29,29,29,29,29,29,29,29,29,29,29,29,29,29,29,29,29,29
29,29,29,29,29,29,29,29,29,29,29,29,29,29,29,29,29,29,29,29,29,29,29,29,29,29,29,29,29,29,29,29,29,29,29,29,29,29,29,29,29,29,29,29,29
29,29,29,29,29,29,29,29,29,29,29,29,29,29,29,29,29,29,29,29,29,29,29,29,29,29,29,29,29,29,29,29,29,29,29,29,29,29,29,29,29,29,29,29,29
29,29,29,29,30,29,29,29,29,29,29,29,29,30,29,29,29,29,29,29,29,29,30,29,29,29,29,29,29,29,29,30,29,29,29,29,29,29,29,29,30,29,29,29,29
29,29,29,29,29,29,29,29,29,29,29,29,29,29,29,29,29,29,29,29,29,29,29,29,29,29,29,29,29,29,29,29,29,29,29,29,29,29,29,29,29,29,29,29,29
29,29,29,29,29,29,29,29,29,29,29,29,29,29,29,29,29,29,29,29,29,29,29,29,29,29,29,29,29,29,29,29,29,29,29,29,29,29,29,29,29,29,29,29,29
29,29,29,29,29,29,29,29,29,29,29,29,29,29,29,29,29,29,29,29,29,29,29,29,29,29,29,29,29,29,29,29,29,29,29,29,29,29,29,29,29,29,29,29,29
29,29,29,29,29,29,29,29,29,29,29,29,29,29,29,29,29,29,29,29,29,29,29,29,29,29,29,29,29,29,29,29,29,29,29,29,29,29,29,29,29,29,29,29,29
29,29,29,29,29,29,29,29,29,29,29,29,29,29,29,29,29,29,29,29,29,29,29,29,29,29,29,29,29,29,29,29,29,29,29,29,29,29,29,29,29,29,29,29,29
29,29,29,29,29,29,29,29,29,29,29,29,29,29,29,29,29,29,29,29,29,29,29,29,29,29,29,29,29,29,29,29,29,29,29,29,29,29,29,29,29,29,29,29,29
29,29,29,29,29,29,29,29,29,29,29,29,29,29,29,29,29,29,29,29,29,29,29,29,29,29,29,29,29,29,29,29,29,29,29,29,29,29,29,29,29,29,29,29,29
29,29,29,29,29,29,29,29,29,29,29,29,29,29,29,29,29,29,29,29,29,29,29,29,29,29,29,29,29,29,29,29,29,29,29,29,29,29,29,29,29,29,29,29,29
29,29,29,29,30,29,29,29,29,29,29,29,29,30,29,29,29,29,29,29,29,29,30,29,29,29,29,29,29,29,29,30,29,29,29,29,29,29,29,29,30,29,29,29,29
29,29,29,29,29,29,29,29,29,29,29,29,29,29,29,29,29,29,29,29,29,29,29,29,29,29,29,29,29,29,29,29,29,29,29,29,29,29,29,29,29,29,29,29,29
29,29,29,29,29,29,29,29,29,29,29,29,29,29,29,29,29,29,29,29,29,29,29,29,29,29,29,29,29,29,29,29,29,29,29,29,29,29,29,29,29,29,29,29,29
29,29,29,29,29,29,29,29,29,29,29,29,29,29,29,29,29,29,29,29,29,29,29,29,29,29,29,29,29,29,29,29,29,29,29,29,29,29,29,29,29,29,29,29,29
29,29,29,29,29,29,29,29,29,29,29,29,29,29,29,29,29,29,29,29,29,29,29,29,29,29,29,29,29,29,29,29,29,29,29,29,29,29,29,29,29,29,29,29,29
29,29,29,29,29,29,29,29,29,29,29,29,29,29,29,29,29,29,29,29,29,29,29,29,29,29,29,29,29,29,29,29,29,29,29,29,29,29,29,29,29,29,29,29,29
29,29,29,29,29,29,29,29,29,29,29,29,29,29,29,29,29,29,29,29,29,29,29,29,29,29,29,29,29,29,29,29,29,29,29,29,29,29,29,29,29,29,29,29,29
29,29,29,29,29,29,29,29,29,29,29,29,29,29,29,29,29,29,29,29,29,29,29,29,29,29,29,29,29,29,29,29,29,29,29,29,29,29,29,29,29,29,29,29,29
29,29,29,29,29,29,29,29,29,29,29,29,29,29,29,29,29,29,29,29,29,29,1,29,29,29,29,29,29,29,29,29,29,29,29,29,29,29,29,29,29,29,29,29,29
29,29,29,29,30,29,29,29,29,29,29,29,29,30,29,29,29,29,29,29,29,1,13,1,29,29,29,29,29,29,29,30,29,29,29,29,29,29,29,29,30,29,29,29,29
29,29,29,29,29,29,29,29,29,29,29,29,29,29,29,29,29,29,29,29,29,29,1,29,29,29,29,29,29,29,29,29,29,29,29,29,29,29,29,29,29,29,29,29,29
29,29,29,29,29,29,29,29,29,29,29,29,29,29,29,29,29,29,29,29,29,29,29,29,29,29,29,29,29,29,29,29,29,29,29,29,29,29,29,29,29,29,29,29,29
29,29,29,29,29,29,29,29,29,29,29,29,29,29,29,29,29,29,29,29,29,29,29,29,29,29,29,29,29,29,29,29,29,29,29,29,29,29,29,29,29,29,29,29,29
29,29,29,29,29,29,29,29,29,29,29,29,29,29,29,29,29,29,29,29,29,29,29,29,29,29,29,29,29,29,29,29,29,29,29,29,29,29,29,29,29,29,29,29,29
29,29,29,29,29,29,29,29,29,29,29,29,29,29,29,29,29,29,29,29,29,29,29,29,29,29,29,29,29,29,29,29,29,29,29,29,29,29,29,29,29,29,29,29,29
29,29,29,29,29,29,29,29,29,29,29,29,29,29,29,29,29,29,29,29,29,29,29,29,29,29,29,29,29,29,29,29,29,29,29,29,29,29,29,29,29,29,29,29,29
29,29,29,29,29,29,29,29,29,29,29,29,29,29,29,29,29,29,29,29,29,29,29,29,29,29,29,29,29,29,29,29,29,29,29,29,29,29,29,29,29,29,29,29,29
29,29,29,29,29,29,29,29,29,29,29,29,29,29,29,29,29,29,29,29,29,29,29,29,29,29,29,29,29,29,29,29,29,29,29,29,29,29,29,29,29,29,29,29,29
29,29,29,29,30,29,29,29,29,29,29,29,29,30,29,29,29,29,29,29,29,29,30,29,29,29,29,29,29,29,29,30,29,29,29,29,29,29,29,29,30,29,29,29,29
29,29,29,29,29,29,29,29,29,29,29,29,29,29,29,29,29,29,29,29,29,29,29,29,29,29,29,29,29,29,29,29,29,29,29,29,29,29,29,29,29,29,29,29,29
29,29,29,29,29,29,29,29,29,29,29,29,29,29,29,29,29,29,29,29,29,29,29,29,29,29,29,29,29,29,29,29,29,29,29,29,29,29,29,29,29,29,29,29,29
29,29,29,29,29,29,29,29,29,29,29,29,29,29,29,29,29,29,29,29,29,29,29,29,29,29,29,29,29,29,29,29,29,29,29,29,29,29,29,29,29,29,29,29,29
29,29,29,29,29,29,29,29,29,29,29,29,29,29,29,29,29,29,29,29,29,29,29,29,29,29,29,29,29,29,29,29,29,29,29,29,29,29,29,29,29,29,29,29,29
29,29,29,29,29,29,29,29,29,29,29,29,29,29,29,29,29,29,29,29,29,29,29,29,29,29,29,29,29,29,29,29,29,29,29,29,29,29,29,29,29,29,29,29,29
29,29,29,29,29,29,29,29,29,29,29,29,29,29,29,29,29,29,29,29,29,29,29,29,29,29,29,29,29,29,29,29,29,29,29,29,29,29,29,29,29,29,29,29,29
29,29,29,29,29,29,29,29,29,29,29,29,29,29,29,29,29,29,29,29,29,29,29,29,29,29,29,29,29,29,29,29,29,29,29,29,29,29,29,29,29,29,29,29,29
29,29,29,29,29,29,29,29,29,29,29,29,29,29,29,29,29,29,29,29,29,29,29,29,29,29,29,29,29,29,29,29,29,29,29,29,29,29,29,29,29,29,29,29,29
29,29,29,29,30,29,29,29,29,29,29,29,29,30,29,29,29,29,29,29,29,29,30,29,29,29,29,29,29,29,29,30,29,29,29,29,29,29,29,29,30,29,29,29,29
29,29,29,29,29,29,29,29,29,29,29,29,29,29,29,29,29,29,29,29,29,29,29,29,29,29,29,29,29,29,29,29,29,29,29,29,29,29,29,29,29,29,29,29,29
29,29,29,29,29,29,29,29,29,29,29,29,29,29,29,29,29,29,29,29,29,29,29,29,29,29,29,29,29,29,29,29,29,29,29,29,29,29,29,29,29,29,29,29,29
29,29,29,29,29,29,29,29,29,29,29,29,29,29,29,29,29,29,29,29,29,29,29,29,29,29,29,29,29,29,29,29,29,29,29,29,29,29,29,29,29,29,29,29,29
29,29,29,29,29,29,29,29,29,29,29,29,29,29,29,29,29,29,29,29,29,29,29,29,29,29,29,29,29,29,29,29,29,29,29,29,29,29,29,29,29,29,29,29,29
endlayer

layer
29,29,29,29,29,29,29,29,29,29,29,29,29,29,29,29,29,29,29,29,29,29,29,29,29,29,29,29,29,29,29,29,29,29,29,29,29,29,29,29,29,29,29,29,29
29,29,29,29,29,29,29,29,29,29,29,29,29,29,29,29,29,29,29,29,29,29,29,29,29,29,29,29,29,29,29,29,29,29,29,29,29,29,29,29,29,29,29,29,29
29,29,29,29,29,29,29,29,29,29,29,29,29,29,29,29,29,29,29,29,29,29,29,29,29,29,29,29,29,29,29,29,29,29,29,29,29,29,29,29,29,29,29,29,29
29,29,29,29,29,29,29,29,29,29,29,29,29,29,29,29,29,29,29,29,29,29,29,29,29,29,29,29,29,29,29,29,29,29,29,29,29,29,29,29,29,29,29,29,29
29,29,29,29,29,29,29,29,29,29,29,29,29,29,29,29,29,29,29,29,29,29,29,29,29,29,29,29,29,29,29,29,29,29,29,29,29,29,29,29,29,29,29,29,29
29,29,29,29,29,29,29,29,29,29,29,29,29,29,29,29,29,29,29,29,29,29,29,29,29,29,29,29,29,29,29,29,29,29,29,29,29,29,29,29,29,29,29,29,29
29,29,29,29,29,29,29,29,29,29,29,29,29,29,29,29,29,29,29,29,29,29,29,29,29,29,29,29,29,29,29,29,29,29,29,29,29,29,29,29,29,29,29,29,29
29,29,29,29,29,29,29,29,29,29,29,29,29,29,29,29,29,29,29,29,29,29,29,29,29,29,29,29,29,29,29,29,29,29,29,29,29,29,29,29,29,29,29,29,29
29,29,29,29,29,29,29,29,29,29,29,29,29,29,29,29,29,29,29,29,29,29,29,29,29,29,29,29,29,29,29,29,29,29,29,29,29,29,29,29,29,29,29,29,29
29,29,29,29,29,29,29,29,29,29,29,29,29,29,29,29,29,29,29,29,29,29,29,29,29,29,29,29,29,29,29,29,29,29,29,29,29,29,29,29,29,29,29,29,29
29,29,29,29,29,29,29,29,29,29,29,29,29,29,29,29,29,29,29,29,29,29,29,29,29,29,29,29,29,29,29,29,29,29,29,29,29,29,29,29,29,29,29,29,29
29,29,29,29,29,29,29,29,29,29,29,29,29,29,29,29,29,29,29,29,29,29,29,29,29,29,29,29,29,29,29,29,29,29,29,29,29,29,29,29,29,29,29,29,29
29,29,29,29,29,29,29,29,29,29,29,29,29,29,29,29,29,29,29,29,29,29,29,29,29,29,29,29,29,29,29,29,29,29,29,29,29,29,29,29,29,29,29,29,29
29,29,29,29,29,29,29,29,29,29,29,29,29,29,29,29,29,29,29,29,29,29,29,29,29,29,29,29,29,29,29,29,29,29,29,29,29,29,29,29,29,29,29,29,29
29,29,29,29,29,29,29,29,29,29,29,29,29,29,29,29,29,29,29,29,29,29,29,29,29,29,29,29,29,29,29,29,29,29,29,29,29,29,29,29,29,29,29,29,29
29,29,29,29,29,29,29,29,29,29,29,29,29,29,29,29,29,29,29,29,29,29,29,29,29,29,29,29,29,29,29,29,29,29,29,29,29,29,29,29,29,29,29,29,29
29,29,29,29,29,29,29,29,29,29,29,29,29,29,29,29,29,29,29,29,29,29,29,29,29,29,29,29,29,29,29,29,29,29,29,29,29,29,29,29,29,29,29,29,29
29,29,29,29,29,29,29,29,29,29,29,29,29,29,29,29,29,29,29,29,29,29,29,29,29,29,29,29,29,29,29,29,29,29,29,29,29,29,29,29,29,29,29,29,29
29,29,29,29,29,29,29,29,29,29,29,29,29,29,29,29,29,29,29,29,29,29,29,29,29,29,29,29,29,29,29,29,29,29,29,29,29,29,29,29,29,29,29,29,29
29,29,29,29,29,29,29,29,29,29,29,29,29,29,29,29,29,29,29,29,29,29,29,29,29,29,29,29,29,29,29,29,29,29,29,29,29,29,29,29,29,29,29,29,29
29,29,29,29,29,29,29,29,29,29,29,29,29,29,29,29,29,29,29,29,29,29,29,29,29,29,29,29,29,29,29,29,29,29,29,29,29,29,29,29,29,29,29,29,29
29,29,29,29,29,29,29,29,29,29,29,29,29,29,29,29,29,29,29,29,29,29,1,29,29,29,29,29,29,29,29,29,29,29,29,29,29,29,29,29,29,29,29,29,29
29,29,29,29,29,29,29,29,29,29,29,29,29,29,29,29,29,29,29,29,29,1,13,1,29,29,29,29,29,29,29,29,29,29,29,29,29,29,29,29,29,29,29,29,29
29,29,29,29,29,29,29,29,29,29,29,29,29,29,29,29,29,29,29,29,29,29,1,29,29,29,29,29,29,29,29,29,29,29,29,29,29,29,29,29,29,29,29,29,29
29,29,29,29,29,29,29,29,29,29,29,29,29,29,29,29,29,29,29,29,29,29,29,29,29,29,29,29,29,29,29,29,29,29,29,29,29,29,29,29,29,29,29,29,29
29,29,29,29,29,29,29,29,29,29,29,29,29,29,29,29,29,29,29,29,29,29,29,29,29,29,29,29,29,29,29,29,29,29,29,29,29,29,29,29,29,29,29,29,29
29,29,29,29,29,29,29,29,29,29,29,29,29,29,29,29,29,29,29,29,29,29,29,29,29,29,29,29,29,29,29,29,29,29,29,29,29,29,29,29,29,29,29,29,29
29,29,29,29,29,29,29,29,29,29,29,29,29,29,29,29,29,29,29,29,29,29,29,29,29,29,29,29,29,29,29,29,29,29,29,29,29,29,29,29,29,29,29,29,29
29,29,29,29,29,29,29,29,29,29,29,29,29,29,29,29,29,29,29,29,29,29,29,29,29,29,29,29,29,29,29,29,29,29,29,29,29,29,29,29,29,29,29,29,29
29,29,29,29,29,29,29,29,29,29,29,29,29,29,29,29,29,29,29,29,29,29,29,29,29,29,29,29,29,29,29,29,29,29,29,29,29,29,29,29,29,29,29,29,29
29,29,29,29,29,29,29,29,29,29,29,29,29,29,29,29,29,29,29,29,29,29,29,29,29,29,29,29,29,29,29,29,29,29,29,29,29,29,29,29,29,29,29,29,29
29,29,29,29,29,29,29,29,29,29,29,29,29,29,29,29,29,29,29,29,29,29,29,29,29,29,29,29,29,29,29,29,29,29,29,29,29,29,29,29,29,29,29,29,29
29,29,29,29,29,29,29,29,29,29,29,29,29,29,29,29,29,29,29,29,29,29,29,29,29,29,29,29,29,29,29,29,29,29,29,29,29,29,29,29,29,29,29,29,29
29,29,29,29,29,29,29,29,29,29,29,29,29,29,29,29,29,29,29,29,29,29,29,29,29,29,29,29,29,29,29,29,29,29,29,29,29,29,29,29,29,29,29,29,29
29,29,29,29,29,29,29,29,29,29,29,29,29,29,29,29,29,29,29,29,29,29,29,29,29,29,29,29,29,29,29,29,29,29,29,29,29,29,29,29,29,29,29,29,29
29,29,29,29,29,29,29,29,29,29,29,29,29,29,29,29,29,29,29,29,29,29,29,29,29,29,29,29,29,29,29,29,29,29,29,29,29,29,29,29,29,29,29,29,29
29,29,29,29,29,29,29,29,29,29,29,29,29,29,29,29,29,29,29,29,29,29,29,29,29,29,29,29,29,29,29,29,29,29,29,29,29,29,29,29,29,29,29,29,29
29,29,29,29,29,29,29,29,29,29,29,29,29,29,29,29,29,29,29,29,29,29,29,29,29,29,29,29,29,29,29,29,29,29,29,29,29,29,29,29,29,29,29,29,29
29,29,29,29,29,29,29,29,29,29,29,29,29,29,29,29,29,29,29,29,29,29,29,29,29,29,29,29,29,29,29,29,29,29,29,29,29,29,29,29,29,29,29,29,29
29,29,29,29,29,29,29,29,29,29,29,29,29,29,29,29,29,29,29,29,29,29,29,29,29,29,29,29,29,29,29,29,29,29,29,29,29,29,29,29,29,29,29,29,29
29,29,29,29,29,29,29,29,29,29,29,29,29,29,29,29,29,29,29,29,29,29,29,29,29,29,29,29,29,29,29,29,29,29,29,29,29,29,29,29,29,29,29,29,29
29,29,29,29,29,29,29,29,29,29,29,29,29,29,29,29,29,29,29,29,29,29,29,29,29,29,29,29,29,29,29,29,29,29,29,29,29,29,29,29,29,29,29,29,29
29,29,29,29,29,29,29,29,29,29,29,29,29,29,29,29,29,29,29,29,29,29,29,29,29,29,29,29,29,29,29,29,29,29,29,29,29,29,29,29,29,29,29,29,29
29,29,29,29,29,29,29,29,29,29,29,29,29,29,29,29,29,29,29,29,29,29,29,29,29,29,29,29,29,29,29,29,29,29,29,29,29,29,29,29,29,29,29,29,29
29,29,29,29,29,29,29,29,29,29,29,29,29,29,29,29,29,29,29,29,29,29,29,29,29,29,29,29,29,29,29,29,29,29,29,29,29,29,29,29,29,29,29,29,29
endlayer

layer
29,29,29,29,29,29,29,29,29,29,29,29,29,29,29,29,29,29,29,29,29,29,29,29,29,29,29,29,29,29,29,29,29,29,29,29,29,29,29,29,29,29,29,29,29
29,29,29,29,29,29,29,29,29,29,29,29,29,29,29,29,29,29,29,29,29,29,29,29,29,29,29,29,29,29,29,29,29,29,29,29,29,29,29,29,29,29,29,29,29
29,29,29,29,29,29,29,29,29,29,29,29,29,29,29,29,29,29,29,29,29,29,29,29,29,29,29,29,29,29,29,29,29,29,29,29,29,29,29,29,29,29,29,29,29
29,29,29,29,29,29,29,29,29,29,29,29,29,29,29,29,29,29,29,29,29,29,29,29,29,29,29,29,29,29,29,29,29,29,29,29,29,29,29,29,29,29,29,29,29
29,29,29,29,29,29,29,29,29,29,29,29,29,29,29,29,29,29,29,29,29,29,29,29,29,29,29,29,29,29,29,29,29,29,29,29,29,29,29,29,29,29,29,29,29
29,29,29,29,29,29,29,29,29,29,29,29,29,29,29,29,29,29,29,29,29,29,29,29,29,29,29,29,29,29,29,29,29,29,29,29,29,29,29,29,29,29,29,29,29
29,29,29,29,29,29,29,29,29,29,29,29,29,29,29,29,29,29,29,29,29,29,29,29,29,29,29,29,29,29,29,29,29,29,29,29,29,29,29,29,29,29,29,29,29
29,29,29,29,29,29,29,29,29,29,29,29,29,29,29,29,29,29,29,29,29,29,29,29,29,29,29,29,29,29,29,29,29,29,29,29,29,29,29,29,29,29,29,29,29
29,29,29,29,29,29,29,29,29,29,29,29,29,29,29,29,29,29,29,29,29,29,29,29,29,29,29,29,29,29,29,29,29,29,29,29,29,29,29,29,29,29,29,29,29
29,29,29,29,29,29,29,29,29,29,29,29,29,29,29,29,29,29,29,29,29,29,29,29,29,29,29,29,29,29,29,29,29,29,29,29,29,29,29,29,29,29,29,29,29
29,29,29,29,29,29,29,29,29,29,29,29,29,29,29,29,29,29,29,29,29,29,29,29,29,29,29,29,29,29,29,29,29,29,29,29,29,29,29,29,29,29,29,29,29
29,29,29,29,29,29,29,29,29,29,29,29,29,29,29,29,29,29,29,29,29,29,29,29,29,29,29,29,29,29,29,29,29,29,29,29,29,29,29,29,29,29,29,29,29
29,29,29,29,29,29,29,29,29,29,29,29,29,29,29,29,29,29,29,29,29,29,29,29,29,29,29,29,29,29,29,29,29,29,29,29,29,29,29,29,29,29,29,29,29
29,29,29,29,29,29,29,29,29,29,29,29,29,29,29,29,29,29,29,29,29,29,29,29,29,29,29,29,29,29,29,29,29,29,29,29,29,29,29,29,29,29,29,29,29
29,29,29,29,29,29,29,29,29,29,29,29,29,29,29,29,29,29,29,29,29,29,29,29,29,29,29,29,29,29,29,29,29,29,29,29,29,29,29,29,29,29,29,29,29
29,29,29,29,29,29,29,29,29,29,29,29,29,29,29,29,29,29,29,29,29,29,29,29,29,29,29,29,29,29,29,29,29,29,29,29,29,29,29,29,29,29,29,29,29
29,29,29,29,29,29,29,29,29,29,29,29,29,29,29,29,29,29,29,29,29,29,29,29,29,29,29,29,29,29,29,29,29,29,29,29,29,29,29,29,29,29,29,29,29
29,29,29,29,29,29,29,29,29,29,29,29,29,29,29,29,29,29,29,29,29,29,29,29,29,29,29,29,29,29,29,29,29,29,29,29,29,29,29,29,29,29,29,29,29
29,29,29,29,29,29,29,29,29,29,29,29,29,29,29,29,29,29,29,29,29,29,29,29,29,29,29,29,29,29,29,29,29,29,29,29,29,29,29,29,29,29,29,29,29
29,29,29,29,29,29,29,29,29,29,29,29,29,29,29,29,29,29,29,29,29,29,29,29,29,29,29,29,29,29,29,29,29,29,29,29,29,29,29,29,29,29,29,29,29
29,29,29,29,29,29,29,29,29,29,29,29,29,29,29,29,29,29,29,29,29,29,29,29,29,29,29,29,29,29,29,29,29,29,29,29,29,29,29,29,29,29,29,29,29
29,29,29,29,29,29,29,29,29,29,29,29,29,29,29,29,29,29,29,29,29,29,1,29,29,29,29,29,29,29,29,29,29,29,29,29,29,29,29,29,29,29,29,29,29
29,29,29,29,29,29,29,29,29,29,29,29,29,29,29,29,29,29,29,29,29,1,13,1,29,29,29,29,29,29,29,29,29,29,29,29,29,29,29,29,29,29,29,29,29
29,29,29,29,29,29,29,29,29,29,29,29,29,29,29,29,29,29,29,29,29,29,1,29,29,29,29,29,29,29,29,29,29,29,29,29,29,29,29,29,29,29,29,29,29
29,29,29,29,29,29,29,29,29,29,29,29,29,29,29,29,29,29,29,29,29,29,29,29,29,29,29,29,29,29,29,29,29,29,29,29,29,29,29,29,29,29,29,29,29
29,29,29,29,29,29,29,29,29,29,29,29,29,29,29,29,29,29,29,29,29,29,29,29,29,29,29,29,29,29,29,29,29,29,29,29,29,29,29,29,29,29,29,29,29
29,29,29,29,29,29,29,29,29,29,29,29,29,29,29,29,29,29,29,29,29,29,29,29,29,29,29,29,29,29,29,29,29,29,29,29,29,29,29,29,29,29,29,29,29
29,29,29,29,29,29,29,29,29,29,29,29,29,29,29,29,29,29,29,29,29,29,29,29,29,29,29,29,29,29,29,29,29,29,29,29,29,29,29,29,29,29,29,29,29
29,29,29,29,29,29,29,29,29,29,29,29,29,29,29,29,29,29,29,29,29,29,29,29,29,29,29,29,29,29,29,29,29,29,29,29,29,29,29,29,29,29,29,29,29
29,29,29,29,29,29,29,29,29,29,29,29,29,29,29,29,29,29,29,29,29,29,29,29,29,29,29,29,29,29,29,29,29,29,29,29,29,29,29,29,29,29,29,29,29
29,29,29,29,29,29,29,29,29,29,29,29,29,29,29,29,29,29,29,29,29,29,29,29,29,29,29,29,29,29,29,29,29,29,29,29,29,29,29,29,29,29,29,29,29
29,29,29,29,29,29,29,29,29,29,29,29,29,29,29,29,29,29,29,29,29,29,29,29,29,29,29,29,29,29,29,29,29,29,29,29,29,29,29,29,29,29,29,29,29
29,29,29,29,29,29,29,29,29,29,29,29,29,29,29,29,29,29,29,29,29,29,29,29,29,29,29,29,29,29,29,29,29,29,29,29,29,29,29,29,29,29,29,29,29
29,29,29,29,29,29,29,29,29,29,29,29,29,29,29,29,29,29,29,29,29,29,29,29,29,29,29,29,29,29,29,29,29,29,29,29,29,29,29,29,29,29,29,29,29
29,29,29,29,29,29,29,29,29,29,29,29,29,29,29,29,29,29,29,29,29,29,29,29,29,29,29,29,29,29,29,29,29,29,29,29,29,29,29,29,29,29,29,29,29
29,29,29,29,29,29,29,29,29,29,29,29,29,29,29,29,29,29,29,29,29,29,29,29,29,29,29,29,29,29,29,29,29,29,29,29,29,29,29,29,29,29,29,29,29
29,29,29,29,29,29,29,29,29,29,29,29,29,29,29,29,29,29,29,29,29,29,29,29,29,29,29,29,29,29,29,29,29,29,29,29,29,29,29,29,29,29,29,29,29
29,29,29,29,29,29,29,29,29,29,29,29,29,29,29,29,29,29,29,29,29,29,29,29,29,29,29,29,29,29,29,29,29,29,29,29,29,29,29,29,29,29,29,29,29
29,29,29,29,29,29,29,29,29,29,29,29,29,29,29,29,29,29,29,29,29,29,29,29,29,29,29,29,29,29,29,29,29,29,29,29,29,29,29,29,29,29,29,29,29
29,29,29,29,29,29,29,29,29,29,29,29,29,29,29,29,29,29,29,29,29,29,29,29,29,29,29,29,29,29,29,29,29,29,29,29,29,29,29,29,29,29,29,29,29
29,29,29,29,29,29,29,29,29,29,29,29,29,29,29,29,29,29,29,29,29,29,29,29,29,29,29,29,29,29,29,29,29,29,29,29,29,29,29,29,29,29,29,29,29
29,29,29,29,29,29,29,29,29,29,29,29,29,29,29,29,29,29,29,29,29,29,29,29,29,29,29,29,29,29,29,29,29,29,29,29,29,29,29,29,29,29,29,29,29
29,29,29,29,29,29,29,29,29,29,29,29,29,29,29,29,29,29,29,29,29,29,29,29,29,29,29,29,29,29,29,29,29,29,29,29,29,29,29,29,29,29,29,29,29
29,29,29,29,29,29,29,29,29,29,29,29,29,29,29,29,29,29,29,29,29,29,29,29,29,29,29,29,29,29,29,29,29,29,29,29,29,29,29,29,29,29,29,29,29
29,29,29,29,29,29,29,29,29,29,29,29,29,29,29,29,29,29,29,29,29,29,29,29,29,29,29,29,29,29,29,29,29,29,29,29,29,29,29,29,29,29,29,29,29
endlayer

layer
29,29,29,29,29,29,29,29,29,29,29,29,29,29,29,29,29,29,29,29,29,29,29,29,29,29,29,29,29,29,29,29,29,29,29,29,29,29,29,29,29,29,29,29,29
29,29,29,29,29,29,29,29,29,29,29,29,29,29,29,29,29,29,29,29,29,29,29,29,29,29,29,29,29,29,29,29,29,29,29,29,29,29,29,29,29,29,29,29,29
29,29,29,29,29,29,29,29,29,29,29,29,29,29,29,29,29,29,29,29,29,29,29,29,29,29,29,29,29,29,29,29,29,29,29,29,29,29,29,29,29,29,29,29,29
29,29,29,29,29,29,29,29,29,29,29,29,29,29,29,29,29,29,29,29,29,29,29,29,29,29,29,29,29,29,29,29,29,29,29,29,29,29,29,29,29,29,29,29,29
29,29,29,29,29,29,29,29,29,29,29,29,29,29,29,29,29,29,29,29,29,29,29,29,29,29,29,29,29,29,29,29,29,29,29,29,29,29,29,29,29,29,29,29,29
29,29,29,29,29,29,29,29,29,29,29,29,29,29,29,29,29,29,29,29,29,29,29,29,29,29,29,29,29,29,29,29,29,29,29,29,29,29,29,29,29,29,29,29,29
29,29,29,29,29,29,29,29,29,29,29,29,29,29,29,29,29,29,29,29,29,29,29,29,29,29,29,29,29,29,29,29,29,29,29,29,29,29,29,29,29,29,29,29,29
29,29,29,29,29,29,29,29,29,29,29,29,29,29,29,29,29,29,29,29,29,29,29,29,29,29,29,29,29,29,29,29,29,29,29,29,29,29,29,29,29,29,29,29,29
29,29,29,29,29,29,29,29,29,29,29,29,29,29,29,29,29,29,29,29,29,29,29,29,29,29,29,29,29,29,29,29,29,29,29,29,29,29,29,29,29,29,29,29,29
29,29,29,29,29,29,29,29,29,29,29,29,29,29,29,29,29,29,29,29,29,29,29,29,29,29,29,29,29,29,29,29,29,29,29,29,29,29,29,29,29,29,29,29,29
29,29,29,29,29,29,29,29,29,29,29,29,29,29,29,29,29,29,29,29,29,29,29,29,29,29,29,29,29,29,29,29,29,29,29,29,29,29,29,29,29,29,29,29,29
29,29,29,29,29,29,29,29,29,29,29,29,29,29,29,29,29,29,29,29,29,29,29,29,29,29,29,29,29,29,29,29,29,29,29,29,29,29,29,29,29,29,29,29,29
29,29,29,29,29,29,29,29,29,29,29,29,29,29,29,29,29,29,29,29,29,29,29,29,29,29,29,29,29,29,29,29,29,29,29,29,29,29,29,29,29,29,29,29,29
29,29,29,29,29,29,29,29,29,29,29,29,29,29,29,29,29,29,29,29,29,29,29,29,29,29,29,29,29,29,29,29,29,29,29,29,29,29,29,29,29,29,29,29,29
29,29,29,29,29,29,29,29,29,29,29,29,29,29,29,29,29,29,29,29,29,29,29,29,29,29,29,29,29,29,29,29,29,29,29,29,29,29,29,29,29,29,29,29,29
29,29,29,29,29,29,29,29,29,29,29,29,29,29,29,29,29,29,29,29,29,29,29,29,29,29,29,29,29,29,29,29,29,29,29,29,29,29,29,29,29,29,29,29,29
29,29,29,29,29,29,29,29,29,29,29,29,29,29,29,29,29,29,29,29,29,29,29,29,29,29,29,29,29,29,29,29,29,29,29,29,29,29,29,29,29,29,29,29,29
29,29,29,29,29,29,29,29,29,29,29,29,29,29,29,29,29,29,29,29,29,29,29,29,29,29,29,29,29,29,29,29,29,29,29,29,29,29,29,29,29,29,29,29,29
29,29,29,29,29,29,29,29,29,29,29,29,29,29,29,29,29,29,29,29,29,29,29,29,29,29,29,29,29,29,29,29,29,29,29,29,29,29,29,29,29,29,29,29,29
29,29,29,29,29,29,29,29,29,29,29,29,29,29,29,29,29,29,29,29,29,29,29,29,29,29,29,29,29,29,29,29,29,29,29,29,29,29,29,29,29,29,29,29,29
29,29,29,29,29,29,29,29,29,29,29,29,29,29,29,29,29,29,29,29,29,29,29,29,29,29,29,29,29,29,29,29,29,29,29,29,29,29,29,29,29,29,29,29,29
29,29,29,29,29,29,29,29,29,29,29,29,29,29,29,29,29,29,29,29,29,29,1,29,29,29,29,29,29,29,29,29,29,29,29,29,29,29,29,29,29,29,29,29,29
29,29,29,29,29,29,29,29,29,29,29,29,29,29,29,29,29,29,29,29,29,1,13,1,29,29,29,29,29,29,29,29,29,29,29,29,29,29,29,29,29,29,29,29,29
29,29,29,29,29,29,29,29,29,29,29,29,29,29,29,29,29,29,29,29,29,29,1,29,29,29,29,29,29,29,29,29,29,29,29,29,29,29,29,29,29,29,29,29,29
29,29,29,29,29,29,29,29,29,29,29,29,29,29,29,29,29,29,29,29,29,29,29,29,29,29,29,29,29,29,29,29,29,29,29,29,29,29,29,29,29,29,29,29,29
29,29,29,29,29,29,29,29,29,29,29,29,29,29,29,29,29,29,29,29,29,29,29,29,29,29,29,29,29,29,29,29,29,29,29,29,29,29,29,29,29,29,29,29,29
29,29,29,29,29,29,29,29,29,29,29,29,29,29,29,29,29,29,29,29,29,29,29,29,29,29,29,29,29,29,29,29,29,29,29,29,29,29,29,29,29,29,29,29,29
29,29,29,29,29,29,29,29,29,29,29,29,29,29,29,29,29,29,29,29,29,29,29,29,29,29,29,29,29,29,29,29,29,29,29,29,29,29,29,29,29,29,29,29,29
29,29,29,29,29,29,29,29,29,29,29,29,29,29,29,29,29,29,29,29,29,29,29,29,29,29,29,29,29,29,29,29,29,29,29,29,29,29,29,29,29,29,29,29,29
29,29,29,29,29,29,29,29,29,29,29,29,29,29,29,29,29,29,29,29,29,29,29,29,29,29,29,29,29,29,29,29,29,29,29,29,29,29,29,29,29,29,29,29,29
29,29,29,29,29,29,29,29,29,29,29,29,29,29,29,29,29,29,29,29,29,29,29,29,29,29,29,29,29,29,29,29,29,29,29,29,29,29,29,29,29,29,29,29,29
29,29,29,29,29,29,29,29,29,29,29,29,29,29,29,29,29,29,29,29,29,29,29,29,29,29,29,29,29,29,29,29,29,29,29,29,29,29,29,29,29,29,29,29,29
29,29,29,29,29,29,29,29,29,29,29,29,29,29,29,29,29,29,29,29,29,29,29,29,29,29,29,29,29,29,29,29,29,29,29,29,29,29,29,29,29,29,29,29,29
29,29,29,29,29,29,29,29,29,29,29,29,29,29,29,29,29,29,29,29,29,29,29,29,29,29,29,29,29,29,29,29,29,29,29,29,29,29,29,29,29,29,29,29,29
29,29,29,29,29,29,29,29,29,29,29,29,29,29,29,29,29,29,29,29,29,29,29,29,29,29,29,29,29,29,29,29,29,29,29,29,29,29,29,29,29,29,29,29,29
29,29,29,29,29,29,29,29,29,29,29,29,29,29,29,29,29,29,29,29,29,29,29,29,29,29,29,29,29,29,29,29,29,29,29,29,29,29,29,29,29,29,29,29,29
29,29,29,29,29,29,29,29,29,29,29,29,29,29,29,29,29,29,29,29,29,29,29,29,29,29,29,29,29,29,29,29,29,29,29,29,29,29,29,29,29,29,29,29,29
29,29,29,29,29,29,29,29,29,29,29,29,29,29,29,29,29,29,29,29,29,29,29,29,29,29,29,29,29,29,29,29,29,29,29,29,29,29,29,29,29,29,29,29,29
29,29,29,29,29,29,29,29,29,29,29,29,29,29,29,29,29,29,29,29,29,29,29,29,29,29,29,29,29,29,29,29,29,29,29,29,29,29,29,29,29,29,29,29,29
29,29,29,29,29,29,29,29,29,29,29,29,29,29,29,29,29,29,29,29,29,29,29,29,29,29,29,29,29,29,29,29,29,29,29,29,29,29,29,29,29,29,29,29,29
29,29,29,29,29,29,29,29,29,29,29,29,29,29,29,29,29,29,29,29,29,29,29,29,29,29,29,29,29,29,29,29,29,29,29,29,29,29,29,29,29,29,29,29,29
29,29,29,29,29,29,29,29,29,29,29,29,29,29,29,29,29,29,29,29,29,29,29,29,29,29,29,29,29,29,29,29,29,29,29,29,29,29,29,29,29,29,29,29,29
29,29,29,29,29,29,29,29,29,29,29,29,29,29,29,29,29,29,29,29,29,29,29,29,29,29,29,29,29,29,29,29,29,29,29,29,29,29,29,29,29,29,29,29,29
29,29,29,29,29,29,29,29,29,29,29,29,29,29,29,29,29,29,29,29,29,29,29,29,29,29,29,29,29,29,29,29,29,29,29,29,29,29,29,29,29,29,29,29,29
29,29,29,29,29,29,29,29,29,29,29,29,29,29,29,29,29,29,29,29,29,29,29,29,29,29,29,29,29,29,29,29,29,29,29,29,29,29,29,29,29,29,29,29,29
endlayer

layer
29,29,29,29,29,29,29,29,29,29,29,29,29,29,29,29,29,29,29,29,29,29,29,29,29,29,29,29,29,29,29,29,29,29,29,29,29,29,29,29,29,29,29,29,29
29,29,29,29,29,29,29,29,29,29,29,29,29,29,29,29,29,29,29,29,29,29,29,29,29,29,29,29,29,29,29,29,29,29,29,29,29,29,29,29,29,29,29,29,29
29,29,29,29,29,29,29,29,29,29,29,29,29,29,29,29,29,29,29,29,29,29,29,29,29,29,29,29,29,29,29,29,29,29,29,29,29,29,29,29,29,29,29,29,29
29,29,29,29,29,29,29,29,29,29,29,29,29,29,29,29,29,29,29,29,29,29,29,29,29,29,29,29,29,29,29,29,29,29,29,29,29,29,29,29,29,29,29,29,29
29,29,29,29,29,29,29,29,29,29,29,29,29,29,29,29,29,29,29,29,29,29,29,29,29,29,29,29,29,29,29,29,29,29,29,29,29,29,29,29,29,29,29,29,29
29,29,29,29,29,29,29,29,29,29,29,29,29,29,29,29,29,29,29,29,29,29,29,29,29,29,29,29,29,29,29,29,29,29,29,29,29,29,29,29,29,29,29,29,29
29,29,29,29,29,29,29,29,29,29,29,29,29,29,29,29,29,29,29,29,29,29,29,29,29,29,29,29,29,29,29,29,29,29,29,29,29,29,29,29,29,29,29,29,29
29,29,29,29,29,29,29,29,29,29,29,29,29,29,29,29,29,29,29,29,29,29,29,29,29,29,29,29,29,29,29,29,29,29,29,29,29,29,29,29,29,29,29,29,29
29,29,29,29,29,29,29,29,29,29,29,29,29,29,29,29,29,29,29,29,29,29,29,29,29,29,29,29,29,29,29,29,29,29,29,29,29,29,29,29,29,29,29,29,29
29,29,29,29,29,29,29,29,29,29,29,29,29,29,29,29,29,29,29,29,29,29,29,29,29,29,29,29,29,29,29,29,29,29,29,29,29,29,29,29,29,29,29,29,29
29,29,29,29,29,29,29,29,29,29,29,29,29,29,29,29,29,29,29,29,29,29,29,29,29,29,29,29,29,29,29,29,29,29,29,29,29,29,29,29,29,29,29,29,29
29,29,29,29,29,29,29,29,29,29,29,29,29,29,29,29,29,29,29,29,29,29,29,29,29,29,29,29,29,29,29,29,29,29,29,29,29,29,29,29,29,29,29,29,29
29,29,29,29,29,29,29,29,29,29,29,29,29,29,29,29,29,29,29,29,29,29,29,29,29,29,29,29,29,29,29,29,29,29,29,29,29,29,29,29,29,29,29,29,29
29,29,29,29,29,29,29,29,29,29,29,29,29,29,29,29,29,29,29,29,29,29,29,29,29,29,29,29,29,29,29,29,29,29,29,29,29,29,29,29,29,29,29,29,29
29,29,29,29,29,29,29,29,29,29,29,29,29,29,29,29,29,29,29,29,29,29,29,29,29,29,29,29,29,29,29,29,29,29,29,29,29,29,29,29,29,29,29,29,29
29,29,29,29,29,29,29,29,29,29,29,29,29,29,29,29,29,29,29,29,29,29,29,29,29,29,29,29,29,29,29,29,29,29,29,29,29,29,29,29,29,29,29,29,29
29,29,29,29,29,29,29,29,29,29,29,29,29,29,29,29,29,29,29,29,29,29,29,29,29,29,29,29,29,29,29,29,29,29,29,29,29,29,29,29,29,29,29,29,29
29,29,29,29,29,29,29,29,29,29,29,29,29,29,29,29,29,29,29,29,29,29,29,29,29,29,29,29,29,29,29,29,29,29,29,29,29,29,29,29,29,29,29,29,29
29,29,29,29,29,29,29,29,29,29,29,29,29,29,29,29,29,29,29,29,29,29,29,29,29,29,29,29,29,29,29,29,29,29,29,29,29,29,29,29,29,29,29,29,29
29,29,29,29,29,29,29,29,29,29,29,29,29,29,29,29,29,29,29,29,29,29,29,29,29,29,29,29,29,29,29,29,29,29,29,29,29,29,29,29,29,29,29,29,29
29,29,29,29,29,29,29,29,29,29,29,29,29,29,29,29,29,29,29,29,29,29,29,29,29,29,29,29,29,29,29,29,29,29,29,29,29,29,29,29,29,29,29,29,29
29,29,29,29,29,29,29,29,29,29,29,29,29,29,29,29,29,29,29,29,29,29,1,29,29,29,29,29,29,29,29,29,29,29,29,29,29,29,29,29,29,29,29,29,29
29,29,29,29,29,29,29,29,29,29,29,29,29,29,29,29,29,29,29,29,29,1,13,1,29,29,29,29,29,29,29,29,29,29,29,29,29,29,29,29,29,29,29,29,29
29,29,29,29,29,29,29,29,29,29,29,29,29,29,29,29,29,29,29,29,29,29,1,29,29,29,29,29,29,29,29,29,29,29,29,29,29,29,29,29,29,29,29,29,29
29,29,29,29,29,29,29,29,29,29,29,29,29,29,29,29,29,29,29,29,29,29,29,29,29,29,29,29,29,29,29,29,29,29,29,29,29,29,29,29,29,29,29,29,29
29,29,29,29,29,29,29,29,29,29,29,29,29,29,29,29,29,29,29,29,29,29,29,29,29,29,29,29,29,29,29,29,29,29,29,29,29,29,29,29,29,29,29,29,29
29,29,29,29,29,29,29,29,29,29,29,29,29,29,29,29,29,29,29,29,29,29,29,29,29,29,29,29,29,29,29,29,29,29,29,29,29,29,29,29,29,29,29,29,29
29,29,29,29,29,29,29,29,29,29,29,29,29,29,29,29,29,29,29,29,29,29,29,29,29,29,29,29,29,29,29,29,29,29,29,29,29,29,29,29,29,29,29,29,29
29,29,29,29,29,29,29,29,29,29,29,29,29,29,29,29,29,29,29,29,29,29,29,29,29,29,29,29,29,29,29,29,29,29,29,29,29,29,29,29,29,29,29,29,29
29,29,29,29,29,29,29,29,29,29,29,29,29,29,29,29,29,29,29,29,29,29,29,29,29,29,29,29,29,29,29,29,29,29,29,29,29,29,29,29,29,29,29,29,29
29,29,29,29,29,29,29,29,29,29,29,29,29,29,29,29,29,29,29,29,29,29,29,29,29,29,29,29,29,29,29,29,29,29,29,29,29,29,29,29,29,29,29,29,29
29,29,29,29,29,29,29,29,29,29,29,29,29,29,29,29,29,29,29,29,29,29,29,29,29,29,29,29,29,29,29,29,29,29,29,29,29,29,29,29,29,29,29,29,29
29,29,29,29,29,29,29,29,29,29,29,29,29,29,29,29,29,29,29,29,29,29,29,29,29,29,29,29,29,29,29,29,29,29,29,29,29,29,29,29,29,29,29,29,29
29,29,29,29,29,29,29,29,29,29,29,29,29,29,29,29,29,29,29,29,29,29,29,29,29,29,29,29,29,29,29,29,29,29,29,29,29,29,29,29,29,29,29,29,29
29,29,29,29,29,29,29,29,29,29,29,29,29,29,29,29,29,29,29,29,29,29,29,29,29,29,29,29,29,29,29,29,29,29,29,29,29,29,29,29,29,29,29,29,29
29,29,29,29,29,29,29,29,29,29,29,29,29,29,29,29,29,29,29,29,29,29,29,29,29,29,29,29,29,29,29,29,29,29,29,29,29,29,29,29,29,29,29,29,29
29,29,29,29,29,29,29,29,29,29,29,29,29,29,29,29,29,29,29,29,29,29,29,29,29,29,29,29,29,29,29,29,29,29,29,29,29,29,29,29,29,29,29,29,29
29,29,29,29,29,29,29,29,29,29,29,29,29,29,29,29,29,29,29,29,29,29,29,29,29,29,29,29,29,29,29,29,29,29,29,29,29,29,29,29,29,29,29,29,29
29,29,29,29,29,29,29,29,29,29,29,29,29,29,29,29,29,29,29,29,29,29,29,29,29,29,29,29,29,29,29,29,29,29,29,29,29,29,29,29,29,29,29,29,29
29,29,29,29,29,29,29,29,29,29,29,29,29,29,29,29,29,29,29,29,29,29,29,29,29,29,29,29,29,29,29,29,29,29,29,29,29,29,29,29,29,29,29,29,29
29,29,29,29,29,29,29,29,29,29,29,29,29,29,29,29,29,29,29,29,29,29,29,29,29,29,29,29,29,29,29,29,29,29,29,29,29,29,29,29,29,29,29,29,29
29,29,29,29,29,29,29,29,29,29,29,29,29,29,29,29,29,29,29,29,29,29,29,29,29,29,29,29,29,29,29,29,29,29,29,29,29,29,29,29,29,29,29,29,29
29,29,29,29,29,29,29,29,29,29,29,29,29,29,29,29,29,29,29,29,29,29,29,29,29,29,29,29,29,29,29,29,29,29,29,29,29,29,29,29,29,29,29,29,29
29,29,29,29,29,29,29,29,29,29,29,29,29,29,29,29,29,29,29,29,29,29,29,29,29,29,29,29,29,29,29,29,29,29,29,29,29,29,29,29,29,29,29,29,29
29,29,29,29,29,29,29,29,29,29,29,29,29,29,29,29,29,29,29,29,29,29,29,29,29,29,29,29,29,29,29,29,29,29,29,29,29,29,29,29,29,29,29,29,29
endlayer

layer
29,29,29,29,29,29,29,29,29,29,29,29,29,29,29,29,29,29,29,29,29,29,29,29,29,29,29,29,29,29,29,29,29,29,29,29,29,29,29,29,29,29,29,29,29
29,29,29,29,29,29,29,29,29,29,29,29,29,29,29,29,29,29,29,29,29,29,29,29,29,29,29,29,29,29,29,29,29,29,29,29,29,29,29,29,29,29,29,29,29
29,29,29,29,29,29,29,29,29,29,29,29,29,29,29,29,29,29,29,29,29,29,29,29,29,29,29,29,29,29,29,29,29,29,29,29,29,29,29,29,29,29,29,29,29
29,29,29,29,29,29,29,29,29,29,29,29,29,29,29,29,29,29,29,29,29,29,29,29,29,29,29,29,29,29,29,29,29,29,29,29,29,29,29,29,29,29,29,29,29
29,29,29,29,29,29,29,29,29,29,29,29,29,29,29,29,29,29,29,29,29,29,29,29,29,29,29,29,29,29,29,29,29,29,29,29,29,29,29,29,29,29,29,29,29
29,29,29,29,29,29,29,29,29,29,29,29,29,29,29,29,29,29,29,29,29,29,29,29,29,29,29,29,29,29,29,29,29,29,29,29,29,29,29,29,29,29,29,29,29
29,29,29,29,29,29,29,29,29,29,29,29,29,29,29,29,29,29,29,29,29,29,29,29,29,29,29,29,29,29,29,29,29,29,29,29,29,29,29,29,29,29,29,29,29
29,29,29,29,29,29,29,29,29,29,29,29,29,29,29,29,29,29,29,29,29,29,29,29,29,29,29,29,29,29,29,29,29,29,29,29,29,29,29,29,29,29,29,29,29
29,29,29,29,29,29,29,29,29,29,29,29,29,29,29,29,29,29,29,29,29,29,29,29,29,29,29,29,29,29,29,29,29,29,29,29,29,29,29,29,29,29,29,29,29
29,29,29,29,29,29,29,29,29,29,29,29,29,29,29,29,29,29,29,29,29,29,29,29,29,29,29,29,29,29,29,29,29,29,29,29,29,29,29,29,29,29,29,29,29
29,29,29,29,29,29,29,29,29,29,29,29,29,29,29,29,29,29,29,29,29,29,29,29,29,29,29,29,29,29,29,29,29,29,29,29,29,29,29,29,29,29,29,29,29
29,29,29,29,29,29,29,29,29,29,29,29,29,29,29,29,29,29,29,29,29,29,29,29,29,29,29,29,29,29,29,29,29,29,29,29,29,29,29,29,29,29,29,29,29
29,29,29,29,29,29,29,29,29,29,29,29,29,29,29,29,29,29,29,29,29,29,29,29,29,29,29,29,29,29,29,29,29,29,29,29,29,29,29,29,29,29,29,29,29
29,29,29,29,29,29,29,29,29,29,29,29,29,29,29,29,29,29,29,29,29,29,29,29,29,29,29,29,29,29,29,29,29,29,29,29,29,29,29,29,29,29,29,29,29
29,29,29,29,29,29,29,29,29,29,29,29,29,29,29,29,29,29,29,29,29,29,29,29,29,29,29,29,29,29,29,29,29,29,29,29,29,29,29,29,29,29,29,29,29
29,29,29,29,29,29,29,29,29,29,29,29,29,29,29,29,29,29,29,29,29,29,29,29,29,29,29,29,29,29,29,29,29,29,29,29,29,29,29,29,29,29,29,29,29
29,29,29,29,29,29,29,29,29,29,29,29,29,29,29,29,29,29,29,29,29,29,29,29,29,29,29,29,29,29,29,29,29,29,29,29,29,29,29,29,29,29,29,29,29
29,29,29,29,29,29,29,29,29,29,29,29,29,29,29,29,29,29,29,29,29,29,29,29,29,29,29,29,29,29,29,29,29,29,29,29,29,29,29,29,29,29,29,29,29
29,29,29,29,29,29,29,29,29,29,29,29,29,29,29,29,29,29,29,29,29,29,29,29,29,29,29,29,29,29,29,29,29,29,29,29,29,29,29,29,29,29,29,29,29
29,29,29,29,29,29,29,29,29,29,29,29,29,29,29,29,29,29,29,29,29,31,31,31,29,29,29,29,29,29,29,29,29,29,29,29,29,29,29,29,29,29,29,29,29
29,29,29,29,29,29,29,29,29,29,29,29,29,29,29,29,29,29,29,29,31,31,32,31,31,29,29,29,29,29,29,29,29,29,29,29,29,29,29,29,29,29,29,29,29
29,29,29,29,29,29,29,29,29,29,29,29,29,29,29,29,29,29,29,31,31,32,1,32,31,31,29,29,29,29,29,29,29,29,29,29,29,29,29,29,29,29,29,29,29
29,29,29,29,29,29,29,29,29,29,29,29,29,29,29,29,29,29,29,31,32,1,13,1,32,31,29,29,29,29,29,29,29,29,29,29,29,29,29,29,29,29,29,29,29
29,29,29,29,29,29,29,29,29,29,29,29,29,29,29,29,29,29,29,31,31,32,1,32,31,31,29,29,29,29,29,29,29,29,29,29,29,29,29,29,29,29,29,29,29
29,29,29,29,29,29,29,29,29,29,29,29,29,29,29,29,29,29,29,29,31,31,32,31,31,29,29,29,29,29,29,29,29,29,29,29,29,29,29,29,29,29,29,29,29
29,29,29,29,29,29,29,29,29,29,29,29,29,29,29,29,29,29,29,29,29,31,31,31,29,29,29,29,29,29,29,29,29,29,29,29,29,29,29,29,29,29,29,29,29
29,29,29,29,29,29,29,29,29,29,29,29,29,29,29,29,29,29,29,29,29,29,29,29,29,29,29,29,29,29,29,29,29,29,29,29,29,29,29,29,29,29,29,29,29
29,29,29,29,29,29,29,29,29,29,29,29,29,29,29,29,29,29,29,29,29,29,29,29,29,29,29,29,29,29,29,29,29,29,29,29,29,29,29,29,29,29,29,29,29
29,29,29,29,29,29,29,29,29,29,29,29,29,29,29,29,29,29,29,29,29,29,29,29,29,29,29,29,29,29,29,29,29,29,29,29,29,29,29,29,29,29,29,29,29
29,29,29,29,29,29,29,29,29,29,29,29,29,29,29,29,29,29,29,29,29,29,29,29,29,29,29,29,29,29,29,29,29,29,29,29,29,29,29,29,29,29,29,29,29
29,29,29,29,29,29,29,29,29,29,29,29,29,29,29,29,29,29,29,29,29,29,29,29,29,29,29,29,29,29,29,29,29,29,29,29,29,29,29,29,29,29,29,29,29
29,29,29,29,29,29,29,29,29,29,29,29,29,29,29,29,29,29,29,29,29,29,29,29,29,29,29,29,29,29,29,29,29,29,29,29,29,29,29,29,29,29,29,29,29
29,29,29,29,29,29,29,29,29,29,29,29,29,29,29,29,29,29,29,29,29,29,29,29,29,29,29,29,29,29,29,29,29,29,29,29,29,29,29,29,29,29,29,29,29
29,29,29,29,29,29,29,29,29,29,29,29,29,29,29,29,29,29,29,29,29,29,29,29,29,29,29,29,29,29,29,29,29,29,29,29,29,29,29,29,29,29,29,29,29
29,29,29,29,29,29,29,29,29,29,29,29,29,29,29,29,29,29,29,29,29,29,29,29,29,29,29,29,29,29,29,29,29,29,29,29,29,29,29,29,29,29,29,29,29
29,29,29,29,29,29,29,29,29,29,29,29,29,29,29,29,29,29,29,29,29,29,29,29,29,29,29,29,29,29,29,29,29,29,29,29,29,29,29,29,29,29,29,29,29
29,29,29,29,29,29,29,29,29,29,29,29,29,29,29,29,29,29,29,29,29,29,29,29,29,29,29,29,29,29,29,29,29,29,29,29,29,29,29,29,29,29,29,29,29
29,29,29,29,29,29,29,29,29,29,29,29,29,29,29,29,29,29,29,29,29,29,29,29,29,29,29,29,29,29,29,29,29,29,29,29,29,29,29,29,29,29,29,29,29
29,29,29,29,29,29,29,29,29,29,29,29,29,29,29,29,29,29,29,29,29,29,29,29,29,29,29,29,29,29,29,29,29,29,29,29,29,29,29,29,29,29,29,29,29
29,29,29,29,29,29,29,29,29,29,29,29,29,29,29,29,29,29,29,29,29,29,29,29,29,29,29,29,29,29,29,29,29,29,29,29,29,29,29,29,29,29,29,29,29
29,29,29,29,29,29,29,29,29,29,29,29,29,29,29,29,29,29,29,29,29,29,29,29,29,29,29,29,29,29,29,29,29,29,29,29,29,29,29,29,29,29,29,29,29
29,29,29,29,29,29,29,29,29,29,29,29,29,29,29,29,29,29,29,29,29,29,29,29,29,29,29,29,29,29,29,29,29,29,29,29,29,29,29,29,29,29,29,29,29
29,29,29,29,29,29,29,29,29,29,29,29,29,29,29,29,29,29,29,29,29,29,29,29,29,29,29,29,29,29,29,29,29,29,29,29,29,29,29,29,29,29,29,29,29
29,29,29,29,29,29,29,29,29,29,29,29,29,29,29,29,29,29,29,29,29,29,29,29,29,29,29,29,29,29,29,29,29,29,29,29,29,29,29,29,29,29,29,29,29
29,29,29,29,29,29,29,29,29,29,29,29,29,29,29,29,29,29,29,29,29,29,29,29,29,29,29,29,29,29,29,29,29,29,29,29,29,29,29,29,29,29,29,29,29
endlayer

layer
29,29,29,29,29,29,29,29,29,29,29,29,29,29,29,29,29,29,29,29,29,29,29,29,29,29,29,29,29,29,29,29,29,29,29,29,29,29,29,29,29,29,29,29,29
29,29,29,29,29,29,29,29,29,29,29,29,29,29,29,29,29,29,29,29,29,29,29,29,29,29,29,29,29,29,29,29,29,29,29,29,29,29,29,29,29,29,29,29,29
29,29,29,29,29,29,29,29,29,29,29,29,29,29,29,29,29,29,29,29,29,29,29,29,29,29,29,29,29,29,29,29,29,29,29,29,29,29,29,29,29,29,29,29,29
29,29,29,29,29,29,29,29,29,29,29,29,29,29,29,29,29,29,29,29,29,29,29,29,29,29,29,29,29,29,29,29,29,29,29,29,29,29,29,29,29,29,29,29,29
29,29,29,29,29,29,29,29,29,29,29,29,29,29,29,29,29,29,29,29,29,29,29,29,29,29,29,29,29,29,29,29,29,29,29,29,29,29,29,29,29,29,29,29,29
29,29,29,29,29,29,29,29,29,29,29,29,29,29,29,29,29,29,29,29,29,29,29,29,29,29,29,29,29,29,29,29,29,29,29,29,29,29,29,29,29,29,29,29,29
29,29,29,29,29,29,29,29,29,29,29,29,29,29,29,29,29,29,29,29,29,29,29,29,29,29,29,29,29,29,29,29,29,29,29,29,29,29,29,29,29,29,29,29,29
29,29,29,29,29,29,29,29,29,29,29,29,29,29,29,29,29,29,29,29,29,29,29,29,29,29,29,29,29,29,29,29,29,29,29,29,29,29,29,29,29,29,29,29,29
29,29,29,29,29,29,29,29,29,29,29,29,29,29,29,29,29,29,29,29,29,29,29,29,29,29,29,29,29,29,29,29,29,29,29,29,29,29,29,29,29,29,29,29,29
29,29,29,29,29,29,29,29,29,29,29,29,29,29,29,29,29,29,29,29,29,29,29,29,29,29,29,29,29,29,29,29,29,29,29,29,29,29,29,29,29,29,29,29,29
29,29,29,29,29,29,29,29,29,29,29,29,29,29,29,29,29,29,29,29,29,29,29,29,29,29,29,29,29,29,29,29,29,29,29,29,29,29,29,29,29,29,29,29,29
29,29,29,29,29,29,29,29,29,29,29,29,29,29,29,29,29,29,29,29,29,29,29,29,29,29,29,29,29,29,29,29,29,29,29,29,29,29,29,29,29,29,29,29,29
29,29,29,29,29,29,29,29,29,29,29,29,29,29,29,29,29,29,29,29,29,29,29,29,29,29,29,29,29,29,29,29,29,29,29,29,29,29,29,29,29,29,29,29,29
29,29,29,29,29,29,29,29,29,29,29,29,29,29,29,29,29,29,29,29,29,29,29,29,29,29,29,29,29,29,29,29,29,29,29,29,29,29,29,29,29,29,29,29,29
29,29,29,29,29,29,29,29,29,29,29,29,29,29,29,29,29,29,29,29,29,29,29,29,29,29,29,29,29,29,29,29,29,29,29,29,29,29,29,29,29,29,29,29,29
29,29,29,29,29,29,29,29,29,29,29,29,29,29,29,29,29,29,29,29,29,29,29,29,29,29,29,29,29,29,29,29,29,29,29,29,29,29,29,29,29,29,29,29,29
29,29,29,29,29,29,29,29,29,29,29,29,29,29,29,29,29,29,29,29,29,29,29,29,29,29,29,29,29,29,29,29,29,29,29,29,29,29,29,29,29,29,29,29,29
29,29,29,29,29,29,29,29,29,29,29,29,29,29,29,29,29,29,29,29,29,29,29,29,29,29,29,29,29,29,29,29,29,29,29,29,29,29,29,29,29,29,29,29,29
29,29,29,29,29,29,29,29,29,29,29,29,29,29,29,29,29,29,29,29,29,29,29,29,29,29,29,29,29,29,29,29,29,29,29,29,29,29,29,29,29,29,29,29,29
29,29,29,29,29,29,29,29,29,29,29,29,29,29,29,29,29,29,29,29,29,34,0,33,29,29,29,29,29,29,29,29,29,29,29,29,29,29,29,29,29,29,29,29,29
29,29,29,29,29,29,29,29,29,29,29,29,29,29,29,29,29,29,29,29,0,0,0,0,0,29,29,29,29,29,29,29,29,29,29,29,29,29,29,29,29,29,29,29,29
29,29,29,29,29,29,29,29,29,29,29,29,29,29,29,29,29,29,29,33,0,0,0,0,0,34,29,29,29,29,29,29,29,29,29,29,29,29,29,29,29,29,29,29,29
29,29,29,29,29,29,29,29,29,29,29,29,29,29,29,29,29,29,29,0,0,0,0,0,0,0,29,29,29,29,29,29,29,29,29,29,29,29,29,29,29,29,29,29,29
29,29,29,29,29,29,29,29,29,29,29,29,29,29,29,29,29,29,29,34,0,0,0,0,0,34,29,29,29,29,29,29,29,29,29,29,29,29,29,29,29,29,29,29,29
29,29,29,29,29,29,29,29,29,29,29,29,29,29,29,29,29,29,29,29,0,0,0,0,0,29,29,29,29,29,29,29,29,29,29,29,29,29,29,29,29,29,29,29,29
29,29,29,29,29,29,29,29,29,29,29,29,29,29,29,29,29,29,29,29,29,34,0,34,29,29,29,29,29,29,29,29,29,29,29,29,29,29,29,29,29,29,29,29,29
29,29,29,29,29,29,29,29,29,29,29,29,29,29,29,29,29,29,29,29,29,29,29,29,29,29,29,29,29,29,29,29,29,29,29,29,29,29,29,29,29,29,29,29,29
29,29,29,29,29,29,29,29,29,29,29,29,29,29,29,29,29,29,29,29,29,29,29,29,29,29,29,29,29,29,29,29,29,29,29,29,29,29,29,29,29,29,29,29,29
29,29,29,29,29,29,29,29,29,29,29,29,29,29,29,29,29,29,29,29,29,29,29,29,29,29,29,29,29,29,29,29,29,29,29,29,29,29,29,29,29,29,29,29,29
29,29,29,29,29,29,29,29,29,29,29,29,29,29,29,29,29,29,29,29,29,29,29,29,29,29,29,29,29,29,29,29,29,29,29,29,29,29,29,29,29,29,29,29,29
29,29,29,29,29,29,29,29,29,29,29,29,29,29,29,29,29,29,29,29,29,29,29,29,29,29,29,29,29,29,29,29,29,29,29,29,29,29,29,29,29,29,29,29,29
29,29,29,29,29,29,29,29,29,29,29,29,29,29,29,29,29,29,29,29,29,29,29,29,29,29,29,29,29,29,29,29,29,29,29,29,29,29,29,29,29,29,29,29,29
29,29,29,29,29,29,29,29,29,29,29,29,29,29,29,29,29,29,29,29,29,29,29,29,29,29,29,29,29,29,29,29,29,29,29,29,29,29,29,29,29,29,29,29,29
29,29,29,29,29,29,29,29,29,29,29,29,29,29,29,29,29,29,29,29,29,29,29,29,29,29,29,29,29,29,29,29,29,29,29,29,29,29,29,29,29,29,29,29,29
29,29,29,29,29,29,29,29,29,29,29,29,29,29,29,29,29,29,29,29,29,29,29,29,29,29,29,29,29,29,29,29,29,29,29,29,29,29,29,29,29,29,29,29,29
29,29,29,29,29,29,29,29,29,29,29,29,29,29,29,29,29,29,29,29,29,29,29,29,29,29,29,29,29,29,29,29,29,29,29,29,29,29,29,29,29,29,29,29,29
29,29,29,29,29,29,29,29,29,29,29,29,29,29,29,29,29,29,29,29,29,29,29,29,29,29,29,29,29,29,29,29,29,29,29,29,29,29,29,29,29,29,29,29,29
29,29,29,29,29,29,29,29,29,29,29,29,29,29,29,29,29,29,29,29,29,29,29,29,29,29,29,29,29,29,29,29,29,29,29,29,29,29,29,29,29,29,29,29,29
29,29,29,29,29,29,29,29,29,29,29,29,29,29,29,29,29,29,29,29,29,29,29,29,29,29,29,29,29,29,29,29,29,29,29,29,29,29,29,29,29,29,29,29,29
29,29,29,29,29,29,29,29,29,29,29,29,29,29,29,29,29,29,29,29,29,29,29,29,29,29,29,29,29,29,29,29,29,29,29,29,29,29,29,29,29,29,29,29,29
29,29,29,29,29,29,29,29,29,29,29,29,29,29,29,29,29,29,29,29,29,29,29,29,29,29,29,29,29,29,29,29,29,29,29,29,29,29,29,29,29,29,29,29,29
29,29,29,29,29,29,29,29,29,29,29,29,29,29,29,29,29,29,29,29,29,29,29,29,29,29,29,29,29,29,29,29,29,29,29,29,29,29,29,29,29,29,29,29,29
29,29,29,29,29,29,29,29,29,29,29,29,29,29,29,29,29,29,29,29,29,29,29,29,29,29,29,29,29,29,29,29,29,29,29,29,29,29,29,29,29,29,29,29,29
29,29,29,29,29,29,29,29,29,29,29,29,29,29,29,29,29,29,29,29,29,29,29,29,29,29,29,29,29,29,29,29,29,29,29,29,29,29,29,29,29,29,29,29,29
29,29,29,29,29,29,29,29,29,29,29,29,29,29,29,29,29,29,29,29,29,29,29,29,29,29,29,29,29,29,29,29,29,29,29,29,29,29,29,29,29,29,29,29,29
endlayer

layer
29,29,29,29,29,29,29,29,29,29,29,29,29,29,29,29,29,29,29,29,29,29,29,29,29,29,29,29,29,29,29,29,29,29,29,29,29,29,29,29,29,29,29,29,29
29,29,29,29,29,29,29,29,29,29,29,29,29,29,29,29,29,29,29,29,29,29,29,29,29,29,29,29,29,29,29,29,29,29,29,29,29,29,29,29,29,29,29,29,29
29,29,29,29,29,29,29,29,29,29,29,29,29,29,29,29,29,29,29,29,29,29,29,29,29,29,29,29,29,29,29,29,29,29,29,29,29,29,29,29,29,29,29,29,29
29,29,29,29,29,29,29,29,29,29,29,29,29,29,29,29,29,29,29,29,29,29,29,29,29,29,29,29,29,29,29,29,29,29,29,29,29,29,29,29,29,29,29,29,29
29,29,29,29,29,29,29,29,29,29,29,29,29,29,29,29,29,29,29,29,29,29,29,29,29,29,29,29,29,29,29,29,29,29,29,29,29,29,29,29,29,29,29,29,29
29,29,29,29,29,29,29,29,29,29,29,29,29,29,29,29,29,29,29,29,29,29,29,29,29,29,29,29,29,29,29,29,29,29,29,29,29,29,29,29,29,29,29,29,29
29,29,29,29,29,29,29,29,29,29,29,29,29,29,29,29,29,29,29,29,29,29,29,29,29,29,29,29,29,29,29,29,29,29,29,29,29,29,29,29,29,29,29,29,29
29,29,29,29,29,29,29,29,29,29,29,29,29,29,29,29,29,29,29,29,29,29,29,29,29,29,29,29,29,29,29,29,29,29,29,29,29,29,29,29,29,29,29,29,29
29,29,29,29,29,29,29,29,29,29,29,29,29,29,29,29,29,29,29,29,29,29,29,29,29,29,29,29,29,29,29,29,29,29,29,29,29,29,29,29,29,29,29,29,29
29,29,29,29,29,29,29,29,29,29,29,29,29,29,29,29,29,29,29,29,29,29,29,29,29,29,29,29,29,29,29,29,29,29,29,29,29,29,29,29,29,29,29,29,29
29,29,29,29,29,29,29,29,29,29,29,29,29,29,29,29,29,29,29,29,29,29,29,29,29,29,29,29,29,29,29,29,29,29,29,29,29,29,29,29,29,29,29,29,29
29,29,29,29,29,29,29,29,29,29,29,29,29,29,29,29,29,29,29,29,29,29,29,29,29,29,29,29,29,29,29,29,29,29,29,29,29,29,29,29,29,29,29,29,29
29,29,29,29,29,29,29,29,29,29,29,29,29,29,29,29,29,29,29,29,29,29,29,29,29,29,29,29,29,29,29,29,29,29,29,29,29,29,29,29,29,29,29,29,29
29,29,29,29,29,29,29,29,29,29,29,29,29,29,29,29,29,29,29,29,29,29,29,29,29,29,29,29,29,29,29,29,29,29,29,29,29,29,29,29,29,29,29,29,29
29,29,29,29,29,29,29,29,29,29,29,29,29,29,29,29,29,29,29,29,29,29,29,29,29,29,29,29,29,29,29,29,29,29,29,29,29,29,29,29,29,29,29,29,29
29,29,29,29,29,29,29,29,29,29,29,29,29,29,29,29,29,29,29,29,29,29,29,29,29,29,29,29,29,29,29,29,29,29,29,29,29,29,29,29,29,29,29,29,29
29,29,29,29,29,29,29,29,29,29,29,29,29,29,29,29,29,29,29,29,29,29,29,29,29,29,29,29,29,29,29,29,29,29,29,29,29,29,29,29,29,29,29,29,29
29,29,29,29,29,29,29,29,29,29,29,29,29,29,29,29,29,29,29,29,29,29,29,29,29,29,29,29,29,29,29,29,29,29,29,29,29,29,29,29,29,29,29,29,29
29,29,29,29,29,29,29,29,29,29,29,29,29,29,29,29,29,29,29,29,29,29,29,29,29,29,29,29,29,29,29,29,29,29,29,29,29,29,29,29,29,29,29,29,29
29,29,29,29,29,29,29,29,29,29,29,29,29,29,29,29,29,29,29,29,29,34,0,34,29,29,29,29,29,29,29,29,29,29,29,29,29,29,29,29,29,29,29,29,29
29,29,29,29,29,29,29,29,29,29,29,29,29,29,29,29,29,29,29,29,0,0,0,0,0,29,29,29,29,29,29,29,29,29,29,29,29,29,29,29,29,29,29,29,29
29,29,29,29,29,29,29,29,29,29,29,29,29,29,29,29,29,29,29,34,0,0,0,0,0,34,29,29,29,29,29,29,29,29,29,29,29,29,29,29,29,29,29,29,29
29,29,29,29,29,29,29,29,29,29,29,29,29,29,29,29,29,29,29,0,0,0,0,0,0,0,29,29,29,29,29,29,29,29,29,29,29,29,29,29,29,29,29,29,29
29,29,29,29,29,29,29,29,29,29,29,29,29,29,29,29,29,29,29,34,0,0,0,0,0,33,29,29,29,29,29,29,29,29,29,29,29,29,29,29,29,29,29,29,29
29,29,29,29,29,29,29,29,29,29,29,29,29,29,29,29,29,29,29,29,0,0,0,0,0,29,29,29,29,29,29,29,29,29,29,29,29,29,29,29,29,29,29,29,29
29,29,29,29,29,29,29,29,29,29,29,29,29,29,29,29,29,29,29,29,29,33,0,34,29,29,29,29,29,29,29,29,29,29,29,29,29,29,29,29,29,29,29,29,29
29,29,29,29,29,29,29,29,29,29,29,29,29,29,29,29,29,29,29,29,29,29,29,29,29,29,29,29,29,29,29,29,29,29,29,29,29,29,29,29,29,29,29,29,29
29,29,29,29,29,29,29,29,29,29,29,29,29,29,29,29,29,29,29,29,29,29,29,29,29,29,29,29,29,29,29,29,29,29,29,29,29,29,29,29,29,29,29,29,29
29,29,29,29,29,29,29,29,29,29,29,29,29,29,29,29,29,29,29,29,29,29,29,29,29,29,29,29,29,29,29,29,29,29,29,29,29,29,29,29,29,29,29,29,29
29,29,29,29,29,29,29,29,29,29,29,29,29,29,29,29,29,29,29,29,29,29,29,29,29,29,29,29,29,29,29,29,29,29,29,29,29,29,29,29,29,29,29,29,29
29,29,29,29,29,29,29,29,29,29,29,29,29,29,29,29,29,29,29,29,29,29,29,29,29,29,29,29,29,29,29,29,29,29,29,29,29,29,29,29,29,29,29,29,29
29,29,29,29,29,29,29,29,29,29,29,29,29,29,29,29,29,29,29,29,29,29,29,29,29,29,29,29,29,29,29,29,29,29,29,29,29,29,29,29,29,29,29,29,29
29,29,29,29,29,29,29,29,29,29,29,29,29,29,29,29,29,29,29,29,29,29,29,29,29,29,29,29,29,29,29,29,29,29,29,29,29,29,29,29,29,29,29,29,29
29,29,29,29,29,29,29,29,29,29,29,29,29,29,29,29,29,29,29,29,29,29,29,29,29,29,29,29,29,29,29,29,29,29,29,29,29,29,29,29,29,29,29,29,29
29,29,29,29,29,29,29,29,29,29,29,29,29,29,29,29,29,29,29,29,29,29,29,29,29,29,29,29,29,29,29,29,29,29,29,29,29,29,29,29,29,29,29,29,29
29,29,29,29,29,29,29,29,29,29,29,29,29,29,29,29,29,29,29,29,29,29,29,29,29,29,29,29,29,29,29,29,29,29,29,29,29,29,29,29,29,29,29,29,29
29,29,29,29,29,29,29,29,29,29,29,29,29,29,29,29,29,29,29,29,29,29,29,29,29,29,29,29,29,29,29,29,29,29,29,29,29,29,29,29,29,29,29,29,29
29,29,29,29,29,29,29,29,29,29,29,29,29,29,29,29,29,29,29,29,29,29,29,29,29,29,29,29,29,29,29,29,29,29,29,29,29,29,29,29,29,29,29,29,29
29,29,29,29,29,29,29,29,29,29,29,29,29,29,29,29,29,29,29,29,29,29,29,29,29,29,29,29,29,29,29,29,29,29,29,29,29,29,29,29,29,29,29,29,29
29,29,29,29,29,29,29,29,29,29,29,29,29,29,29,29,29,29,29,29,29,29,29,29,29,29,29,29,29,29,29,29,29,29,29,29,29,29,29,29,29,29,29,29,29
29,29,29,29,29,29,29,29,29,29,29,29,29,29,29,29,29,29,29,29,29,29,29,29,29,29,29,29,29,29,29,29,29,29,29,29,29,29,29,29,29,29,29,29,29
29,29,29,29,29,29,29,29,29,29,29,29,29,29,29,29,29,29,29,29,29,29,29,29,29,29,29,29,29,29,29,29,29,29,29,29,29,29,29,29,29,29,29,29,29
29,29,29,29,29,29,29,29,29,29,29,29,29,29,29,29,29,29,29,29,29,29,29,29,29,29,29,29,29,29,29,29,29,29,29,29,29,29,29,29,29,29,29,29,29
29,29,29,29,29,29,29,29,29,29,29,29,29,29,29,29,29,29,29,29,29,29,29,29,29,29,29,29,29,29,29,29,29,29,29,29,29,29,29,29,29,29,29,29,29
29,29,29,29,29,29,29,29,29,29,29,29,29,29,29,29,29,29,29,29,29,29,29,29,29,29,29,29,29,29,29,29,29,29,29,29,29,29,29,29,29,29,29,29,29
endlayer

layer
29,29,29,29,29,29,29,29,29,29,29,29,29,29,29,29,29,29,29,29,29,29,29,29,29,29,29,29,29,29,29,29,29,29,29,29,29,29,29,29,29,29,29,29,29
29,29,29,29,29,29,29,29,29,29,29,29,29,29,29,29,29,29,29,29,29,29,29,29,29,29,29,29,29,29,29,29,29,29,29,29,29,29,29,29,29,29,29,29,29
29,29,29,29,29,29,29,29,29,29,29,29,29,29,29,29,29,29,29,29,29,29,29,29,29,29,29,29,29,29,29,29,29,29,29,29,29,29,29,29,29,29,29,29,29
29,29,29,29,29,29,29,29,29,29,29,29,29,29,29,29,29,29,29,29,29,29,29,29,29,29,29,29,29,29,29,29,29,29,29,29,29,29,29,29,29,29,29,29,29
29,29,29,29,29,29,29,29,29,29,29,29,29,29,29,29,29,29,29,29,29,29,29,29,29,29,29,29,29,29,29,29,29,29,29,29,29,29,29,29,29,29,29,29,29
29,29,29,29,29,29,29,29,29,29,29,29,29,29,29,29,29,29,29,29,29,29,29,29,29,29,29,29,29,29,29,29,29,29,29,29,29,29,29,29,29,29,29,29,29
29,29,29,29,29,29,29,29,29,29,29,29,29,29,29,29,29,29,29,29,29,29,29,29,29,29,29,29,29,29,29,29,29,29,29,29,29,29,29,29,29,29,29,29,29
29,29,29,29,29,29,29,29,29,29,29,29,29,29,29,29,29,29,29,29,29,29,29,29,29,29,29,29,29,29,29,29,29,29,29,29,29,29,29,29,29,29,29,29,29
29,29,29,29,29,29,29,29,29,29,29,29,29,29,29,29,29,29,29,29,29,29,29,29,29,29,29,29,29,29,29,29,29,29,29,29,29,29,29,29,29,29,29,29,29
29,29,29,29,29,29,29,29,29,29,29,29,29,29,29,29,29,29,29,29,29,29,29,29,29,29,29,29,29,29,29,29,29,29,29,29,29,29,29,29,29,29,29,29,29
29,29,29,29,29,29,29,29,29,29,29,29,29,29,29,29,29,29,29,29,29,29,29,29,29,29,29,29,29,29,29,29,29,29,29,29,29,29,29,29,29,29,29,29,29
29,29,29,29,29,29,29,29,29,29,29,29,29,29,29,29,29,29,29,29,29,29,29,29,29,29,29,29,29,29,29,29,29,29,29,29,29,29,29,29,29,29,29,29,29
29,29,29,29,29,29,29,29,29,29,29,29,29,29,29,29,29,29,29,29,29,29,29,29,29,29,29,29,29,29,29,29,29,29,29,29,29,29,29,29,29,29,29,29,29
29,29,29,29,29,29,29,29,29,29,29,29,29,29,29,29,29,29,29,29,29,29,29,29,29,29,29,29,29,29,29,29,29,29,29,29,29,29,29,29,29,29,29,29,29
29,29,29,29,29,29,29,29,29,29,29,29,29,29,29,29,29,29,29,29,29,29,29,29,29,29,29,29,29,29,29,29,29,29,29,29,29,29,29,29,29,29,29,29,29
29,29,29,29,29,29,29,29,29,29,29,29,29,29,29,29,29,29,29,29,29,29,29,29,29,29,29,29,29,29,29,29,29,29,29,29,29,29,29,29,29,29,29,29,29
29,29,29,29,29,29,29,29,29,29,29,29,29,29,29,29,29,29,29,29,29,29,29,29,29,29,29,29,29,29,29,29,29,29,29,29,29,29,29,29,29,29,29,29,29
29,29,29,29,29,29,29,29,29,29,29,29,29,29,29,29,29,29,29,29,29,29,29,29,29,29,29,29,29,29,29,29,29,29,29,29,29,29,29,29,29,29,29,29,29
29,29,29,29,29,29,29,29,29,29,29,29,29,29,29,29,29,29,29,29,29,29,29,29,29,29,29,29,29,29,29,29,29,29,29,29,29,29,29,29,29,29,29,29,29
29,29,29,29,29,29,29,29,29,29,29,29,29,29,29,29,29,29,29,29,29,33,0,33,29,29,29,29,29,29,29,29,29,29,29,29,29,29,29,29,29,29,29,29,29
29,29,29,29,29,29,29,29,29,29,29,29,29,29,29,29,29,29,29,29,0,0,0,0,0,29,29,29,29,29,29,29,29,29,29,29,29,29,29,29,29,29,29,29,29
29,29,29,29,29,29,29,29,29,29,29,29,29,29,29,29,29,29,29,34,0,0,0,0,0,34,29,29,29,29,29,29,29,29,29,29,29,29,29,29,29,29,29,29,29
29,29,29,29,29,29,29,29,29,29,29,29,29,29,29,29,29,29,29,0,0,0,0,0,0,0,29,29,29,29,29,29,29,29,29,29,29,29,29,29,29,29,29,29,29
29,29,29,29,29,29,29,29,29,29,29,29,29,29,29,29,29,29,29,33,0,0,0,0,0,33,29,29,29,29,29,29,29,29,29,29,29,29,29,29,29,29,29,29,29
29,29,29,29,29,29,29,29,29,29,29,29,29,29,29,29,29,29,29,29,0,0,0,0,0,29,29,29,29,29,29,29,29,29,29,29,29,29,29,29,29,29,29,29,29
29,29,29,29,29,29,29,29,29,29,29,29,29,29,29,29,29,29,29,29,29,34,0,34,29,29,29,29,29,29,29,29,29,29,29,29,29,29,29,29,29,29,29,29,29
29,29,29,29,29,29,29,29,29,29,29,29,29,29,29,29,29,29,29,29,29,29,29,29,29,29,29,29,29,29,29,29,29,29,29,29,29,29,29,29,29,29,29,29,29
29,29,29,29,29,29,29,29,29,29,29,29,29,29,29,29,29,29,29,29,29,29,29,29,29,29,29,29,29,29,29,29,29,29,29,29,29,29,29,29,29,29,29,29,29
29,29,29,29,29,29,29,29,29,29,29,29,29,29,29,29,29,29,29,29,29,29,29,29,29,29,29,29,29,29,29,29,29,29,29,29,29,29,29,29,29,29,29,29,29
29,29,29,29,29,29,29,29,29,29,29,29,29,29,29,29,29,29,29,29,29,29,29,29,29,29,29,29,29,29,29,29,29,29,29,29,29,29,29,29,29,29,29,29,29
29,29,29,29,29,29,29,29,29,29,29,29,29,29,29,29,29,29,29,29,29,29,29,29,29,29,29,29,29,29,29,29,29,29,29,29,29,29,29,29,29,29,29,29,29
29,29,29,29,29,29,29,29,29,29,29,29,29,29,29,29,29,29,29,29,29,29,29,29,29,29,29,29,29,29,29,29,29,29,29,29,29,29,29,29,29,29,29,29,29
29,29,29,29,29,29,29,29,29,29,29,29,29,29,29,29,29,29,29,29,29,29,29,29,29,29,29,29,29,29,29,29,29,29,29,29,29,29,29,29,29,29,29,29,29
29,29,29,29,29,29,29,29,29,29,29,29,29,29,29,29,29,29,29,29,29,29,29,29,29,29,29,29,29,29,29,29,29,29,29,29,29,29,29,29,29,29,29,29,29
29,29,29,29,29,29,29,29,29,29,29,29,29,29,29,29,29,29,29,29,29,29,29,29,29,29,29,29,29,29,29,29,29,29,29,29,29,29,29,29,29,29,29,29,29
29,29,29,29,29,29,29,29,29,29,29,29,29,29,29,29,29,29,29,29,29,29,29,29,29,29,29,29,29,29,29,29,29,29,29,29,29,29,29,29,29,29,29,29,29
29,29,29,29,29,29,29,29,29,29,29,29,29,29,29,29,29,29,29,29,29,29,29,29,29,29,29,29,29,29,29,29,29,29,29,29,29,29,29,29,29,29,29,29,29
29,29,29,29,29,29,29,29,29,29,29,29,29,29,29,29,29,29,29,29,29,29,29,29,29,29,29,29,29,29,29,29,29,29,29,29,29,29,29,29,29,29,29,29,29
29,29,29,29,29,29,29,29,29,29,29,29,29,29,29,29,29,29,29,29,29,29,29,29,29,29,29,29,29,29,29,29,29,29,29,29,29,29,29,29,29,29,29,29,29
29,29,29,29,29,29,29,29,29,29,29,29,29,29,29,29,29,29,29,29,29,29,29,29,29,29,29,29,29,29,29,29,29,29,29,29,29,29,29,29,29,29,29,29,29
29,29,29,29,29,29,29,29,29,29,29,29,29,29,29,29,29,29,29,29,29,29,29,29,29,29,29,29,29,29,29,29,29,29,29,29,29,29,29,29,29,29,29,29,29
29,29,29,29,29,29,29,29,29,29,29,29,29,29,29,29,29,29,29,29,29,29,29,29,29,29,29,29,29,29,29,29,29,29,29,29,29,29,29,29,29,29,29,29,29
29,29,29,29,29,29,29,29,29,29,29,29,29,29,29,29,29,29,29,29,29,29,29,29,29,29,29,29,29,29,29,29,29,29,29,29,29,29,29,29,29,29,29,29,29
29,29,29,29,29,29,29,29,29,29,29,29,29,29,29,29,29,29,29,29,29,29,29,29,29,29,29,29,29,29,29,29,29,29,29,29,29,29,29,29,29,29,29,29,29
29,29,29,29,29,29,29,29,29,29,29,29,29,29,29,29,29,29,29,29,29,29,29,29,29,29,29,29,29,29,29,29,29,29,29,29,29,29,29,29,29,29,29,29,29
endlayer

layer
29,29,29,29,29,29,29,29,29,29,29,29,29,29,29,29,29,29,29,29,29,29,29,29,29,29,29,29,29,29,29,29,29,29,29,29,29,29,29,29,29,29,29,29,29
29,29,29,29,29,29,29,29,29,29,29,29,29,29,29,29,29,29,29,29,29,29,29,29,29,29,29,29,29,29,29,29,29,29,29,29,29,29,29,29,29,29,29,29,29
29,29,29,29,29,29,29,29,29,29,29,29,29,29,29,29,29,29,29,29,29,29,29,29,29,29,29,29,29,29,29,29,29,29,29,29,29,29,29,29,29,29,29,29,29
29,29,29,29,29,29,29,29,29,29,29,29,29,29,29,29,29,29,29,29,29,29,29,29,29,29,29,29,29,29,29,29,29,29,29,29,29,29,29,29,29,29,29,29,29
29,29,29,29,29,29,29,29,29,29,29,29,29,29,29,29,29,29,29,29,29,29,29,29,29,29,29,29,29,29,29,29,29,29,29,29,29,29,29,29,29,29,29,29,29
29,29,29,29,29,29,29,29,29,29,29,29,29,29,29,29,29,29,29,29,29,29,29,29,29,29,29,29,29,29,29,29,29,29,29,29,29,29,29,29,29,29,29,29,29
29,29,29,29,29,29,29,29,29,29,29,29,29,29,29,29,29,29,29,29,29,29,29,29,29,29,29,29,29,29,29,29,29,29,29,29,29,29,29,29,29,29,29,29,29
29,29,29,29,29,29,29,29,29,29,29,29,29,29,29,29,29,29,29,29,29,29,29,29,29,29,29,29,29,29,29,29,29,29,29,29,29,29,29,29,29,29,29,29,29
29,29,29,29,29,29,29,29,29,29,29,29,29,29,29,29,29,29,29,29,29,29,29,29,29,29,29,29,29,29,29,29,29,29,29,29,29,29,29,29,29,29,29,29,29
29,29,29,29,29,29,29,29,29,29,29,29,29,29,29,29,29,29,29,29,29,29,29,29,29,29,29,29,29,29,29,29,29,29,29,29,29,29,29,29,29,29,29,29,29
29,29,29,29,29,29,29,29,29,29,29,29,29,29,29,29,29,29,29,29,29,29,29,29,29,29,29,29,29,29,29,29,29,29,29,29,29,29,29,29,29,29,29,29,29
29,29,29,29,29,29,29,29,29,29,29,29,29,29,29,29,29,29,29,29,29,29,29,29,29,29,29,29,29,29,29,29,29,29,29,29,29,29,29,29,29,29,29,29,29
29,29,29,29,29,29,29,29,29,29,29,29,29,29,29,29,29,29,29,29,29,29,29,29,29,29,29,29,29,29,29,29,29,29,29,29,29,29,29,29,29,29,29,29,29
29,29,29,29,29,29,29,29,29,29,29,29,29,29,29,29,29,29,29,29,29,29,29,29,29,29,29,29,29,29,29,29,29,29,29,29,29,29,29,29,29,29,29,29,29
29,29,29,29,29,29,29,29,29,29,29,29,29,29,29,29,29,29,29,29,29,29,29,29,29,29,29,29,29,29,29,29,29,29,29,29,29,29,29,29,29,29,29,29,29
29,29,29,29,29,29,29,29,29,29,29,29,29,29,29,29,29,29,29,29,29,29,29,29,29,29,29,29,29,29,29,29,29,29,29,29,29,29,29,29,29,29,29,29,29
29,29,29,29,29,29,29,29,29,29,29,29,29,29,29,29,29,29,29,29,29,29,29,29,29,29,29,29,29,29,29,29,29,29,29,29,29,29,29,29,29,29,29,29,29
29,29,29,29,29,29,29,29,29,29,29,29,29,29,29,29,29,29,29,29,29,29,29,29,29,29,29,29,29,29,29,29,29,29,29,29,29,29,29,29,29,29,29,29,29
29,29,29,29,29,29,29,29,29,29,29,29,29,29,29,29,29,29,29,29,29,29,29,29,29,29,29,29,29,29,29,29,29,29,29,29,29,29,29,29,29,29,29,29,29
29,29,29,29,29,29,29,29,29,29,29,29,29,29,29,29,29,29,29,29,29,36,36,35,29,29,29,29,29,29,29,29,29,29,29,29,29,29,29,29,29,29,29,29,29
29,29,29,29,29,29,29,29,29,29,29,29,29,29,29,29,29,29,29,29,36,37,32,36,35,29,29,29,29,29,29,29,29,29,29,29,29,29,29,29,29,29,29,29,29
29,29,29,29,29,29,29,29,29,29,29,29,29,29,29,29,29,29,29,36,37,40,39,38,36,35,29,29,29,29,29,29,29,29,29,29,29,29,29,29,29,29,29,29,29
29,29,29,29,29,29,29,29,29,29,29,29,29,29,29,29,29,29,29,37,32,42,0,41,32,35,29,29,29,29,29,29,29,29,29,29,29,29,29,29,29,29,29,29,29
29,29,29,29,29,29,29,29,29,29,29,29,29,29,29,29,29,29,29,43,37,40,45,44,35,43,29,29,29,29,29,29,29,29,29,29,29,29,29,29,29,29,29,29,29
29,29,29,29,29,29,29,29,29,29,29,29,29,29,29,29,29,29,29,29,43,37,32,35,43,29,29,29,29,29,29,29,29,29,29,29,29,29,29,29,29,29,29,29,29
29,29,29,29,29,29,29,29,29,29,29,29,29,29,29,29,29,29,29,29,29,37,43,35,29,29,29,29,29,29,29,29,29,29,29,29,29,29,29,29,29,29,29,29,29
29,29,29,29,29,29,29,29,29,29,29,29,29,29,29,29,29,29,29,29,29,29,29,29,29,29,29,29,29,29,29,29,29,29,29,29,29,29,29,29,29,29,29,29,29
29,29,29,29,29,29,29,29,29,29,29,29,29,29,29,29,29,29,29,29,29,29,29,29,29,29,29,29,29,29,29,29,29,29,29,29,29,29,29,29,29,29,29,29,29
29,29,29,29,29,29,29,29,29,29,29,29,29,29,29,29,29,29,29,29,29,29,29,29,29,29,29,29,29,29,29,29,29,29,29,29,29,29,29,29,29,29,29,29,29
29,29,29,29,29,29,29,29,29,29,29,29,29,29,29,29,29,29,29,29,29,29,29,29,29,29,29,29,29,29,29,29,29,29,29,29,29,29,29,29,29,29,29,29,29
29,29,29,29,29,29,29,29,29,29,29,29,29,29,29,29,29,29,29,29,29,29,29,29,29,29,29,29,29,29,29,29,29,29,29,29,29,29,29,29,29,29,29,29,29
29,29,29,29,29,29,29,29,29,29,29,29,29,29,29,29,29,29,29,29,29,29,29,29,29,29,29,29,29,29,29,29,29,29,29,29,29,29,29,29,29,29,29,29,29
29,29,29,29,29,29,29,29,29,29,29,29,29,29,29,29,29,29,29,29,29,29,29,29,29,29,29,29,29,29,29,29,29,29,29,29,29,29,29,29,29,29,29,29,29
29,29,29,29,29,29,29,29,29,29,29,29,29,29,29,29,29,29,29,29,29,29,29,29,29,29,29,29,29,29,29,29,29,29,29,29,29,29,29,29,29,29,29,29,29
29,29,29,29,29,29,29,29,29,29,29,29,29,29,29,29,29,29,29,29,29,29,29,29,29,29,29,29,29,29,29,29,29,29,29,29,29,29,29,29,29,29,29,29,29
29,29,29,29,29,29,29,29,29,29,29,29,29,29,29,29,29,29,29,29,29,29,29,29,29,29,29,29,29,29,29,29,29,29,29,29,29,29,29,29,29,29,29,29,29
29,29,29,29,29,29,29,29,29,29,29,29,29,29,29,29,29,29,29,29,29,29,29,29,29,29,29,29,29,29,29,29,29,29,29,29,29,29,29,29,29,29,29,29,29
29,29,29,29,29,29,29,29,29,29,29,29,29,29,29,29,29,29,29,29,29,29,29,29,29,29,29,29,29,29,29,29,29,29,29,29,29,29,29,29,29,29,29,29,29
29,29,29,29,29,29,29,29,29,29,29,29,29,29,29,29,29,29,29,29,29,29,29,29,29,29,29,29,29,29,29,29,29,29,29,29,29,29,29,29,29,29,29,29,29
29,29,29,29,29,29,29,29,29,29,29,29,29,29,29,29,29,29,29,29,29,29,29,29,29,29,29,29,29,29,29,29,29,29,29,29,29,29,29,29,29,29,29,29,29
29,29,29,29,29,29,29,29,29,29,29,29,29,29,29,29,29,29,29,29,29,29,29,29,29,29,29,29,29,29,29,29,29,29,29,29,29,29,29,29,29,29,29,29,29
29,29,29,29,29,29,29,29,29,29,29,29,29,29,29,29,29,29,29,29,29,29,29,29,29,29,29,29,29,29,29,29,29,29,29,29,29,29,29,29,29,29,29,29,29
29,29,29,29,29,29,29,29,29,29,29,29,29,29,29,29,29,29,29,29,29,29,29,29,29,29,29,29,29,29,29,29,29,29,29,29,29,29,29,29,29,29,29,29,29
29,29,29,29,29,29,29,29,29,29,29,29,29,29,29,29,29,29,29,29,29,29,29,29,29,29,29,29,29,29,29,29,29,29,29,29,29,29,29,29,29,29,29,29,29
29,29,29,29,29,29,29,29,29,29,29,29,29,29,29,29,29,29,29,29,29,29,29,29,29,29,29,29,29,29,29,29,29,29,29,29,29,29,29,29,29,29,29,29,29
endlayer

layer
29,29,29,29,29,29,29,29,29,29,29,29,29,29,29,29,29,29,29,29,29,29,29,29,29,29,29,29,29,29,29,29,29,29,29,29,29,29,29,29,29,29,29,29,29
29,29,29,29,29,29,29,29,29,29,29,29,29,29,29,29,29,29,29,29,29,29,29,29,29,29,29,29,29,29,29,29,29,29,29,29,29,29,29,29,29,29,29,29,29
29,29,29,29,29,29,29,29,29,29,29,29,29,29,29,29,29,29,29,29,29,29,29,29,29,29,29,29,29,29,29,29,29,29,29,29,29,29,29,29,29,29,29,29,29
29,29,29,29,29,29,29,29,29,29,29,29,29,29,29,29,29,29,29,29,29,29,29,29,29,29,29,29,29,29,29,29,29,29,29,29,29,29,29,29,29,29,29,29,29
29,29,29,29,29,29,29,29,29,29,29,29,29,29,29,29,29,29,29,29,29,29,29,29,29,29,29,29,29,29,29,29,29,29,29,29,29,29,29,29,29,29,29,29,29
29,29,29,29,29,29,29,29,29,29,29,29,29,29,29,29,29,29,29,29,29,29,29,29,29,29,29,29,29,29,29,29,29,29,29,29,29,29,29,29,29,29,29,29,29
29,29,29,29,29,29,29,29,29,29,29,29,29,29,29,29,29,29,29,29,29,29,29,29,29,29,29,29,29,29,29,29,29,29,29,29,29,29,29,29,29,29,29,29,29
29,29,29,29,29,29,29,29,29,29,29,29,29,29,29,29,29,29,29,29,29,29,29,29,29,29,29,29,29,29,29,29,29,29,29,29,29,29,29,29,29,29,29,29,29
29,29,29,29,29,29,29,29,29,29,29,29,29,29,29,29,29,29,29,29,29,29,29,29,29,29,29,29,29,29,29,29,29,29,29,29,29,29,29,29,29,29,29,29,29
29,29,29,29,29,29,29,29,29,29,29,29,29,29,29,29,29,29,29,29,29,29,29,29,29,29,29,29,29,29,29,29,29,29,29,29,29,29,29,29,29,29,29,29,29
29,29,29,29,29,29,29,29,29,29,29,29,29,29,29,29,29,29,29,29,29,29,29,29,29,29,29,29,29,29,29,29,29,29,29,29,29,29,29,29,29,29,29,29,29
29,29,29,29,29,29,29,29,29,29,29,29,29,29,29,29,29,29,29,29,29,29,29,29,29,29,29,29,29,29,29,29,29,29,29,29,29,29,29,29,29,29,29,29,29
29,29,29,29,29,29,29,29,29,29,29,29,29,29,29,29,29,29,29,29,29,29,29,29,29,29,29,29,29,29,29,29,29,29,29,29,29,29,29,29,29,29,29,29,29
29,29,29,29,29,29,29,29,29,29,29,29,29,29,29,29,29,29,29,29,29,29,29,29,29,29,29,29,29,29,29,29,29,29,29,29,29,29,29,29,29,29,29,29,29
29,29,29,29,29,29,29,29,29,29,29,29,29,29,29,29,29,29,29,29,29,29,29,29,29,29,29,29,29,29,29,29,29,29,29,29,29,29,29,29,29,29,29,29,29
29,29,29,29,29,29,29,29,29,29,29,29,29,29,29,29,29,29,29,29,29,29,29,29,29,29,29,29,29,29,29,29,29,29,29,29,29,29,29,29,29,29,29,29,29
29,29,29,29,29,29,29,29,29,29,29,29,29,29,29,29,29,29,29,29,29,29,29,29,29,29,29,29,29,29,29,29,29,29,29,29,29,29,29,29,29,29,29,29,29
29,29,29,29,29,29,29,29,29,29,29,29,29,29,29,29,29,29,29,29,29,29,29,29,29,29,29,29,29,29,29,29,29,29,29,29,29,29,29,29,29,29,29,29,29
29,29,29,29,29,29,29,29,29,29,29,29,29,29,29,29,29,29,29,29,29,29,29,29,29,29,29,29,29,29,29,29,29,29,29,29,29,29,29,29,29,29,29,29,29
29,29,29,29,29,29,29,29,29,29,29,29,29,29,29,29,29,29,29,29,29,29,29,29,29,29,29,29,29,29,29,29,29,29,29,29,29,29,29,29,29,29,29,29,29
29,29,29,29,29,29,29,29,29,29,29,29,29,29,29,29,29,29,29,29,29,29,29,29,29,29,29,29,29,29,29,29,29,29,29,29,29,29,29,29,29,29,29,29,29
29,29,29,29,29,29,29,29,29,29,29,29,29,29,29,29,29,29,29,29,29,48,47,46,29,29,29,29,29,29,29,29,29,29,29,29,29,29,29,29,29,29,29,29,29
29,29,29,29,29,29,29,29,29,29,29,29,29,29,29,29,29,29,29,29,29,50,3,49,29,29,29,29,29,29,29,29,29,29,29,29,29,29,29,29,29,29,29,29,29
29,29,29,29,29,29,29,29,29,29,29,29,29,29,29,29,29,29,29,29,29,52,51,46,29,29,29,29,29,29,29,29,29,29,29,29,29,29,29,29,29,29,29,29,29
29,29,29,29,29,29,29,29,29,29,29,29,29,29,29,29,29,29,29,29,29,29,29,29,29,29,29,29,29,29,29,29,29,29,29,29,29,29,29,29,29,29,29,29,29
29,29,29,29,29,29,29,29,29,29,29,29,29,29,29,29,29,29,29,29,29,29,29,29,29,29,29,29,29,29,29,29,29,29,29,29,29,29,29,29,29,29,29,29,29
29,29,29,29,29,29,29,29,29,29,29,29,29,29,29,29,29,29,29,29,29,29,29,29,29,29,29,29,29,29,29,29,29,29,29,29,29,29,29,29,29,29,29,29,29
29,29,29,29,29,29,29,29,29,29,29,29,29,29,29,29,29,29,29,29,29,29,29,29,29,29,29,29,29,29,29,29,29,29,29,29,29,29,29,29,29,29,29,29,29
29,29,29,29,29,29,29,29,29,29,29,29,29,29,29,29,29,29,29,29,29,29,29,29,29,29,29,29,29,29,29,29,29,29,29,29,29,29,29,29,29,29,29,29,29
29,29,29,29,29,29,29,29,29,29,29,29,29,29,29,29,29,29,29,29,29,29,29,29,29,29,29,29,29,29,29,29,29,29,29,29,29,29,29,29,29,29,29,29,29
29,29,29,29,29,29,29,29,29,29,29,29,29,29,29,29,29,29,29,29,29,29,29,29,29,29,29,29,29,29,29,29,29,29,29,29,29,29,29,29,29,29,29,29,29
29,29,29,29,29,29,29,29,29,29,29,29,29,29,29,29,29,29,29,29,29,29,29,29,29,29,29,29,29,29,29,29,29,29,29,29,29,29,29,29,29,29,29,29,29
29,29,29,29,29,29,29,29,29,29,29,29,29,29,29,29,29,29,29,29,29,29,29,29,29,29,29,29,29,29,29,29,29,29,29,29,29,29,29,29,29,29,29,29,29
29,29,29,29,29,29,29,29,29,29,29,29,29,29,29,29,29,29,29,29,29,29,29,29,29,29,29,29,29,29,29,29,29,29,29,29,29,29,29,29,29,29,29,29,29
29,29,29,29,29,29,29,29,29,29,29,29,29,29,29,29,29,29,29,29,29,29,29,29,29,29,29,29,29,29,29,29,29,29,29,29,29,29,29,29,29,29,29,29,29
29,29,29,29,29,29,29,29,29,29,29,29,29,29,29,29,29,29,29,29,29,29,29,29,29,29,29,29,29,29,29,29,29,29,29,29,29,29,29,29,29,29,29,29,29
29,29,29,29,29,29,29,29,29,29,29,29,29,29,29,29,29,29,29,29,29,29,29,29,29,29,29,29,29,29,29,29,29,29,29,29,29,29,29,29,29,29,29,29,29
29,29,29,29,29,29,29,29,29,29,29,29,29,29,29,29,29,29,29,29,29,29,29,29,29,29,29,29,29,29,29,29,29,29,29,29,29,29,29,29,29,29,29,29,29
29,29,29,29,29,29,29,29,29,29,29,29,29,29,29,29,29,29,29,29,29,29,29,29,29,29,29,29,29,29,29,29,29,29,29,29,29,29,29,29,29,29,29,29,29
29,29,29,29,29,29,29,29,29,29,29,29,29,29,29,29,29,29,29,29,29,29,29,29,29,29,29,29,29,29,29,29,29,29,29,29,29,29,29,29,29,29,29,29,29
29,29,29,29,29,29,29,29,29,29,29,29,29,29,29,29,29,29,29,29,29,29,29,29,29,29,29,29,29,29,29,29,29,29,29,29,29,29,29,29,29,29,29,29,29
29,29,29,29,29,29,29,29,29,29,29,29,29,29,29,29,29,29,29,29,29,29,29,29,29,29,29,29,29,29,29,29,29,29,29,29,29,29,29,29,29,29,29,29,29
29,29,29,29,29,29,29,29,29,29,29,29,29,29,29,29,29,29,29,29,29,29,29,29,29,29,29,29,29,29,29,29,29,29,29,29,29,29,29,29,29,29,29,29,29
29,29,29,29,29,29,29,29,29,29,29,29,29,29,29,29,29,29,29,29,29,29,29,29,29,29,29,29,29,29,29,29,29,29,29,29,29,29,29,29,29,29,29,29,29
29,29,29,29,29,29,29,29,29,29,29,29,29,29,29,29,29,29,29,29,29,29,29,29,29,29,29,29,29,29,29,29,29,29,29,29,29,29,29,29,29,29,29,29,29
endlayer

